{"received_at_ns": 1787373187399230901, "payload": "{\"result\":null,\"id\":1}"}
{"received_at_ns": 1787373187664894441, "payload": "{\"e\":\"depthUpdate\",\"E\":1787373187597,\"T\":1787373187596,\"s\":\"BTCUSDT\",\"ps\":\"BTCUSDT\",\"U\":11351948348181,\"u\":11351948482289,\"pu\":11351948348100,\"b\":[[\"78659.00\",\"1.939\"],[\"78658.90\",\"0.004\"],[\"78658.80\",\"0.002\"],[\"78658.50\",\"0.002\"],[\"78657.50\",\"0.001\"],[\"78657.30\",\"0.001\"],[\"78656.60\",\"0.001\"],[\"78656.20\",\"0.026\"],[\"78656.00\",\"0.003\"],[\"78655.90\",\"0.002\"],[\"78655.40\",\"0.026\"],[\"78655.20\",\"0.311\"],[\"78655.00\",\"0.003\"],[\"78654.90\",\"0.306\"],[\"78654.80\",\"0.339\"],[\"78654.60\",\"0.028\"],[\"78654.50\",\"1.009\"],[\"78654.30\",\"1.001\"],[\"78653.90\",\"1.002\"],[\"78653.80\",\"0.028\"]],\"a\":[[\"78659.10\",\"4.401\"],[\"78659.20\",\"0.026\"],[\"78659.50\",\"0.001\"],[\"78659.60\",\"0.002\"],[\"78659.90\",\"0.002\"],[\"78660.00\",\"0.225\"],[\"78660.20\",\"0.027\"],[\"78660.60\",\"0.001\"],[\"78660.80\",\"0.001\"],[\"78660.90\",\"0.001\"],[\"78661.00\",\"0.317\"],[\"78661.10\",\"0.026\"],[\"78661.20\",\"0.001\"],[\"78661.30\",\"0.001\"],[\"78661.50\",\"0.004\"],[\"78661.70\",\"0.001\"],[\"78661.80\",\"0.002\"],[\"78661.90\",\"0.001\"],[\"78662.00\",\"0.026\"],[\"78662.10\",\"0.002\"]],\"st\":1}"}
{"received_at_ns": 1787373188168661502, "payload": "{\"e\":\"depthUpdate\",\"E\":1787373188101,\"T\":1787373188099,\"s\":\"BTCUSDT\",\"ps\":\"BTCUSDT\",\"U\":11351948482328,\"u\":11351948590207,\"pu\":11351948482289,\"b\":[[\"78659.00\",\"0.203\"],[\"78658.90\",\"0.004\"],[\"78658.80\",\"0.002\"],[\"78658.50\",\"0.002\"],[\"78657.70\",\"0.002\"],[\"78657.50\",\"0.001\"],[\"78657.30\",\"0.001\"],[\"78656.60\",\"0.001\"],[\"78656.00\",\"0.003\"],[\"78655.90\",\"0.002\"],[\"78655.70\",\"0.002\"],[\"78655.20\",\"0.311\"],[\"78655.00\",\"0.003\"],[\"78654.90\",\"0.005\"],[\"78654.80\",\"0.339\"],[\"78654.60\",\"0.028\"],[\"78654.50\",\"1.009\"],[\"78654.30\",\"1.001\"],[\"78653.90\",\"1.001\"],[\"78653.80\",\"0.028\"]],\"a\":[[\"78659.10\",\"11.944\"],[\"78659.20\",\"0.027\"],[\"78659.50\",\"0.001\"],[\"78659.60\",\"0.002\"],[\"78659.90\",\"0.002\"],[\"78660.00\",\"0.225\"],[\"78660.20\",\"0.027\"],[\"78660.60\",\"0.001\"],[\"78660.80\",\"0.032\"],[\"78660.90\",\"0.001\"],[\"78661.00\",\"0.009\"],[\"78661.10\",\"0.026\"],[\"78661.20\",\"0.001\"],[\"78661.30\",\"0.001\"],[\"78661.50\",\"0.004\"],[\"78661.70\",\"0.001\"],[\"78661.80\",\"0.004\"],[\"78661.90\",\"0.001\"],[\"78662.00\",\"0.026\"],[\"78662.10\",\"0.002\"]],\"st\":1}"}
{"received_at_ns": 1787373188673163182, "payload": "{\"e\":\"depthUpdate\",\"E\":1787373188605,\"T\":1787373188604,\"s\":\"BTCUSDT\",\"ps\":\"BTCUSDT\",\"U\":11351948590977,\"u\":11351948745072,\"pu\":11351948590207,\"b\":[[\"78637.60\",\"15.162\"],[\"78637.50\",\"0.120\"],[\"78637.40\",\"0.003\"],[\"78637.20\",\"0.002\"],[\"78637.00\",\"0.001\"],[\"78636.60\",\"0.338\"],[\"78636.40\",\"0.002\"],[\"78636.30\",\"0.557\"],[\"78636.20\",\"0.027\"],[\"78635.80\",\"0.001\"],[\"78635.60\",\"0.255\"],[\"78635.50\",\"0.002\"],[\"78635.10\",\"0.001\"],[\"78635.00\",\"0.002\"],[\"78634.90\",\"0.044\"],[\"78634.80\",\"0.028\"],[\"78634.70\",\"0.001\"],[\"78634.60\",\"0.508\"],[\"78634.50\",\"0.002\"],[\"78633.80\",\"0.001\"]],\"a\":[[\"78637.70\",\"1.271\"],[\"78637.90\",\"0.002\"],[\"78638.00\",\"0.001\"],[\"78638.30\",\"0.001\"],[\"78638.40\",\"0.003\"],[\"78639.30\",\"0.001\"],[\"78639.40\",\"0.001\"],[\"78639.50\",\"0.001\"],[\"78640.00\",\"0.001\"],[\"78640.10\",\"0.001\"],[\"78640.40\",\"0.026\"],[\"78640.60\",\"0.001\"],[\"78640.80\",\"0.002\"],[\"78641.30\",\"0.026\"],[\"78641.40\",\"0.001\"],[\"78641.60\",\"0.001\"],[\"78641.80\",\"0.002\"],[\"78642.20\",\"0.028\"],[\"78642.40\",\"0.001\"],[\"78642.50\",\"0.001\"]],\"st\":1}"}
{"received_at_ns": 1787373189176687743, "payload": "{\"e\":\"depthUpdate\",\"E\":1787373189109,\"T\":1787373189107,\"s\":\"BTCUSDT\",\"ps\":\"BTCUSDT\",\"U\":11351948745292,\"u\":11351948833049,\"pu\":11351948745072,\"b\":[[\"78637.60\",\"2.875\"],[\"78637.50\",\"0.004\"],[\"78637.40\",\"0.002\"],[\"78636.90\",\"0.002\"],[\"78636.40\",\"0.002\"],[\"78636.30\",\"0.002\"],[\"78636.20\",\"0.001\"],[\"78635.80\",\"0.001\"],[\"78635.60\",\"0.026\"],[\"78635.50\",\"0.002\"],[\"78635.10\",\"0.001\"],[\"78635.00\",\"0.002\"],[\"78634.90\",\"0.001\"],[\"78634.80\",\"0.028\"],[\"78634.70\",\"0.001\"],[\"78634.50\",\"0.002\"],[\"78633.90\",\"0.032\"],[\"78633.80\",\"0.309\"],[\"78633.60\",\"0.003\"],[\"78633.40\",\"0.002\"]],\"a\":[[\"78637.70\",\"3.529\"],[\"78637.90\",\"0.002\"],[\"78638.00\",\"0.001\"],[\"78638.30\",\"0.001\"],[\"78638.40\",\"0.003\"],[\"78638.50\",\"0.026\"],[\"78639.30\",\"0.028\"],[\"78639.40\",\"0.001\"],[\"78639.50\",\"0.001\"],[\"78640.00\",\"0.001\"],[\"78640.10\",\"0.001\"],[\"78640.20\",\"0.026\"],[\"78640.60\",\"0.001\"],[\"78640.80\",\"0.002\"],[\"78641.00\",\"0.026\"],[\"78641.40\",\"0.002\"],[\"78641.50\",\"0.308\"],[\"78641.60\",\"0.001\"],[\"78641.80\",\"0.002\"],[\"78642.20\",\"0.030\"]],\"st\":1}"}
{"received_at_ns": 1787373189680497785, "payload": "{\"e\":\"depthUpdate\",\"E\":1787373189613,\"T\":1787373189611,\"s\":\"BTCUSDT\",\"ps\":\"BTCUSDT\",\"U\":11351948833181,\"u\":11351948929483,\"pu\":11351948833049,\"b\":[[\"78637.60\",\"3.582\"],[\"78637.50\",\"0.004\"],[\"78637.40\",\"0.028\"],[\"78636.90\",\"0.002\"],[\"78636.60\",\"0.028\"],[\"78636.40\",\"0.002\"],[\"78636.30\",\"0.002\"],[\"78636.20\",\"0.001\"],[\"78636.10\",\"0.002\"],[\"78635.80\",\"0.256\"],[\"78635.70\",\"0.372\"],[\"78635.60\",\"0.026\"],[\"78635.50\",\"0.002\"],[\"78635.10\",\"0.001\"],[\"78635.00\",\"0.002\"],[\"78634.90\",\"0.001\"],[\"78634.80\",\"0.028\"],[\"78634.70\",\"0.001\"],[\"78634.50\",\"0.002\"],[\"78633.90\",\"0.008\"]],\"a\":[[\"78637.70\",\"1.727\"],[\"78638.20\",\"0.002\"],[\"78638.30\",\"0.001\"],[\"78638.40\",\"0.003\"],[\"78639.30\",\"0.001\"],[\"78639.40\",\"0.001\"],[\"78639.50\",\"0.001\"],[\"78640.00\",\"0.001\"],[\"78640.10\",\"0.001\"],[\"78640.20\",\"0.026\"],[\"78640.60\",\"0.001\"],[\"78640.80\",\"0.002\"],[\"78641.00\",\"0.026\"],[\"78641.40\",\"0.002\"],[\"78641.50\",\"0.308\"],[\"78641.60\",\"0.001\"],[\"78641.80\",\"0.002\"],[\"78642.20\",\"0.030\"],[\"78642.30\",\"0.001\"],[\"78642.40\",\"0.001\"]],\"st\":1}"}
{"received_at_ns": 1787373190184554517, "payload": "{\"e\":\"depthUpdate\",\"E\":1787373190117,\"T\":1787373190116,\"s\":\"BTCUSDT\",\"ps\":\"BTCUSDT\",\"U\":11351948929717,\"u\":11351949037422,\"pu\":11351948929483,\"b\":[[\"78623.80\",\"4.183\"],[\"78623.70\",\"0.076\"],[\"78623.60\",\"0.012\"],[\"78623.20\",\"0.010\"],[\"78622.90\",\"0.343\"],[\"78622.80\",\"0.031\"],[\"78622.70\",\"0.001\"],[\"78622.60\",\"0.001\"],[\"78622.40\",\"0.001\"],[\"78622.00\",\"0.002\"],[\"78621.90\",\"0.317\"],[\"78621.60\",\"0.001\"],[\"78621.50\",\"0.003\"],[\"78621.40\",\"0.001\"],[\"78621.30\",\"0.001\"],[\"78621.00\",\"0.033\"],[\"78620.90\",\"0.029\"],[\"78620.80\",\"0.002\"],[\"78620.60\",\"0.001\"],[\"78620.50\",\"0.011\"]],\"a\":[[\"78623.90\",\"0.328\"],[\"78624.00\",\"0.001\"],[\"78624.70\",\"0.002\"],[\"78624.80\",\"0.001\"],[\"78625.00\",\"0.001\"],[\"78625.50\",\"0.001\"],[\"78625.60\",\"0.001\"],[\"78625.80\",\"0.001\"],[\"78626.40\",\"0.002\"],[\"78626.50\",\"0.026\"],[\"78627.50\",\"0.001\"],[\"78627.80\",\"0.002\"],[\"78627.90\",\"0.027\"],[\"78628.40\",\"0.325\"],[\"78628.60\",\"0.001\"],[\"78628.80\",\"0.001\"],[\"78628.90\",\"0.001\"],[\"78629.10\",\"0.001\"],[\"78629.40\",\"0.001\"],[\"78629.70\",\"0.001\"]],\"st\":1}"}
{"received_at_ns": 1787373190688453435, "payload": "{\"e\":\"depthUpdate\",\"E\":1787373190621,\"T\":1787373190620,\"s\":\"BTCUSDT\",\"ps\":\"BTCUSDT\",\"U\":11351949037437,\"u\":11351949165548,\"pu\":11351949037422,\"b\":[[\"78639.10\",\"15.027\"],[\"78639.00\",\"0.030\"],[\"78638.40\",\"0.002\"],[\"78638.20\",\"0.002\"],[\"78637.60\",\"2.026\"],[\"78637.50\",\"0.106\"],[\"78637.40\",\"0.001\"],[\"78637.00\",\"0.001\"],[\"78636.90\",\"0.006\"],[\"78636.70\",\"0.001\"],[\"78636.60\",\"0.122\"],[\"78636.40\",\"0.002\"],[\"78636.30\",\"0.616\"],[\"78636.20\",\"0.103\"],[\"78636.00\",\"0.001\"],[\"78635.90\",\"0.001\"],[\"78635.40\",\"0.001\"],[\"78635.30\",\"0.146\"],[\"78635.20\",\"0.002\"],[\"78635.10\",\"0.553\"]],\"a\":[[\"78639.20\",\"1.014\"],[\"78639.30\",\"0.002\"],[\"78639.40\",\"0.001\"],[\"78639.60\",\"0.001\"],[\"78640.00\",\"0.001\"],[\"78640.60\",\"0.001\"],[\"78640.80\",\"0.001\"],[\"78641.00\",\"0.003\"],[\"78641.60\",\"0.002\"],[\"78641.80\",\"0.004\"],[\"78642.20\",\"0.029\"],[\"78642.30\",\"0.001\"],[\"78642.40\",\"0.001\"],[\"78642.50\",\"0.001\"],[\"78642.90\",\"0.004\"],[\"78643.20\",\"0.027\"],[\"78643.30\",\"0.004\"],[\"78643.40\",\"0.308\"],[\"78643.50\",\"0.001\"],[\"78643.60\",\"0.001\"]],\"st\":1}"}
{"received_at_ns": 1787373191192715137, "payload": "{\"e\":\"depthUpdate\",\"E\":1787373191125,\"T\":1787373191124,\"s\":\"BTCUSDT\",\"ps\":\"BTCUSDT\",\"U\":11351949165606,\"u\":11351949263838,\"pu\":11351949165548,\"b\":[[\"78636.30\",\"6.494\"],[\"78636.20\",\"0.004\"],[\"78636.10\",\"0.002\"],[\"78635.50\",\"0.026\"],[\"78635.30\",\"0.002\"],[\"78635.10\",\"0.077\"],[\"78635.00\",\"0.008\"],[\"78634.70\",\"0.001\"],[\"78634.60\",\"0.078\"],[\"78634.50\",\"0.026\"],[\"78634.10\",\"0.078\"],[\"78634.00\",\"0.001\"],[\"78633.90\",\"0.001\"],[\"78633.80\",\"0.002\"],[\"78633.70\",\"0.026\"],[\"78633.60\",\"0.002\"],[\"78633.50\",\"0.079\"],[\"78633.40\",\"0.001\"],[\"78633.10\",\"0.001\"],[\"78633.00\",\"0.027\"]],\"a\":[[\"78636.40\",\"0.447\"],[\"78636.50\",\"0.001\"],[\"78637.50\",\"0.001\"],[\"78637.60\",\"0.002\"],[\"78638.10\",\"0.001\"],[\"78638.20\",\"0.026\"],[\"78638.90\",\"0.001\"],[\"78639.10\",\"0.002\"],[\"78639.20\",\"0.050\"],[\"78639.30\",\"0.001\"],[\"78639.40\",\"0.001\"],[\"78639.50\",\"0.001\"],[\"78640.00\",\"0.001\"],[\"78640.30\",\"0.001\"],[\"78640.40\",\"0.324\"],[\"78640.60\",\"0.001\"],[\"78640.80\",\"0.001\"],[\"78641.00\",\"0.003\"],[\"78641.10\",\"0.311\"],[\"78641.60\",\"0.002\"]],\"st\":1}"}
{"received_at_ns": 1787373191696438179, "payload": "{\"e\":\"depthUpdate\",\"E\":1787373191629,\"T\":1787373191625,\"s\":\"BTCUSDT\",\"ps\":\"BTCUSDT\",\"U\":11351949263847,\"u\":11351949337845,\"pu\":11351949263838,\"b\":[[\"78636.30\",\"6.580\"],[\"78636.20\",\"0.030\"],[\"78636.10\",\"0.002\"],[\"78635.80\",\"0.002\"],[\"78635.50\",\"0.026\"],[\"78635.30\",\"0.004\"],[\"78635.00\",\"0.008\"],[\"78634.80\",\"0.077\"],[\"78634.70\",\"0.001\"],[\"78634.60\",\"0.001\"],[\"78634.50\",\"0.026\"],[\"78634.30\",\"0.063\"],[\"78634.20\",\"0.077\"],[\"78634.10\",\"0.001\"],[\"78634.00\",\"0.001\"],[\"78633.90\",\"0.001\"],[\"78633.80\",\"0.002\"],[\"78633.70\",\"0.026\"],[\"78633.60\",\"0.002\"],[\"78633.50\",\"0.002\"]],\"a\":[[\"78636.40\",\"0.283\"],[\"78636.50\",\"0.001\"],[\"78637.50\",\"0.001\"],[\"78637.60\",\"0.002\"],[\"78638.10\",\"0.001\"],[\"78638.20\",\"0.001\"],[\"78638.90\",\"0.001\"],[\"78639.10\",\"0.002\"],[\"78639.20\",\"0.049\"],[\"78639.30\",\"0.027\"],[\"78639.40\",\"0.001\"],[\"78639.50\",\"0.001\"],[\"78639.90\",\"0.001\"],[\"78640.00\",\"0.001\"],[\"78640.30\",\"0.001\"],[\"78640.40\",\"0.323\"],[\"78640.60\",\"0.001\"],[\"78640.80\",\"0.001\"],[\"78641.00\",\"0.004\"],[\"78641.10\",\"0.311\"]],\"st\":1}"}
{"received_at_ns": 1787373192200523940, "payload": "{\"e\":\"depthUpdate\",\"E\":1787373192133,\"T\":1787373192132,\"s\":\"BTCUSDT\",\"ps\":\"BTCUSDT\",\"U\":11351949338400,\"u\":11351949425029,\"pu\":11351949337845,\"b\":[[\"78639.10\",\"10.684\"],[\"78639.00\",\"0.001\"],[\"78638.90\",\"0.002\"],[\"78638.50\",\"0.002\"],[\"78638.30\",\"0.003\"],[\"78638.00\",\"0.026\"],[\"78637.60\",\"0.003\"],[\"78637.50\",\"0.001\"],[\"78637.40\",\"0.001\"],[\"78636.70\",\"0.001\"],[\"78636.40\",\"0.006\"],[\"78636.30\",\"0.092\"],[\"78636.20\",\"0.030\"],[\"78636.10\",\"0.002\"],[\"78636.00\",\"0.002\"],[\"78635.80\",\"0.257\"],[\"78635.60\",\"0.002\"],[\"78635.50\",\"0.026\"],[\"78635.40\",\"0.003\"],[\"78635.30\",\"0.005\"]],\"a\":[[\"78639.20\",\"2.794\"],[\"78639.30\",\"0.002\"],[\"78639.40\",\"0.001\"],[\"78639.50\",\"0.001\"],[\"78640.00\",\"0.001\"],[\"78640.40\",\"0.026\"],[\"78640.60\",\"0.001\"],[\"78640.80\",\"0.001\"],[\"78641.00\",\"0.003\"],[\"78641.20\",\"0.026\"],[\"78641.60\",\"0.002\"],[\"78641.80\",\"0.004\"],[\"78641.90\",\"0.026\"],[\"78642.20\",\"0.003\"],[\"78642.30\",\"0.001\"],[\"78642.40\",\"0.001\"],[\"78642.50\",\"0.001\"],[\"78642.70\",\"0.026\"],[\"78642.90\",\"0.133\"],[\"78643.00\",\"0.309\"]],\"st\":1}"}
{"received_at_ns": 1787373192704458772, "payload": "{\"e\":\"depthUpdate\",\"E\":1787373192637,\"T\":1787373192636,\"s\":\"BTCUSDT\",\"ps\":\"BTCUSDT\",\"U\":11351949425094,\"u\":11351949517749,\"pu\":11351949425029,\"b\":[[\"78639.10\",\"0.254\"],[\"78639.00\",\"0.001\"],[\"78638.60\",\"0.002\"],[\"78638.50\",\"0.002\"],[\"78638.20\",\"0.002\"],[\"78637.60\",\"0.003\"],[\"78637.50\",\"0.001\"],[\"78637.40\",\"0.001\"],[\"78636.70\",\"0.001\"],[\"78636.40\",\"0.001\"],[\"78636.30\",\"0.076\"],[\"78636.10\",\"0.002\"],[\"78636.00\",\"0.002\"],[\"78635.80\",\"0.002\"],[\"78635.30\",\"0.003\"],[\"78635.00\",\"0.012\"],[\"78634.70\",\"0.001\"],[\"78634.60\",\"0.001\"],[\"78634.10\",\"0.001\"],[\"78634.00\",\"0.001\"]],\"a\":[[\"78639.20\",\"12.108\"],[\"78639.30\",\"0.002\"],[\"78639.40\",\"0.029\"],[\"78639.50\",\"0.078\"],[\"78639.90\",\"0.002\"],[\"78640.00\",\"0.001\"],[\"78640.40\",\"0.027\"],[\"78640.60\",\"0.001\"],[\"78640.80\",\"0.001\"],[\"78640.90\",\"0.077\"],[\"78641.00\",\"0.003\"],[\"78641.20\",\"0.026\"],[\"78641.50\",\"0.077\"],[\"78641.60\",\"0.002\"],[\"78641.80\",\"0.004\"],[\"78641.90\",\"0.026\"],[\"78642.20\",\"0.005\"],[\"78642.30\",\"0.333\"],[\"78642.40\",\"0.001\"],[\"78642.50\",\"0.001\"]],\"st\":1}"}
{"received_at_ns": 1787373193208458771, "payload": "{\"e\":\"depthUpdate\",\"E\":1787373193141,\"T\":1787373193140,\"s\":\"BTCUSDT\",\"ps\":\"BTCUSDT\",\"U\":11351949517932,\"u\":11351949582940,\"pu\":11351949517749,\"b\":[[\"78639.10\",\"0.739\"],[\"78639.00\",\"0.001\"],[\"78638.60\",\"0.002\"],[\"78638.50\",\"0.002\"],[\"78638.20\",\"0.002\"],[\"78637.60\",\"0.003\"],[\"78637.50\",\"0.001\"],[\"78637.40\",\"0.001\"],[\"78636.70\",\"0.001\"],[\"78636.40\",\"0.001\"],[\"78636.30\",\"0.076\"],[\"78636.10\",\"0.002\"],[\"78636.00\",\"0.002\"],[\"78635.80\",\"0.002\"],[\"78635.30\",\"0.029\"],[\"78635.00\",\"0.012\"],[\"78634.70\",\"0.001\"],[\"78634.60\",\"0.001\"],[\"78634.50\",\"0.026\"],[\"78634.30\",\"0.063\"]],\"a\":[[\"78639.20\",\"11.274\"],[\"78639.30\",\"0.003\"],[\"78639.40\",\"0.027\"],[\"78639.50\",\"0.001\"],[\"78639.60\",\"0.002\"],[\"78639.90\",\"0.002\"],[\"78640.00\",\"0.004\"],[\"78640.40\",\"0.027\"],[\"78640.60\",\"0.001\"],[\"78640.70\",\"0.002\"],[\"78640.80\",\"0.001\"],[\"78640.90\",\"0.002\"],[\"78641.00\",\"0.003\"],[\"78641.20\",\"0.026\"],[\"78641.60\",\"0.002\"],[\"78641.80\",\"0.004\"],[\"78641.90\",\"0.026\"],[\"78642.20\",\"0.005\"],[\"78642.30\",\"0.256\"],[\"78642.40\",\"0.001\"]],\"st\":1}"}
{"received_at_ns": 1787373193718645333, "payload": "{\"e\":\"depthUpdate\",\"E\":1787373193651,\"T\":1787373193648,\"s\":\"BTCUSDT\",\"ps\":\"BTCUSDT\",\"U\":11351949583321,\"u\":11351949736084,\"pu\":11351949582940,\"b\":[[\"78624.60\",\"9.940\"],[\"78624.50\",\"0.002\"],[\"78624.40\",\"0.002\"],[\"78624.30\",\"0.026\"],[\"78623.50\",\"1.022\"],[\"78623.40\",\"0.027\"],[\"78623.30\",\"0.001\"],[\"78623.00\",\"1.950\"],[\"78622.90\",\"0.001\"],[\"78622.70\",\"0.026\"],[\"78622.30\",\"0.040\"],[\"78622.20\",\"0.001\"],[\"78622.00\",\"0.033\"],[\"78621.90\",\"0.001\"],[\"78621.60\",\"0.001\"],[\"78621.50\",\"0.001\"],[\"78621.40\",\"0.001\"],[\"78621.10\",\"0.001\"],[\"78621.00\",\"0.288\"],[\"78620.90\",\"0.001\"]],\"a\":[[\"78624.70\",\"0.333\"],[\"78624.80\",\"0.002\"],[\"78624.90\",\"0.001\"],[\"78625.00\",\"0.001\"],[\"78625.10\",\"0.002\"],[\"78625.70\",\"0.001\"],[\"78626.40\",\"0.001\"],[\"78626.50\",\"0.001\"],[\"78627.10\",\"0.002\"],[\"78627.90\",\"0.001\"],[\"78628.00\",\"0.001\"],[\"78628.10\",\"0.001\"],[\"78628.20\",\"0.001\"],[\"78628.30\",\"0.002\"],[\"78628.40\",\"0.026\"],[\"78628.70\",\"0.001\"],[\"78628.80\",\"0.004\"],[\"78628.90\",\"0.327\"],[\"78629.30\",\"0.026\"],[\"78629.40\",\"0.001\"]],\"st\":1}"}
{"received_at_ns": 1787373194222675194, "payload": "{\"e\":\"depthUpdate\",\"E\":1787373194155,\"T\":1787373194154,\"s\":\"BTCUSDT\",\"ps\":\"BTCUSDT\",\"U\":11351949736487,\"u\":11351949817573,\"pu\":11351949736084,\"b\":[[\"78629.20\",\"7.792\"],[\"78629.10\",\"0.003\"],[\"78628.90\",\"0.002\"],[\"78628.80\",\"0.029\"],[\"78628.70\",\"0.026\"],[\"78627.80\",\"0.001\"],[\"78627.60\",\"0.002\"],[\"78627.50\",\"0.001\"],[\"78626.90\",\"1.916\"],[\"78626.80\",\"0.001\"],[\"78626.40\",\"0.001\"],[\"78626.20\",\"0.003\"],[\"78625.80\",\"0.004\"],[\"78625.60\",\"0.026\"],[\"78625.30\",\"0.001\"],[\"78625.20\",\"0.001\"],[\"78625.10\",\"0.001\"],[\"78625.00\",\"0.257\"],[\"78624.80\",\"0.002\"],[\"78624.70\",\"0.004\"]],\"a\":[[\"78629.30\",\"1.217\"],[\"78629.50\",\"0.001\"],[\"78629.60\",\"0.001\"],[\"78630.00\",\"0.004\"],[\"78630.30\",\"0.019\"],[\"78630.60\",\"0.002\"],[\"78630.90\",\"0.002\"],[\"78631.00\",\"0.001\"],[\"78631.20\",\"0.001\"],[\"78631.30\",\"0.001\"],[\"78631.50\",\"0.001\"],[\"78631.60\",\"0.001\"],[\"78631.70\",\"0.001\"],[\"78631.80\",\"0.001\"],[\"78632.20\",\"0.001\"],[\"78632.60\",\"0.001\"],[\"78632.90\",\"0.002\"],[\"78633.00\",\"0.002\"],[\"78633.10\",\"0.341\"],[\"78633.40\",\"0.029\"]],\"st\":1}"}
{"received_at_ns": 1787373194726852386, "payload": "{\"e\":\"depthUpdate\",\"E\":1787373194659,\"T\":1787373194658,\"s\":\"BTCUSDT\",\"ps\":\"BTCUSDT\",\"U\":11351949817826,\"u\":11351949906550,\"pu\":11351949817573,\"b\":[[\"78629.20\",\"0.848\"],[\"78629.10\",\"0.003\"],[\"78628.90\",\"0.002\"],[\"78628.80\",\"0.001\"],[\"78628.00\",\"0.002\"],[\"78627.80\",\"0.001\"],[\"78627.60\",\"0.005\"],[\"78627.50\",\"0.001\"],[\"78627.10\",\"0.339\"],[\"78626.80\",\"0.001\"],[\"78626.70\",\"0.002\"],[\"78626.40\",\"0.027\"],[\"78626.10\",\"0.001\"],[\"78625.80\",\"0.001\"],[\"78625.60\",\"0.026\"],[\"78625.40\",\"0.001\"],[\"78625.30\",\"0.005\"],[\"78625.20\",\"0.256\"],[\"78625.10\",\"0.001\"],[\"78625.00\",\"0.341\"]],\"a\":[[\"78629.30\",\"3.335\"],[\"78629.50\",\"0.001\"],[\"78629.60\",\"0.001\"],[\"78630.00\",\"0.004\"],[\"78630.30\",\"0.019\"],[\"78630.60\",\"0.003\"],[\"78630.80\",\"0.001\"],[\"78630.90\",\"0.028\"],[\"78631.20\",\"0.004\"],[\"78631.30\",\"0.001\"],[\"78631.40\",\"0.339\"],[\"78631.50\",\"0.001\"],[\"78631.60\",\"0.001\"],[\"78631.70\",\"0.027\"],[\"78631.80\",\"0.001\"],[\"78632.20\",\"0.001\"],[\"78632.40\",\"0.005\"],[\"78632.60\",\"0.027\"],[\"78632.90\",\"0.002\"],[\"78633.00\",\"0.129\"]],\"st\":1}"}
{"received_at_ns": 1787373195230648688, "payload": "{\"e\":\"depthUpdate\",\"E\":1787373195163,\"T\":1787373195160,\"s\":\"BTCUSDT\",\"ps\":\"BTCUSDT\",\"U\":11351949906612,\"u\":11351949997775,\"pu\":11351949906550,\"b\":[[\"78629.20\",\"0.876\"],[\"78629.10\",\"0.003\"],[\"78628.90\",\"0.002\"],[\"78628.80\",\"0.001\"],[\"78628.00\",\"0.002\"],[\"78627.80\",\"0.001\"],[\"78627.60\",\"0.005\"],[\"78627.50\",\"0.001\"],[\"78627.10\",\"0.339\"],[\"78626.80\",\"0.001\"],[\"78626.70\",\"0.002\"],[\"78626.40\",\"0.027\"],[\"78626.10\",\"0.001\"],[\"78625.80\",\"0.001\"],[\"78625.60\",\"0.026\"],[\"78625.40\",\"0.001\"],[\"78625.30\",\"0.001\"],[\"78625.20\",\"0.001\"],[\"78625.10\",\"0.009\"],[\"78625.00\",\"0.596\"]],\"a\":[[\"78629.30\",\"2.502\"],[\"78629.40\",\"0.001\"],[\"78629.50\",\"0.003\"],[\"78629.60\",\"0.002\"],[\"78630.00\",\"0.004\"],[\"78630.30\",\"0.019\"],[\"78630.60\",\"0.002\"],[\"78630.80\",\"0.027\"],[\"78630.90\",\"0.002\"],[\"78631.20\",\"0.004\"],[\"78631.30\",\"0.001\"],[\"78631.40\",\"0.339\"],[\"78631.50\",\"0.001\"],[\"78631.60\",\"0.001\"],[\"78631.70\",\"0.027\"],[\"78631.80\",\"0.001\"],[\"78632.20\",\"0.001\"],[\"78632.40\",\"0.003\"],[\"78632.60\",\"0.027\"],[\"78632.90\",\"0.002\"]],\"st\":1}"}
{"received_at_ns": 1787373195734635156, "payload": "{\"e\":\"depthUpdate\",\"E\":1787373195667,\"T\":1787373195666,\"s\":\"BTCUSDT\",\"ps\":\"BTCUSDT\",\"U\":11351949998120,\"u\":11351950175697,\"pu\":11351949997775,\"b\":[[\"78630.20\",\"14.944\"],[\"78630.10\",\"0.003\"],[\"78630.00\",\"0.006\"],[\"78629.90\",\"1.022\"],[\"78629.30\",\"2.622\"],[\"78629.20\",\"0.186\"],[\"78629.10\",\"0.283\"],[\"78628.80\",\"0.004\"],[\"78628.50\",\"0.001\"],[\"78628.40\",\"0.026\"],[\"78628.00\",\"0.002\"],[\"78627.80\",\"0.001\"],[\"78627.60\",\"0.007\"],[\"78627.50\",\"0.001\"],[\"78627.30\",\"0.026\"],[\"78626.80\",\"0.001\"],[\"78626.70\",\"0.002\"],[\"78626.40\",\"0.027\"],[\"78626.20\",\"0.004\"],[\"78626.10\",\"0.001\"]],\"a\":[[\"78630.30\",\"0.158\"],[\"78630.60\",\"0.002\"],[\"78630.90\",\"0.002\"],[\"78631.20\",\"0.003\"],[\"78631.50\",\"0.001\"],[\"78631.70\",\"0.001\"],[\"78631.80\",\"0.001\"],[\"78632.60\",\"0.001\"],[\"78632.90\",\"0.001\"],[\"78633.10\",\"0.001\"],[\"78633.40\",\"0.002\"],[\"78633.60\",\"0.001\"],[\"78633.70\",\"0.011\"],[\"78634.10\",\"0.002\"],[\"78634.20\",\"0.207\"],[\"78634.30\",\"0.001\"],[\"78634.40\",\"0.002\"],[\"78634.50\",\"0.299\"],[\"78634.80\",\"0.039\"],[\"78634.90\",\"0.001\"]],\"st\":1}"}
{"received_at_ns": 1787373196238759848, "payload": "{\"e\":\"depthUpdate\",\"E\":1787373196171,\"T\":1787373196169,\"s\":\"BTCUSDT\",\"ps\":\"BTCUSDT\",\"U\":11351950175870,\"u\":11351950257912,\"pu\":11351950175697,\"b\":[[\"78634.70\",\"0.816\"],[\"78634.60\",\"0.001\"],[\"78634.50\",\"0.002\"],[\"78634.40\",\"0.004\"],[\"78633.20\",\"0.001\"],[\"78633.10\",\"0.001\"],[\"78632.60\",\"0.361\"],[\"78632.00\",\"0.001\"],[\"78631.60\",\"0.001\"],[\"78631.30\",\"0.001\"],[\"78631.20\",\"0.001\"],[\"78631.00\",\"0.001\"],[\"78630.90\",\"0.003\"],[\"78630.80\",\"0.001\"],[\"78630.60\",\"0.003\"],[\"78630.50\",\"0.293\"],[\"78630.30\",\"0.003\"],[\"78630.20\",\"0.006\"],[\"78630.10\",\"0.001\"],[\"78630.00\",\"0.002\"]],\"a\":[[\"78634.80\",\"2.359\"],[\"78634.90\",\"0.003\"],[\"78635.00\",\"0.001\"],[\"78635.20\",\"0.002\"],[\"78635.30\",\"0.027\"],[\"78635.60\",\"0.001\"],[\"78636.00\",\"0.001\"],[\"78636.10\",\"0.167\"],[\"78636.40\",\"0.002\"],[\"78636.50\",\"0.001\"],[\"78636.60\",\"0.339\"],[\"78636.80\",\"0.001\"],[\"78636.90\",\"0.026\"],[\"78637.20\",\"0.003\"],[\"78637.40\",\"0.001\"],[\"78637.70\",\"0.026\"],[\"78637.90\",\"0.208\"],[\"78638.00\",\"0.338\"],[\"78638.10\",\"0.256\"],[\"78638.20\",\"0.200\"]],\"st\":1}"}
{"received_at_ns": 1787373196742636579, "payload": "{\"e\":\"depthUpdate\",\"E\":1787373196675,\"T\":1787373196673,\"s\":\"BTCUSDT\",\"ps\":\"BTCUSDT\",\"U\":11351950258254,\"u\":11351950344988,\"pu\":11351950257912,\"b\":[[\"78634.70\",\"0.266\"],[\"78634.60\",\"0.001\"],[\"78634.50\",\"0.002\"],[\"78634.40\",\"0.004\"],[\"78633.20\",\"0.001\"],[\"78633.10\",\"0.001\"],[\"78632.60\",\"0.023\"],[\"78632.00\",\"0.001\"],[\"78631.60\",\"0.001\"],[\"78631.30\",\"0.001\"],[\"78631.20\",\"0.001\"],[\"78631.00\",\"0.001\"],[\"78630.90\",\"0.029\"],[\"78630.80\",\"0.001\"],[\"78630.60\",\"0.003\"],[\"78630.50\",\"0.293\"],[\"78630.30\",\"0.003\"],[\"78630.20\",\"0.004\"],[\"78630.10\",\"0.027\"],[\"78630.00\",\"0.002\"]],\"a\":[[\"78634.80\",\"9.125\"],[\"78634.90\",\"0.003\"],[\"78635.00\",\"0.001\"],[\"78635.20\",\"0.002\"],[\"78635.30\",\"0.027\"],[\"78635.60\",\"0.001\"],[\"78635.70\",\"0.002\"],[\"78636.00\",\"0.003\"],[\"78636.10\",\"0.167\"],[\"78636.40\",\"0.002\"],[\"78636.50\",\"0.001\"],[\"78636.60\",\"0.001\"],[\"78636.80\",\"0.001\"],[\"78636.90\",\"0.026\"],[\"78637.20\",\"0.003\"],[\"78637.40\",\"0.001\"],[\"78637.70\",\"0.026\"],[\"78637.90\",\"0.125\"],[\"78638.00\",\"0.001\"],[\"78638.10\",\"0.256\"]],\"st\":1}"}
{"received_at_ns": 1787373197246414061, "payload": "{\"e\":\"depthUpdate\",\"E\":1787373197179,\"T\":1787373197177,\"s\":\"BTCUSDT\",\"ps\":\"BTCUSDT\",\"U\":11351950345432,\"u\":11351950417101,\"pu\":11351950344988,\"b\":[[\"78634.70\",\"0.517\"],[\"78634.60\",\"0.002\"],[\"78634.50\",\"0.002\"],[\"78634.40\",\"0.004\"],[\"78633.20\",\"0.001\"],[\"78633.10\",\"0.001\"],[\"78632.60\",\"0.023\"],[\"78632.00\",\"0.001\"],[\"78631.60\",\"0.001\"],[\"78631.30\",\"0.001\"],[\"78631.20\",\"0.001\"],[\"78631.00\",\"0.001\"],[\"78630.90\",\"0.029\"],[\"78630.80\",\"0.001\"],[\"78630.60\",\"0.002\"],[\"78630.50\",\"0.293\"],[\"78630.30\",\"0.003\"],[\"78630.20\",\"0.004\"],[\"78630.10\",\"0.027\"],[\"78630.00\",\"0.002\"]],\"a\":[[\"78634.80\",\"9.036\"],[\"78634.90\",\"0.003\"],[\"78635.00\",\"0.001\"],[\"78635.20\",\"0.002\"],[\"78635.30\",\"0.027\"],[\"78635.60\",\"0.001\"],[\"78635.70\",\"0.002\"],[\"78636.00\",\"0.003\"],[\"78636.10\",\"0.167\"],[\"78636.40\",\"0.002\"],[\"78636.50\",\"0.003\"],[\"78636.60\",\"0.001\"],[\"78636.80\",\"0.003\"],[\"78636.90\",\"0.026\"],[\"78637.20\",\"0.003\"],[\"78637.40\",\"0.001\"],[\"78637.70\",\"0.026\"],[\"78637.90\",\"0.125\"],[\"78638.00\",\"0.001\"],[\"78638.10\",\"0.256\"]],\"st\":1}"}
{"received_at_ns": 1787373197750593593, "payload": "{\"e\":\"depthUpdate\",\"E\":1787373197683,\"T\":1787373197681,\"s\":\"BTCUSDT\",\"ps\":\"BTCUSDT\",\"U\":11351950417245,\"u\":11351950486236,\"pu\":11351950417101,\"b\":[[\"78634.70\",\"0.527\"],[\"78634.60\",\"0.002\"],[\"78634.50\",\"0.004\"],[\"78634.40\",\"0.004\"],[\"78633.20\",\"0.001\"],[\"78633.10\",\"0.001\"],[\"78632.60\",\"0.023\"],[\"78632.00\",\"0.001\"],[\"78631.60\",\"0.001\"],[\"78631.30\",\"0.001\"],[\"78631.20\",\"0.001\"],[\"78631.00\",\"0.001\"],[\"78630.90\",\"0.003\"],[\"78630.80\",\"0.001\"],[\"78630.60\",\"0.003\"],[\"78630.50\",\"0.293\"],[\"78630.30\",\"0.003\"],[\"78630.20\",\"0.004\"],[\"78630.10\",\"0.027\"],[\"78630.00\",\"0.008\"]],\"a\":[[\"78634.80\",\"8.697\"],[\"78634.90\",\"0.003\"],[\"78635.00\",\"0.001\"],[\"78635.20\",\"0.002\"],[\"78635.30\",\"0.027\"],[\"78635.60\",\"0.001\"],[\"78635.70\",\"0.002\"],[\"78636.00\",\"0.003\"],[\"78636.10\",\"0.167\"],[\"78636.40\",\"0.002\"],[\"78636.50\",\"0.003\"],[\"78636.60\",\"0.001\"],[\"78636.80\",\"0.003\"],[\"78636.90\",\"0.026\"],[\"78637.20\",\"0.003\"],[\"78637.30\",\"0.002\"],[\"78637.40\",\"0.001\"],[\"78637.60\",\"0.002\"],[\"78637.70\",\"0.026\"],[\"78637.90\",\"0.125\"]],\"st\":1}"}
{"received_at_ns": 1787373198254871674, "payload": "{\"e\":\"depthUpdate\",\"E\":1787373198187,\"T\":1787373198186,\"s\":\"BTCUSDT\",\"ps\":\"BTCUSDT\",\"U\":11351950486502,\"u\":11351950555578,\"pu\":11351950486236,\"b\":[[\"78634.70\",\"0.375\"],[\"78634.60\",\"0.002\"],[\"78634.50\",\"0.004\"],[\"78634.40\",\"0.004\"],[\"78633.20\",\"0.001\"],[\"78633.10\",\"0.001\"],[\"78632.60\",\"0.022\"],[\"78632.00\",\"0.001\"],[\"78631.60\",\"0.001\"],[\"78631.30\",\"0.001\"],[\"78631.20\",\"0.001\"],[\"78631.00\",\"0.002\"],[\"78630.90\",\"0.003\"],[\"78630.80\",\"0.001\"],[\"78630.60\",\"0.003\"],[\"78630.50\",\"0.293\"],[\"78630.30\",\"0.003\"],[\"78630.20\",\"0.004\"],[\"78630.10\",\"0.027\"],[\"78630.00\",\"0.008\"]],\"a\":[[\"78634.80\",\"8.526\"],[\"78634.90\",\"0.003\"],[\"78635.00\",\"0.001\"],[\"78635.20\",\"0.002\"],[\"78635.30\",\"0.027\"],[\"78635.60\",\"0.001\"],[\"78635.70\",\"0.002\"],[\"78636.00\",\"0.003\"],[\"78636.10\",\"0.167\"],[\"78636.40\",\"0.002\"],[\"78636.50\",\"0.003\"],[\"78636.60\",\"0.001\"],[\"78636.80\",\"0.003\"],[\"78636.90\",\"0.026\"],[\"78637.20\",\"0.003\"],[\"78637.30\",\"0.002\"],[\"78637.40\",\"0.001\"],[\"78637.60\",\"0.002\"],[\"78637.70\",\"0.026\"],[\"78637.90\",\"0.125\"]],\"st\":1}"}
{"received_at_ns": 1787373198758792646, "payload": "{\"e\":\"depthUpdate\",\"E\":1787373198691,\"T\":1787373198690,\"s\":\"BTCUSDT\",\"ps\":\"BTCUSDT\",\"U\":11351950555932,\"u\":11351950624163,\"pu\":11351950555578,\"b\":[[\"78634.70\",\"0.942\"],[\"78634.60\",\"0.002\"],[\"78634.50\",\"0.004\"],[\"78634.40\",\"0.004\"],[\"78633.20\",\"0.001\"],[\"78633.10\",\"0.001\"],[\"78633.00\",\"0.001\"],[\"78632.60\",\"0.360\"],[\"78632.00\",\"0.001\"],[\"78631.80\",\"0.026\"],[\"78631.60\",\"0.001\"],[\"78631.30\",\"0.001\"],[\"78631.20\",\"0.001\"],[\"78631.00\",\"0.028\"],[\"78630.90\",\"0.003\"],[\"78630.80\",\"0.001\"],[\"78630.70\",\"0.001\"],[\"78630.60\",\"0.003\"],[\"78630.50\",\"0.293\"],[\"78630.30\",\"0.003\"]],\"a\":[[\"78634.80\",\"2.845\"],[\"78634.90\",\"0.003\"],[\"78635.00\",\"0.001\"],[\"78635.20\",\"0.002\"],[\"78635.30\",\"0.001\"],[\"78635.60\",\"0.001\"],[\"78635.70\",\"0.002\"],[\"78636.00\",\"0.001\"],[\"78636.10\",\"0.167\"],[\"78636.40\",\"0.002\"],[\"78636.50\",\"0.003\"],[\"78636.60\",\"0.001\"],[\"78636.80\",\"0.003\"],[\"78636.90\",\"0.364\"],[\"78637.20\",\"0.003\"],[\"78637.30\",\"0.002\"],[\"78637.40\",\"0.001\"],[\"78637.60\",\"0.002\"],[\"78637.70\",\"0.026\"],[\"78637.90\",\"0.001\"]],\"st\":1}"}
{"received_at_ns": 1787373199262528236, "payload": "{\"e\":\"depthUpdate\",\"E\":1787373199195,\"T\":1787373199192,\"s\":\"BTCUSDT\",\"ps\":\"BTCUSDT\",\"U\":11351950624425,\"u\":11351950679346,\"pu\":11351950624163,\"b\":[[\"78634.70\",\"1.577\"],[\"78634.60\",\"0.002\"],[\"78634.50\",\"0.004\"],[\"78634.40\",\"0.004\"],[\"78634.20\",\"0.001\"],[\"78633.20\",\"0.001\"],[\"78633.10\",\"0.001\"],[\"78633.00\",\"0.001\"],[\"78632.70\",\"0.027\"],[\"78632.60\",\"0.360\"],[\"78632.00\",\"0.001\"],[\"78631.80\",\"0.026\"],[\"78631.60\",\"0.001\"],[\"78631.30\",\"0.001\"],[\"78631.20\",\"0.001\"],[\"78631.00\",\"0.028\"],[\"78630.90\",\"0.003\"],[\"78630.80\",\"0.001\"],[\"78630.70\",\"0.001\"],[\"78630.60\",\"0.003\"]],\"a\":[[\"78634.80\",\"1.888\"],[\"78634.90\",\"0.003\"],[\"78635.00\",\"0.001\"],[\"78635.20\",\"0.002\"],[\"78635.30\",\"0.001\"],[\"78635.60\",\"0.001\"],[\"78635.70\",\"0.002\"],[\"78636.00\",\"0.001\"],[\"78636.10\",\"0.141\"],[\"78636.40\",\"0.002\"],[\"78636.50\",\"0.003\"],[\"78636.60\",\"0.001\"],[\"78636.80\",\"0.003\"],[\"78636.90\",\"0.364\"],[\"78637.20\",\"0.003\"],[\"78637.30\",\"0.002\"],[\"78637.40\",\"0.001\"],[\"78637.60\",\"0.002\"],[\"78637.70\",\"0.026\"],[\"78637.90\",\"0.003\"]],\"st\":1}"}
{"received_at_ns": 1787373199766563147, "payload": "{\"e\":\"depthUpdate\",\"E\":1787373199699,\"T\":1787373199698,\"s\":\"BTCUSDT\",\"ps\":\"BTCUSDT\",\"U\":11351950679756,\"u\":11351950742268,\"pu\":11351950679346,\"b\":[[\"78634.70\",\"0.928\"],[\"78634.60\",\"0.002\"],[\"78634.50\",\"0.004\"],[\"78634.40\",\"0.004\"],[\"78633.20\",\"0.001\"],[\"78633.10\",\"0.001\"],[\"78633.00\",\"0.001\"],[\"78632.60\",\"0.360\"],[\"78632.00\",\"0.001\"],[\"78631.60\",\"0.001\"],[\"78631.30\",\"0.001\"],[\"78631.20\",\"0.001\"],[\"78631.00\",\"0.028\"],[\"78630.90\",\"0.003\"],[\"78630.80\",\"0.001\"],[\"78630.70\",\"0.001\"],[\"78630.60\",\"0.002\"],[\"78630.50\",\"0.293\"],[\"78630.30\",\"0.003\"],[\"78630.20\",\"0.004\"]],\"a\":[[\"78634.80\",\"2.680\"],[\"78634.90\",\"0.003\"],[\"78635.00\",\"0.001\"],[\"78635.20\",\"0.002\"],[\"78635.30\",\"0.027\"],[\"78635.60\",\"0.001\"],[\"78635.70\",\"0.002\"],[\"78636.00\",\"0.027\"],[\"78636.10\",\"0.141\"],[\"78636.40\",\"0.002\"],[\"78636.50\",\"0.003\"],[\"78636.60\",\"0.001\"],[\"78636.80\",\"0.003\"],[\"78636.90\",\"0.364\"],[\"78637.20\",\"0.003\"],[\"78637.30\",\"0.002\"],[\"78637.40\",\"0.001\"],[\"78637.60\",\"0.002\"],[\"78637.70\",\"0.026\"],[\"78637.90\",\"0.006\"]],\"st\":1}"}
{"received_at_ns": 1787373200270641729, "payload": "{\"e\":\"depthUpdate\",\"E\":1787373200203,\"T\":1787373200201,\"s\":\"BTCUSDT\",\"ps\":\"BTCUSDT\",\"U\":11351950742302,\"u\":11351950810951,\"pu\":11351950742268,\"b\":[[\"78634.70\",\"0.857\"],[\"78634.60\",\"0.002\"],[\"78634.50\",\"0.004\"],[\"78634.40\",\"0.004\"],[\"78633.20\",\"0.001\"],[\"78633.10\",\"0.001\"],[\"78633.00\",\"0.001\"],[\"78632.60\",\"0.022\"],[\"78632.00\",\"0.001\"],[\"78631.60\",\"0.001\"],[\"78631.30\",\"0.001\"],[\"78631.20\",\"0.001\"],[\"78631.10\",\"0.026\"],[\"78631.00\",\"0.001\"],[\"78630.90\",\"0.003\"],[\"78630.80\",\"0.001\"],[\"78630.70\",\"0.001\"],[\"78630.60\",\"0.003\"],[\"78630.50\",\"0.293\"],[\"78630.30\",\"0.003\"]],\"a\":[[\"78634.80\",\"3.463\"],[\"78634.90\",\"0.003\"],[\"78635.00\",\"0.001\"],[\"78635.20\",\"0.002\"],[\"78635.30\",\"0.027\"],[\"78635.60\",\"0.001\"],[\"78635.70\",\"0.002\"],[\"78636.00\",\"0.029\"],[\"78636.10\",\"0.141\"],[\"78636.30\",\"0.001\"],[\"78636.40\",\"0.002\"],[\"78636.50\",\"0.003\"],[\"78636.60\",\"0.001\"],[\"78636.80\",\"0.003\"],[\"78636.90\",\"0.364\"],[\"78637.20\",\"0.003\"],[\"78637.30\",\"0.002\"],[\"78637.40\",\"0.001\"],[\"78637.60\",\"0.002\"],[\"78637.70\",\"0.026\"]],\"st\":1}"}
{"received_at_ns": 1787373200774461399, "payload": "{\"e\":\"depthUpdate\",\"E\":1787373200707,\"T\":1787373200705,\"s\":\"BTCUSDT\",\"ps\":\"BTCUSDT\",\"U\":11351950811239,\"u\":11351950882123,\"pu\":11351950810951,\"b\":[[\"78634.70\",\"1.342\"],[\"78634.60\",\"0.002\"],[\"78634.50\",\"0.004\"],[\"78634.40\",\"0.004\"],[\"78633.30\",\"0.003\"],[\"78633.20\",\"0.001\"],[\"78633.10\",\"0.001\"],[\"78633.00\",\"0.001\"],[\"78632.60\",\"0.323\"],[\"78632.00\",\"0.001\"],[\"78631.70\",\"0.026\"],[\"78631.60\",\"0.001\"],[\"78631.30\",\"0.001\"],[\"78631.20\",\"0.001\"],[\"78631.00\",\"0.002\"],[\"78630.90\",\"0.029\"],[\"78630.80\",\"0.001\"],[\"78630.70\",\"0.001\"],[\"78630.60\",\"0.003\"],[\"78630.50\",\"0.293\"]],\"a\":[[\"78634.80\",\"3.139\"],[\"78634.90\",\"0.003\"],[\"78635.00\",\"0.001\"],[\"78635.20\",\"0.002\"],[\"78635.30\",\"0.001\"],[\"78635.60\",\"0.001\"],[\"78635.70\",\"0.002\"],[\"78636.00\",\"0.029\"],[\"78636.10\",\"0.141\"],[\"78636.40\",\"0.002\"],[\"78636.50\",\"0.003\"],[\"78636.60\",\"0.001\"],[\"78636.80\",\"0.003\"],[\"78636.90\",\"0.364\"],[\"78637.20\",\"0.003\"],[\"78637.30\",\"0.002\"],[\"78637.40\",\"0.001\"],[\"78637.60\",\"0.002\"],[\"78637.70\",\"0.026\"],[\"78637.90\",\"0.003\"]],\"st\":1}"}
{"received_at_ns": 1787373201278872731, "payload": "{\"e\":\"depthUpdate\",\"E\":1787373201211,\"T\":1787373201210,\"s\":\"BTCUSDT\",\"ps\":\"BTCUSDT\",\"U\":11351950882731,\"u\":11351950967139,\"pu\":11351950882123,\"b\":[[\"78634.70\",\"0.130\"],[\"78634.60\",\"0.002\"],[\"78634.50\",\"0.004\"],[\"78634.40\",\"0.004\"],[\"78633.30\",\"0.003\"],[\"78633.20\",\"0.001\"],[\"78633.10\",\"0.001\"],[\"78633.00\",\"0.001\"],[\"78632.60\",\"0.022\"],[\"78632.00\",\"0.001\"],[\"78631.30\",\"0.001\"],[\"78631.20\",\"0.001\"],[\"78631.00\",\"0.001\"],[\"78630.90\",\"0.003\"],[\"78630.80\",\"0.001\"],[\"78630.70\",\"0.002\"],[\"78630.60\",\"0.340\"],[\"78630.20\",\"0.004\"],[\"78630.10\",\"0.027\"],[\"78630.00\",\"0.012\"]],\"a\":[[\"78634.80\",\"9.800\"],[\"78634.90\",\"0.005\"],[\"78635.00\",\"0.001\"],[\"78635.20\",\"0.028\"],[\"78635.30\",\"0.001\"],[\"78635.60\",\"0.001\"],[\"78635.70\",\"0.002\"],[\"78636.00\",\"0.029\"],[\"78636.10\",\"0.141\"],[\"78636.30\",\"0.001\"],[\"78636.40\",\"0.002\"],[\"78636.50\",\"0.003\"],[\"78636.60\",\"0.001\"],[\"78636.80\",\"0.003\"],[\"78636.90\",\"0.026\"],[\"78637.20\",\"0.003\"],[\"78637.30\",\"0.002\"],[\"78637.40\",\"0.001\"],[\"78637.60\",\"0.002\"],[\"78637.70\",\"0.026\"]],\"st\":1}"}
{"received_at_ns": 1787373201783052986, "payload": "{\"e\":\"depthUpdate\",\"E\":1787373201715,\"T\":1787373201714,\"s\":\"BTCUSDT\",\"ps\":\"BTCUSDT\",\"U\":11351950967323,\"u\":11351951057647,\"pu\":11351950967139,\"b\":[[\"78632.00\",\"0.914\"],[\"78631.40\",\"0.002\"],[\"78631.30\",\"0.001\"],[\"78630.90\",\"0.002\"],[\"78630.80\",\"0.001\"],[\"78630.70\",\"0.001\"],[\"78630.60\",\"0.001\"],[\"78630.20\",\"0.001\"],[\"78630.10\",\"0.001\"],[\"78630.00\",\"0.012\"],[\"78629.60\",\"0.001\"],[\"78629.50\",\"0.001\"],[\"78629.20\",\"0.002\"],[\"78629.10\",\"0.005\"],[\"78628.80\",\"0.004\"],[\"78628.50\",\"0.028\"],[\"78628.40\",\"0.339\"],[\"78628.10\",\"0.001\"],[\"78628.00\",\"0.002\"],[\"78627.80\",\"0.002\"]],\"a\":[[\"78632.10\",\"10.258\"],[\"78632.20\",\"0.001\"],[\"78632.60\",\"0.205\"],[\"78632.70\",\"0.029\"],[\"78633.80\",\"0.001\"],[\"78633.90\",\"0.001\"],[\"78634.50\",\"0.001\"],[\"78634.70\",\"0.011\"],[\"78634.80\",\"0.380\"],[\"78634.90\",\"0.005\"],[\"78635.00\",\"0.001\"],[\"78635.20\",\"0.028\"],[\"78635.30\",\"0.002\"],[\"78635.60\",\"0.001\"],[\"78635.70\",\"0.002\"],[\"78635.90\",\"0.001\"],[\"78636.00\",\"0.029\"],[\"78636.10\",\"0.141\"],[\"78636.30\",\"0.012\"],[\"78636.40\",\"0.002\"]],\"st\":1}"}
{"received_at_ns": 1787373202286699902, "payload": "{\"e\":\"depthUpdate\",\"E\":1787373202219,\"T\":1787373202218,\"s\":\"BTCUSDT\",\"ps\":\"BTCUSDT\",\"U\":11351951057829,\"u\":11351951196090,\"pu\":11351951057647,\"b\":[[\"78643.30\",\"0.063\"],[\"78642.70\",\"0.001\"],[\"78642.60\",\"0.001\"],[\"78642.20\",\"0.001\"],[\"78642.10\",\"0.001\"],[\"78641.90\",\"0.001\"],[\"78640.80\",\"0.001\"],[\"78640.70\",\"0.001\"],[\"78640.50\",\"0.001\"],[\"78640.40\",\"0.001\"],[\"78640.20\",\"0.001\"],[\"78640.10\",\"0.329\"],[\"78640.00\",\"0.004\"],[\"78639.50\",\"0.002\"],[\"78639.40\",\"0.001\"],[\"78639.10\",\"0.002\"],[\"78638.90\",\"0.002\"],[\"78638.40\",\"0.001\"],[\"78638.30\",\"0.345\"],[\"78638.20\",\"0.002\"]],\"a\":[[\"78643.40\",\"7.051\"],[\"78644.30\",\"0.099\"],[\"78644.40\",\"9.247\"],[\"78644.50\",\"0.001\"],[\"78644.70\",\"0.026\"],[\"78644.80\",\"0.001\"],[\"78645.00\",\"0.002\"],[\"78645.10\",\"0.001\"],[\"78645.50\",\"0.001\"],[\"78645.60\",\"0.028\"],[\"78646.10\",\"0.130\"],[\"78646.20\",\"0.255\"],[\"78646.30\",\"0.002\"],[\"78646.40\",\"0.528\"],[\"78646.50\",\"0.001\"],[\"78646.70\",\"0.002\"],[\"78646.80\",\"0.300\"],[\"78647.00\",\"0.014\"],[\"78647.20\",\"0.026\"],[\"78647.30\",\"0.001\"]],\"st\":1}"}
{"received_at_ns": 1787373202790484700, "payload": "{\"e\":\"depthUpdate\",\"E\":1787373202723,\"T\":1787373202722,\"s\":\"BTCUSDT\",\"ps\":\"BTCUSDT\",\"U\":11351951196118,\"u\":11351951307462,\"pu\":11351951196090,\"b\":[[\"78643.30\",\"0.183\"],[\"78643.20\",\"0.004\"],[\"78643.00\",\"0.002\"],[\"78642.90\",\"0.002\"],[\"78642.70\",\"0.001\"],[\"78642.60\",\"0.001\"],[\"78642.20\",\"0.001\"],[\"78642.10\",\"0.001\"],[\"78641.90\",\"0.001\"],[\"78640.80\",\"0.001\"],[\"78640.70\",\"0.001\"],[\"78640.40\",\"0.001\"],[\"78640.00\",\"0.003\"],[\"78639.50\",\"0.002\"],[\"78639.40\",\"0.001\"],[\"78639.10\",\"0.002\"],[\"78638.90\",\"0.002\"],[\"78638.80\",\"0.001\"],[\"78638.40\",\"0.002\"],[\"78638.30\",\"0.339\"]],\"a\":[[\"78643.40\",\"14.477\"],[\"78643.50\",\"0.001\"],[\"78643.80\",\"0.001\"],[\"78643.90\",\"0.001\"],[\"78644.30\",\"0.001\"],[\"78644.40\",\"0.007\"],[\"78644.50\",\"0.002\"],[\"78644.70\",\"0.074\"],[\"78644.80\",\"0.001\"],[\"78645.00\",\"0.001\"],[\"78645.10\",\"0.002\"],[\"78645.50\",\"0.001\"],[\"78645.60\",\"0.028\"],[\"78645.90\",\"0.001\"],[\"78646.10\",\"0.129\"],[\"78646.20\",\"0.255\"],[\"78646.30\",\"0.003\"],[\"78646.40\",\"0.528\"],[\"78646.50\",\"0.001\"],[\"78646.70\",\"0.002\"]],\"st\":1}"}
{"received_at_ns": 1787373203295100208, "payload": "{\"e\":\"depthUpdate\",\"E\":1787373203227,\"T\":1787373203226,\"s\":\"BTCUSDT\",\"ps\":\"BTCUSDT\",\"U\":11351951307538,\"u\":11351951451233,\"pu\":11351951307462,\"b\":[[\"78643.30\",\"7.827\"],[\"78643.20\",\"0.009\"],[\"78643.00\",\"0.026\"],[\"78642.70\",\"0.011\"],[\"78642.40\",\"0.002\"],[\"78642.20\",\"0.002\"],[\"78642.10\",\"0.029\"],[\"78641.70\",\"0.002\"],[\"78641.60\",\"0.148\"],[\"78641.50\",\"0.255\"],[\"78641.30\",\"0.026\"],[\"78640.90\",\"0.001\"],[\"78640.80\",\"0.001\"],[\"78640.70\",\"0.002\"],[\"78640.40\",\"0.001\"],[\"78640.20\",\"0.001\"],[\"78640.10\",\"0.026\"],[\"78640.00\",\"0.004\"],[\"78639.50\",\"0.065\"],[\"78639.40\",\"0.002\"]],\"a\":[[\"78643.40\",\"1.733\"],[\"78643.50\",\"0.001\"],[\"78643.80\",\"0.001\"],[\"78643.90\",\"0.001\"],[\"78644.80\",\"0.001\"],[\"78645.00\",\"0.001\"],[\"78645.10\",\"0.002\"],[\"78645.50\",\"0.001\"],[\"78645.60\",\"0.002\"],[\"78645.90\",\"0.001\"],[\"78646.30\",\"0.003\"],[\"78646.40\",\"0.504\"],[\"78646.50\",\"0.001\"],[\"78646.70\",\"0.087\"],[\"78646.80\",\"0.300\"],[\"78647.00\",\"0.014\"],[\"78647.30\",\"0.001\"],[\"78647.50\",\"0.127\"],[\"78647.60\",\"0.027\"],[\"78647.80\",\"0.007\"]],\"st\":1}"}
{"received_at_ns": 1787373203798569773, "payload": "{\"e\":\"depthUpdate\",\"E\":1787373203731,\"T\":1787373203729,\"s\":\"BTCUSDT\",\"ps\":\"BTCUSDT\",\"U\":11351951451335,\"u\":11351951524472,\"pu\":11351951451233,\"b\":[[\"78643.30\",\"9.545\"],[\"78643.20\",\"0.009\"],[\"78643.00\",\"0.043\"],[\"78642.70\",\"0.001\"],[\"78642.40\",\"0.002\"],[\"78642.20\",\"0.001\"],[\"78642.10\",\"0.029\"],[\"78641.70\",\"0.004\"],[\"78641.60\",\"0.150\"],[\"78641.50\",\"0.255\"],[\"78641.30\",\"0.028\"],[\"78640.90\",\"0.256\"],[\"78640.80\",\"0.001\"],[\"78640.70\",\"0.002\"],[\"78640.40\",\"0.001\"],[\"78640.20\",\"0.001\"],[\"78640.10\",\"0.026\"],[\"78640.00\",\"0.004\"],[\"78639.80\",\"0.001\"],[\"78639.50\",\"0.002\"]],\"a\":[[\"78643.40\",\"0.410\"],[\"78643.50\",\"0.001\"],[\"78643.80\",\"0.001\"],[\"78643.90\",\"0.001\"],[\"78644.80\",\"0.001\"],[\"78645.00\",\"0.001\"],[\"78645.10\",\"0.002\"],[\"78645.50\",\"0.001\"],[\"78645.60\",\"0.002\"],[\"78645.90\",\"0.001\"],[\"78646.30\",\"0.003\"],[\"78646.40\",\"0.504\"],[\"78646.50\",\"0.001\"],[\"78646.70\",\"0.188\"],[\"78646.80\",\"0.300\"],[\"78647.00\",\"0.014\"],[\"78647.30\",\"0.001\"],[\"78647.60\",\"0.001\"],[\"78647.80\",\"0.007\"],[\"78647.90\",\"0.001\"]],\"st\":1}"}
{"received_at_ns": 1787373204302596555, "payload": "{\"e\":\"depthUpdate\",\"E\":1787373204235,\"T\":1787373204234,\"s\":\"BTCUSDT\",\"ps\":\"BTCUSDT\",\"U\":11351951524607,\"u\":11351951592869,\"pu\":11351951524472,\"b\":[[\"78643.30\",\"8.386\"],[\"78643.20\",\"0.007\"],[\"78643.10\",\"0.002\"],[\"78643.00\",\"0.036\"],[\"78642.70\",\"0.001\"],[\"78642.40\",\"0.002\"],[\"78642.20\",\"0.002\"],[\"78642.10\",\"0.029\"],[\"78641.70\",\"0.002\"],[\"78641.60\",\"0.150\"],[\"78641.50\",\"0.255\"],[\"78641.30\",\"0.028\"],[\"78640.90\",\"0.001\"],[\"78640.80\",\"0.003\"],[\"78640.70\",\"0.002\"],[\"78640.40\",\"0.001\"],[\"78640.20\",\"0.003\"],[\"78640.10\",\"0.026\"],[\"78640.00\",\"0.004\"],[\"78639.80\",\"0.001\"]],\"a\":[[\"78643.40\",\"0.574\"],[\"78643.50\",\"0.001\"],[\"78643.80\",\"0.001\"],[\"78643.90\",\"0.001\"],[\"78644.80\",\"0.001\"],[\"78645.00\",\"0.001\"],[\"78645.10\",\"0.002\"],[\"78645.50\",\"0.001\"],[\"78645.60\",\"0.002\"],[\"78645.90\",\"0.001\"],[\"78646.30\",\"0.002\"],[\"78646.40\",\"0.504\"],[\"78646.50\",\"0.001\"],[\"78646.70\",\"0.188\"],[\"78646.80\",\"0.300\"],[\"78647.00\",\"0.014\"],[\"78647.30\",\"0.001\"],[\"78647.50\",\"0.001\"],[\"78647.60\",\"0.366\"],[\"78647.80\",\"0.007\"]],\"st\":1}"}
{"received_at_ns": 1787373204806822036, "payload": "{\"e\":\"depthUpdate\",\"E\":1787373204739,\"T\":1787373204738,\"s\":\"BTCUSDT\",\"ps\":\"BTCUSDT\",\"U\":11351951593019,\"u\":11351951668126,\"pu\":11351951592869,\"b\":[[\"78643.30\",\"7.476\"],[\"78643.20\",\"0.009\"],[\"78643.00\",\"0.037\"],[\"78642.70\",\"0.001\"],[\"78642.40\",\"0.002\"],[\"78642.20\",\"0.002\"],[\"78642.10\",\"0.029\"],[\"78641.70\",\"0.002\"],[\"78641.60\",\"0.150\"],[\"78641.50\",\"0.255\"],[\"78641.30\",\"0.028\"],[\"78640.90\",\"0.001\"],[\"78640.80\",\"0.003\"],[\"78640.70\",\"0.002\"],[\"78640.40\",\"0.001\"],[\"78640.20\",\"0.003\"],[\"78640.10\",\"0.026\"],[\"78640.00\",\"0.006\"],[\"78639.80\",\"0.001\"],[\"78639.50\",\"0.065\"]],\"a\":[[\"78643.40\",\"1.082\"],[\"78643.50\",\"0.003\"],[\"78643.80\",\"0.001\"],[\"78643.90\",\"0.001\"],[\"78644.80\",\"0.001\"],[\"78645.00\",\"0.001\"],[\"78645.10\",\"0.002\"],[\"78645.50\",\"0.001\"],[\"78645.60\",\"0.002\"],[\"78645.90\",\"0.001\"],[\"78646.30\",\"0.334\"],[\"78646.40\",\"0.504\"],[\"78646.50\",\"0.001\"],[\"78646.70\",\"0.188\"],[\"78646.80\",\"0.326\"],[\"78647.00\",\"0.014\"],[\"78647.30\",\"0.001\"],[\"78647.60\",\"0.027\"],[\"78647.80\",\"0.007\"],[\"78647.90\",\"0.001\"]],\"st\":1}"}
{"received_at_ns": 1787373205310488803, "payload": "{\"e\":\"depthUpdate\",\"E\":1787373205243,\"T\":1787373205242,\"s\":\"BTCUSDT\",\"ps\":\"BTCUSDT\",\"U\":11351951668548,\"u\":11351951794389,\"pu\":11351951668126,\"b\":[[\"78649.90\",\"2.426\"],[\"78649.80\",\"0.001\"],[\"78649.60\",\"0.002\"],[\"78649.50\",\"0.001\"],[\"78649.40\",\"0.026\"],[\"78649.10\",\"0.001\"],[\"78648.30\",\"0.028\"],[\"78648.20\",\"0.001\"],[\"78648.00\",\"0.001\"],[\"78647.50\",\"0.001\"],[\"78647.40\",\"0.026\"],[\"78646.80\",\"0.001\"],[\"78646.60\",\"0.001\"],[\"78646.50\",\"0.001\"],[\"78646.30\",\"0.001\"],[\"78646.10\",\"0.001\"],[\"78646.00\",\"0.001\"],[\"78645.90\",\"0.001\"],[\"78645.70\",\"0.006\"],[\"78645.60\",\"0.003\"]],\"a\":[[\"78650.00\",\"3.727\"],[\"78650.10\",\"0.003\"],[\"78650.30\",\"0.001\"],[\"78650.50\",\"0.001\"],[\"78650.60\",\"0.002\"],[\"78651.10\",\"0.001\"],[\"78651.20\",\"0.002\"],[\"78651.30\",\"0.001\"],[\"78651.40\",\"0.001\"],[\"78651.80\",\"0.001\"],[\"78652.00\",\"0.001\"],[\"78652.10\",\"0.339\"],[\"78652.40\",\"0.001\"],[\"78652.50\",\"0.001\"],[\"78652.60\",\"0.001\"],[\"78652.80\",\"0.201\"],[\"78653.00\",\"0.026\"],[\"78653.30\",\"0.004\"],[\"78653.40\",\"0.008\"],[\"78653.70\",\"0.005\"]],\"st\":1}"}
{"received_at_ns": 1787373205814538527, "payload": "{\"e\":\"depthUpdate\",\"E\":1787373205747,\"T\":1787373205746,\"s\":\"BTCUSDT\",\"ps\":\"BTCUSDT\",\"U\":11351951794553,\"u\":11351951869409,\"pu\":11351951794389,\"b\":[[\"78649.90\",\"1.798\"],[\"78649.80\",\"0.003\"],[\"78649.70\",\"0.003\"],[\"78649.60\",\"0.001\"],[\"78649.50\",\"0.001\"],[\"78649.10\",\"0.002\"],[\"78648.30\",\"0.028\"],[\"78648.20\",\"0.001\"],[\"78648.00\",\"0.002\"],[\"78647.80\",\"0.339\"],[\"78647.50\",\"0.001\"],[\"78647.40\",\"0.026\"],[\"78646.80\",\"0.001\"],[\"78646.60\",\"0.002\"],[\"78646.50\",\"0.001\"],[\"78646.30\",\"0.256\"],[\"78646.10\",\"0.001\"],[\"78646.00\",\"0.001\"],[\"78645.90\",\"0.001\"],[\"78645.70\",\"0.345\"]],\"a\":[[\"78650.00\",\"4.029\"],[\"78650.10\",\"0.003\"],[\"78650.30\",\"0.001\"],[\"78650.50\",\"0.001\"],[\"78650.60\",\"0.002\"],[\"78651.10\",\"0.001\"],[\"78651.20\",\"0.002\"],[\"78651.30\",\"0.001\"],[\"78651.40\",\"0.001\"],[\"78651.80\",\"0.001\"],[\"78652.30\",\"0.026\"],[\"78652.40\",\"0.001\"],[\"78652.50\",\"0.002\"],[\"78652.60\",\"0.001\"],[\"78652.80\",\"0.201\"],[\"78653.00\",\"0.026\"],[\"78653.40\",\"0.008\"],[\"78653.70\",\"0.036\"],[\"78653.80\",\"0.007\"],[\"78653.90\",\"0.028\"]],\"st\":1}"}
{"received_at_ns": 1787373206318742439, "payload": "{\"e\":\"depthUpdate\",\"E\":1787373206251,\"T\":1787373206250,\"s\":\"BTCUSDT\",\"ps\":\"BTCUSDT\",\"U\":11351951869462,\"u\":11351951941438,\"pu\":11351951869409,\"b\":[[\"78649.90\",\"2.464\"],[\"78649.80\",\"0.003\"],[\"78649.70\",\"0.002\"],[\"78649.60\",\"0.002\"],[\"78649.50\",\"0.001\"],[\"78649.40\",\"0.026\"],[\"78649.10\",\"0.002\"],[\"78648.80\",\"0.003\"],[\"78648.30\",\"0.004\"],[\"78648.20\",\"0.027\"],[\"78648.00\",\"0.002\"],[\"78647.90\",\"0.055\"],[\"78647.80\",\"0.339\"],[\"78647.50\",\"0.001\"],[\"78647.40\",\"0.026\"],[\"78646.80\",\"0.147\"],[\"78646.60\",\"0.002\"],[\"78646.50\",\"0.001\"],[\"78646.30\",\"0.001\"],[\"78646.10\",\"0.001\"]],\"a\":[[\"78650.00\",\"3.236\"],[\"78650.10\",\"0.003\"],[\"78650.30\",\"0.001\"],[\"78650.50\",\"0.001\"],[\"78650.60\",\"0.002\"],[\"78651.10\",\"0.001\"],[\"78651.20\",\"0.002\"],[\"78651.30\",\"0.001\"],[\"78651.40\",\"0.001\"],[\"78651.80\",\"0.001\"],[\"78652.40\",\"0.001\"],[\"78652.50\",\"0.004\"],[\"78652.60\",\"0.001\"],[\"78652.80\",\"0.201\"],[\"78653.00\",\"0.026\"],[\"78653.40\",\"0.008\"],[\"78653.70\",\"0.036\"],[\"78653.80\",\"0.007\"],[\"78653.90\",\"0.028\"],[\"78654.00\",\"0.001\"]],\"st\":1}"}
{"received_at_ns": 1787373206822676762, "payload": "{\"e\":\"depthUpdate\",\"E\":1787373206755,\"T\":1787373206754,\"s\":\"BTCUSDT\",\"ps\":\"BTCUSDT\",\"U\":11351951941711,\"u\":11351951999401,\"pu\":11351951941438,\"b\":[[\"78649.90\",\"8.723\"],[\"78649.80\",\"0.080\"],[\"78649.70\",\"0.002\"],[\"78649.60\",\"0.002\"],[\"78649.50\",\"0.001\"],[\"78649.40\",\"0.026\"],[\"78649.10\",\"0.002\"],[\"78648.80\",\"0.003\"],[\"78648.30\",\"0.035\"],[\"78648.20\",\"0.104\"],[\"78648.00\",\"0.002\"],[\"78647.80\",\"0.063\"],[\"78647.60\",\"0.002\"],[\"78647.50\",\"0.001\"],[\"78647.40\",\"0.026\"],[\"78646.80\",\"0.147\"],[\"78646.60\",\"0.002\"],[\"78646.50\",\"0.001\"],[\"78646.30\",\"0.001\"],[\"78646.10\",\"0.001\"]],\"a\":[[\"78650.00\",\"3.146\"],[\"78650.10\",\"0.003\"],[\"78650.30\",\"0.001\"],[\"78650.50\",\"0.001\"],[\"78650.60\",\"0.002\"],[\"78650.70\",\"0.126\"],[\"78650.90\",\"0.002\"],[\"78651.10\",\"0.001\"],[\"78651.20\",\"0.002\"],[\"78651.30\",\"0.001\"],[\"78651.40\",\"0.001\"],[\"78651.80\",\"0.001\"],[\"78652.00\",\"0.017\"],[\"78652.40\",\"0.001\"],[\"78652.50\",\"0.003\"],[\"78652.60\",\"0.001\"],[\"78652.80\",\"0.201\"],[\"78653.40\",\"0.008\"],[\"78653.70\",\"0.036\"],[\"78653.80\",\"0.007\"]],\"st\":1}"}
