{"received_at_ns": 1787590747099054468, "payload": "{\"result\":null,\"id\":1}"}
{"received_at_ns": 1787590747485212567, "payload": "{\"e\":\"depthUpdate\",\"E\":1787590747417,\"T\":1787590747416,\"s\":\"BTCUSDT\",\"ps\":\"BTCUSDT\",\"U\":11376697221648,\"u\":11376697268574,\"pu\":11376697221612,\"b\":[[\"79023.20\",\"2.960\"],[\"79023.00\",\"0.201\"],[\"79022.90\",\"0.004\"],[\"79022.70\",\"0.001\"],[\"79022.20\",\"0.001\"],[\"79021.90\",\"0.001\"],[\"79021.70\",\"0.003\"],[\"79021.60\",\"0.003\"],[\"79021.50\",\"0.001\"],[\"79021.40\",\"0.001\"],[\"79021.30\",\"0.003\"],[\"79021.20\",\"0.010\"],[\"79021.10\",\"0.129\"],[\"79021.00\",\"0.003\"],[\"79020.90\",\"0.002\"],[\"79020.70\",\"0.001\"],[\"79020.50\",\"0.002\"],[\"79020.30\",\"0.002\"],[\"79020.00\",\"0.155\"],[\"79019.60\",\"0.005\"]],\"a\":[[\"79023.30\",\"2.406\"],[\"79023.40\",\"0.257\"],[\"79023.50\",\"0.002\"],[\"79023.60\",\"0.002\"],[\"79024.50\",\"0.001\"],[\"79024.60\",\"0.003\"],[\"79024.80\",\"0.002\"],[\"79024.90\",\"0.001\"],[\"79025.00\",\"0.002\"],[\"79025.50\",\"0.002\"],[\"79025.80\",\"0.002\"],[\"79026.40\",\"0.001\"],[\"79026.50\",\"0.083\"],[\"79026.80\",\"0.002\"],[\"79027.00\",\"0.004\"],[\"79027.10\",\"0.096\"],[\"79027.20\",\"0.150\"],[\"79027.30\",\"0.442\"],[\"79027.70\",\"0.030\"],[\"79027.80\",\"0.255\"]],\"st\":1}"}
{"received_at_ns": 1787590747989171791, "payload": "{\"e\":\"depthUpdate\",\"E\":1787590747921,\"T\":1787590747920,\"s\":\"BTCUSDT\",\"ps\":\"BTCUSDT\",\"U\":11376697268713,\"u\":11376697313680,\"pu\":11376697268574,\"b\":[[\"79023.20\",\"2.933\"],[\"79023.00\",\"0.201\"],[\"79022.90\",\"0.004\"],[\"79022.70\",\"0.001\"],[\"79022.20\",\"0.001\"],[\"79021.90\",\"0.001\"],[\"79021.70\",\"0.003\"],[\"79021.60\",\"0.004\"],[\"79021.50\",\"0.002\"],[\"79021.40\",\"0.001\"],[\"79021.30\",\"0.003\"],[\"79021.20\",\"0.010\"],[\"79021.10\",\"0.129\"],[\"79021.00\",\"0.003\"],[\"79020.90\",\"0.002\"],[\"79020.70\",\"0.001\"],[\"79020.50\",\"0.002\"],[\"79020.30\",\"0.002\"],[\"79020.00\",\"0.155\"],[\"79019.60\",\"0.005\"]],\"a\":[[\"79023.30\",\"1.374\"],[\"79023.40\",\"0.003\"],[\"79023.50\",\"0.002\"],[\"79023.60\",\"0.002\"],[\"79024.60\",\"0.003\"],[\"79024.80\",\"0.002\"],[\"79024.90\",\"0.001\"],[\"79025.00\",\"0.002\"],[\"79025.50\",\"0.002\"],[\"79025.80\",\"0.002\"],[\"79026.30\",\"0.002\"],[\"79026.40\",\"0.001\"],[\"79027.00\",\"0.011\"],[\"79027.10\",\"0.096\"],[\"79027.20\",\"0.150\"],[\"79027.30\",\"0.443\"],[\"79027.60\",\"0.002\"],[\"79027.70\",\"0.030\"],[\"79027.80\",\"0.255\"],[\"79028.20\",\"0.002\"]],\"st\":1}"}
{"received_at_ns": 1787590748493262426, "payload": "{\"e\":\"depthUpdate\",\"E\":1787590748425,\"T\":1787590748424,\"s\":\"BTCUSDT\",\"ps\":\"BTCUSDT\",\"U\":11376697313792,\"u\":11376697439980,\"pu\":11376697313680,\"b\":[[\"79039.00\",\"8.154\"],[\"79038.90\",\"0.255\"],[\"79038.80\",\"0.001\"],[\"79038.70\",\"0.200\"],[\"79037.60\",\"0.002\"],[\"79037.30\",\"0.002\"],[\"79037.20\",\"0.001\"],[\"79036.90\",\"0.001\"],[\"79036.50\",\"0.001\"],[\"79036.40\",\"0.043\"],[\"79036.10\",\"0.002\"],[\"79036.00\",\"0.076\"],[\"79035.90\",\"0.004\"],[\"79035.60\",\"0.003\"],[\"79035.50\",\"0.003\"],[\"79035.40\",\"0.004\"],[\"79035.30\",\"0.003\"],[\"79035.20\",\"0.001\"],[\"79035.00\",\"0.002\"],[\"79034.80\",\"0.001\"]],\"a\":[[\"79039.10\",\"0.282\"],[\"79039.20\",\"0.002\"],[\"79039.30\",\"0.001\"],[\"79039.40\",\"0.001\"],[\"79039.80\",\"0.001\"],[\"79040.00\",\"0.003\"],[\"79040.10\",\"0.010\"],[\"79040.60\",\"0.001\"],[\"79040.70\",\"0.002\"],[\"79040.80\",\"0.002\"],[\"79041.30\",\"0.001\"],[\"79041.40\",\"0.001\"],[\"79041.50\",\"0.001\"],[\"79041.60\",\"0.003\"],[\"79041.80\",\"0.002\"],[\"79041.90\",\"0.002\"],[\"79042.00\",\"0.001\"],[\"79042.10\",\"0.001\"],[\"79042.20\",\"0.009\"],[\"79042.30\",\"0.003\"]],\"st\":1}"}
{"received_at_ns": 1787590748997241820, "payload": "{\"e\":\"depthUpdate\",\"E\":1787590748929,\"T\":1787590748928,\"s\":\"BTCUSDT\",\"ps\":\"BTCUSDT\",\"U\":11376697440010,\"u\":11376697521786,\"pu\":11376697439980,\"b\":[[\"79039.00\",\"7.020\"],[\"79038.90\",\"0.258\"],[\"79038.80\",\"0.001\"],[\"79038.70\",\"0.200\"],[\"79037.60\",\"0.002\"],[\"79037.30\",\"0.002\"],[\"79037.20\",\"0.001\"],[\"79036.90\",\"0.001\"],[\"79036.80\",\"0.002\"],[\"79036.50\",\"0.001\"],[\"79036.40\",\"0.003\"],[\"79036.10\",\"0.002\"],[\"79036.00\",\"0.075\"],[\"79035.90\",\"0.004\"],[\"79035.60\",\"0.003\"],[\"79035.50\",\"0.003\"],[\"79035.30\",\"0.003\"],[\"79035.20\",\"0.002\"],[\"79035.00\",\"0.002\"],[\"79034.80\",\"0.001\"]],\"a\":[[\"79039.10\",\"0.324\"],[\"79039.30\",\"0.001\"],[\"79039.40\",\"0.001\"],[\"79039.50\",\"0.002\"],[\"79039.80\",\"0.001\"],[\"79040.00\",\"0.003\"],[\"79040.10\",\"0.010\"],[\"79040.60\",\"0.001\"],[\"79040.90\",\"0.001\"],[\"79041.30\",\"0.001\"],[\"79041.40\",\"0.001\"],[\"79041.50\",\"0.001\"],[\"79041.60\",\"0.003\"],[\"79041.80\",\"0.002\"],[\"79041.90\",\"0.002\"],[\"79042.00\",\"0.001\"],[\"79042.10\",\"0.001\"],[\"79042.20\",\"0.007\"],[\"79042.30\",\"0.042\"],[\"79042.40\",\"0.002\"]],\"st\":1}"}
{"received_at_ns": 1787590749501223145, "payload": "{\"e\":\"depthUpdate\",\"E\":1787590749433,\"T\":1787590749431,\"s\":\"BTCUSDT\",\"ps\":\"BTCUSDT\",\"U\":11376697521817,\"u\":11376697575122,\"pu\":11376697521786,\"b\":[[\"79039.00\",\"6.259\"],[\"79038.90\",\"0.255\"],[\"79038.80\",\"0.001\"],[\"79038.70\",\"0.200\"],[\"79037.60\",\"0.002\"],[\"79037.30\",\"0.002\"],[\"79037.20\",\"0.001\"],[\"79036.90\",\"0.001\"],[\"79036.80\",\"0.002\"],[\"79036.50\",\"0.001\"],[\"79036.40\",\"0.003\"],[\"79036.10\",\"0.004\"],[\"79036.00\",\"0.077\"],[\"79035.90\",\"0.004\"],[\"79035.60\",\"0.003\"],[\"79035.50\",\"0.003\"],[\"79035.30\",\"0.003\"],[\"79035.20\",\"0.002\"],[\"79035.00\",\"0.014\"],[\"79034.90\",\"0.202\"]],\"a\":[[\"79039.10\",\"0.129\"],[\"79039.30\",\"0.001\"],[\"79039.40\",\"0.001\"],[\"79039.50\",\"0.002\"],[\"79039.80\",\"0.001\"],[\"79040.00\",\"0.003\"],[\"79040.10\",\"0.010\"],[\"79040.60\",\"0.001\"],[\"79040.90\",\"0.001\"],[\"79041.30\",\"0.001\"],[\"79041.40\",\"0.001\"],[\"79041.50\",\"0.001\"],[\"79041.60\",\"0.003\"],[\"79041.80\",\"0.002\"],[\"79041.90\",\"0.002\"],[\"79042.00\",\"0.001\"],[\"79042.10\",\"0.001\"],[\"79042.20\",\"0.007\"],[\"79042.30\",\"0.004\"],[\"79042.40\",\"0.002\"]],\"st\":1}"}
{"received_at_ns": 1787590750005276799, "payload": "{\"e\":\"depthUpdate\",\"E\":1787590749937,\"T\":1787590749934,\"s\":\"BTCUSDT\",\"ps\":\"BTCUSDT\",\"U\":11376697575403,\"u\":11376697624050,\"pu\":11376697575122,\"b\":[[\"79039.00\",\"4.952\"],[\"79038.90\",\"0.255\"],[\"79038.80\",\"0.001\"],[\"79038.70\",\"0.200\"],[\"79037.60\",\"0.002\"],[\"79037.30\",\"0.002\"],[\"79037.20\",\"0.001\"],[\"79036.90\",\"0.001\"],[\"79036.80\",\"0.002\"],[\"79036.50\",\"0.003\"],[\"79036.40\",\"0.003\"],[\"79036.00\",\"0.077\"],[\"79035.90\",\"0.004\"],[\"79035.60\",\"0.005\"],[\"79035.50\",\"0.003\"],[\"79035.30\",\"0.003\"],[\"79035.20\",\"0.001\"],[\"79035.00\",\"0.014\"],[\"79034.90\",\"0.104\"],[\"79034.80\",\"0.001\"]],\"a\":[[\"79039.10\",\"2.493\"],[\"79039.20\",\"0.001\"],[\"79039.30\",\"0.001\"],[\"79039.40\",\"0.001\"],[\"79039.50\",\"0.002\"],[\"79039.80\",\"0.001\"],[\"79039.90\",\"0.001\"],[\"79040.00\",\"0.003\"],[\"79040.10\",\"0.010\"],[\"79040.60\",\"0.001\"],[\"79040.90\",\"0.001\"],[\"79041.20\",\"0.146\"],[\"79041.30\",\"0.001\"],[\"79041.40\",\"0.001\"],[\"79041.50\",\"0.001\"],[\"79041.60\",\"0.003\"],[\"79041.70\",\"0.003\"],[\"79041.80\",\"0.002\"],[\"79041.90\",\"0.002\"],[\"79042.00\",\"0.001\"]],\"st\":1}"}
{"received_at_ns": 1787590750509413264, "payload": "{\"e\":\"depthUpdate\",\"E\":1787590750441,\"T\":1787590750439,\"s\":\"BTCUSDT\",\"ps\":\"BTCUSDT\",\"U\":11376697624368,\"u\":11376697676567,\"pu\":11376697624050,\"b\":[[\"79039.00\",\"5.165\"],[\"79038.90\",\"0.255\"],[\"79038.80\",\"0.001\"],[\"79038.70\",\"0.200\"],[\"79038.50\",\"0.002\"],[\"79037.60\",\"0.002\"],[\"79037.30\",\"0.002\"],[\"79037.20\",\"0.001\"],[\"79037.00\",\"0.003\"],[\"79036.90\",\"0.002\"],[\"79036.80\",\"0.002\"],[\"79036.60\",\"0.001\"],[\"79036.50\",\"0.001\"],[\"79036.40\",\"0.003\"],[\"79036.00\",\"0.077\"],[\"79035.90\",\"0.004\"],[\"79035.60\",\"0.008\"],[\"79035.50\",\"0.003\"],[\"79035.30\",\"0.003\"],[\"79035.20\",\"0.001\"]],\"a\":[[\"79039.10\",\"0.857\"],[\"79039.20\",\"0.001\"],[\"79039.30\",\"0.001\"],[\"79039.40\",\"0.001\"],[\"79039.50\",\"0.002\"],[\"79039.80\",\"0.003\"],[\"79039.90\",\"0.001\"],[\"79040.00\",\"0.003\"],[\"79040.10\",\"0.010\"],[\"79040.60\",\"0.001\"],[\"79040.90\",\"0.001\"],[\"79041.10\",\"0.002\"],[\"79041.30\",\"0.001\"],[\"79041.40\",\"0.001\"],[\"79041.50\",\"0.001\"],[\"79041.60\",\"0.003\"],[\"79041.80\",\"0.002\"],[\"79041.90\",\"0.002\"],[\"79042.00\",\"0.001\"],[\"79042.10\",\"0.001\"]],\"st\":1}"}
{"received_at_ns": 1787590751013796128, "payload": "{\"e\":\"depthUpdate\",\"E\":1787590750945,\"T\":1787590750941,\"s\":\"BTCUSDT\",\"ps\":\"BTCUSDT\",\"U\":11376697676732,\"u\":11376697718105,\"pu\":11376697676567,\"b\":[[\"79039.00\",\"5.130\"],[\"79038.90\",\"0.255\"],[\"79038.80\",\"0.001\"],[\"79038.70\",\"0.200\"],[\"79037.60\",\"0.002\"],[\"79037.30\",\"0.002\"],[\"79037.20\",\"0.001\"],[\"79036.90\",\"0.002\"],[\"79036.80\",\"0.076\"],[\"79036.60\",\"0.001\"],[\"79036.50\",\"0.001\"],[\"79036.40\",\"0.003\"],[\"79036.10\",\"0.002\"],[\"79036.00\",\"0.003\"],[\"79035.90\",\"0.004\"],[\"79035.60\",\"0.006\"],[\"79035.50\",\"0.003\"],[\"79035.30\",\"0.003\"],[\"79035.20\",\"0.001\"],[\"79035.10\",\"0.002\"]],\"a\":[[\"79039.10\",\"2.575\"],[\"79039.20\",\"0.001\"],[\"79039.30\",\"0.001\"],[\"79039.40\",\"0.001\"],[\"79039.50\",\"0.002\"],[\"79039.80\",\"0.003\"],[\"79039.90\",\"0.001\"],[\"79040.00\",\"0.003\"],[\"79040.10\",\"0.010\"],[\"79040.60\",\"0.003\"],[\"79040.80\",\"0.002\"],[\"79040.90\",\"0.001\"],[\"79041.30\",\"0.001\"],[\"79041.40\",\"0.001\"],[\"79041.50\",\"0.001\"],[\"79041.60\",\"0.003\"],[\"79041.80\",\"0.002\"],[\"79041.90\",\"0.002\"],[\"79042.00\",\"0.001\"],[\"79042.10\",\"0.001\"]],\"st\":1}"}
{"received_at_ns": 1787590751517610143, "payload": "{\"e\":\"depthUpdate\",\"E\":1787590751449,\"T\":1787590751448,\"s\":\"BTCUSDT\",\"ps\":\"BTCUSDT\",\"U\":11376697718329,\"u\":11376697783724,\"pu\":11376697718105,\"b\":[[\"79039.00\",\"5.132\"],[\"79038.90\",\"0.255\"],[\"79038.80\",\"0.001\"],[\"79038.70\",\"0.200\"],[\"79037.60\",\"0.002\"],[\"79037.40\",\"0.002\"],[\"79037.30\",\"0.002\"],[\"79037.20\",\"0.001\"],[\"79036.90\",\"0.002\"],[\"79036.80\",\"0.076\"],[\"79036.50\",\"0.001\"],[\"79036.40\",\"0.003\"],[\"79036.00\",\"0.003\"],[\"79035.90\",\"0.004\"],[\"79035.60\",\"0.006\"],[\"79035.50\",\"0.003\"],[\"79035.30\",\"0.003\"],[\"79035.20\",\"0.001\"],[\"79035.00\",\"0.016\"],[\"79034.90\",\"0.126\"]],\"a\":[[\"79039.10\",\"1.721\"],[\"79039.30\",\"0.001\"],[\"79039.40\",\"0.001\"],[\"79039.50\",\"0.002\"],[\"79039.80\",\"0.003\"],[\"79040.00\",\"0.003\"],[\"79040.10\",\"0.010\"],[\"79040.60\",\"0.003\"],[\"79040.70\",\"0.001\"],[\"79040.90\",\"0.001\"],[\"79041.30\",\"0.001\"],[\"79041.40\",\"0.003\"],[\"79041.50\",\"0.001\"],[\"79041.60\",\"0.003\"],[\"79041.80\",\"0.002\"],[\"79041.90\",\"0.043\"],[\"79042.00\",\"0.001\"],[\"79042.10\",\"0.001\"],[\"79042.20\",\"0.007\"],[\"79042.30\",\"0.004\"]],\"st\":1}"}
{"received_at_ns": 1787590752021300627, "payload": "{\"e\":\"depthUpdate\",\"E\":1787590751953,\"T\":1787590751951,\"s\":\"BTCUSDT\",\"ps\":\"BTCUSDT\",\"U\":11376697783888,\"u\":11376697828819,\"pu\":11376697783724,\"b\":[[\"79039.00\",\"5.198\"],[\"79038.90\",\"0.256\"],[\"79038.80\",\"0.002\"],[\"79038.70\",\"0.200\"],[\"79037.60\",\"0.002\"],[\"79037.30\",\"0.002\"],[\"79037.20\",\"0.001\"],[\"79036.90\",\"0.150\"],[\"79036.80\",\"0.076\"],[\"79036.60\",\"0.001\"],[\"79036.50\",\"0.001\"],[\"79036.40\",\"0.003\"],[\"79036.00\",\"0.003\"],[\"79035.90\",\"0.004\"],[\"79035.60\",\"0.006\"],[\"79035.50\",\"0.003\"],[\"79035.40\",\"0.003\"],[\"79035.30\",\"0.003\"],[\"79035.20\",\"0.001\"],[\"79035.00\",\"0.016\"]],\"a\":[[\"79039.10\",\"0.566\"],[\"79039.30\",\"0.001\"],[\"79039.40\",\"0.001\"],[\"79039.50\",\"0.002\"],[\"79039.80\",\"0.003\"],[\"79040.00\",\"0.003\"],[\"79040.10\",\"0.010\"],[\"79040.60\",\"0.003\"],[\"79040.90\",\"0.001\"],[\"79041.30\",\"0.001\"],[\"79041.40\",\"0.003\"],[\"79041.50\",\"0.001\"],[\"79041.60\",\"0.003\"],[\"79041.80\",\"0.002\"],[\"79041.90\",\"0.004\"],[\"79042.00\",\"0.001\"],[\"79042.10\",\"0.001\"],[\"79042.20\",\"0.009\"],[\"79042.30\",\"0.004\"],[\"79042.40\",\"0.002\"]],\"st\":1}"}
{"received_at_ns": 1787590752525207482, "payload": "{\"e\":\"depthUpdate\",\"E\":1787590752457,\"T\":1787590752456,\"s\":\"BTCUSDT\",\"ps\":\"BTCUSDT\",\"U\":11376697829315,\"u\":11376697875707,\"pu\":11376697828819,\"b\":[[\"79039.00\",\"5.049\"],[\"79038.90\",\"0.255\"],[\"79038.80\",\"0.001\"],[\"79038.70\",\"0.200\"],[\"79037.60\",\"0.002\"],[\"79037.30\",\"0.002\"],[\"79037.20\",\"0.001\"],[\"79037.00\",\"0.002\"],[\"79036.90\",\"0.002\"],[\"79036.80\",\"0.076\"],[\"79036.60\",\"0.001\"],[\"79036.50\",\"0.001\"],[\"79036.40\",\"0.003\"],[\"79036.00\",\"0.003\"],[\"79035.90\",\"0.004\"],[\"79035.60\",\"0.006\"],[\"79035.50\",\"0.003\"],[\"79035.30\",\"0.003\"],[\"79035.20\",\"0.001\"],[\"79035.00\",\"0.016\"]],\"a\":[[\"79039.10\",\"2.172\"],[\"79039.20\",\"0.001\"],[\"79039.30\",\"0.001\"],[\"79039.40\",\"0.001\"],[\"79039.50\",\"0.002\"],[\"79039.80\",\"0.003\"],[\"79039.90\",\"0.001\"],[\"79040.00\",\"0.003\"],[\"79040.10\",\"0.010\"],[\"79040.60\",\"0.003\"],[\"79040.90\",\"0.001\"],[\"79041.30\",\"0.001\"],[\"79041.40\",\"0.003\"],[\"79041.50\",\"0.001\"],[\"79041.60\",\"0.003\"],[\"79041.80\",\"0.002\"],[\"79041.90\",\"0.002\"],[\"79042.00\",\"0.001\"],[\"79042.10\",\"0.001\"],[\"79042.20\",\"0.009\"]],\"st\":1}"}
{"received_at_ns": 1787590753029408766, "payload": "{\"e\":\"depthUpdate\",\"E\":1787590752961,\"T\":1787590752960,\"s\":\"BTCUSDT\",\"ps\":\"BTCUSDT\",\"U\":11376697875797,\"u\":11376697916528,\"pu\":11376697875707,\"b\":[[\"79039.00\",\"3.797\"],[\"79038.90\",\"0.255\"],[\"79038.80\",\"0.001\"],[\"79038.70\",\"0.200\"],[\"79037.60\",\"0.002\"],[\"79037.30\",\"0.002\"],[\"79037.20\",\"0.001\"],[\"79036.80\",\"0.076\"],[\"79036.50\",\"0.001\"],[\"79036.40\",\"0.002\"],[\"79036.00\",\"0.003\"],[\"79035.90\",\"0.001\"],[\"79035.20\",\"0.001\"],[\"79035.00\",\"0.014\"],[\"79034.80\",\"0.001\"],[\"79034.60\",\"0.003\"],[\"79034.50\",\"0.001\"],[\"79034.40\",\"0.001\"],[\"79034.30\",\"0.001\"],[\"79033.90\",\"0.003\"]],\"a\":[[\"79039.10\",\"2.626\"],[\"79039.20\",\"0.001\"],[\"79039.30\",\"0.001\"],[\"79039.40\",\"0.001\"],[\"79039.50\",\"0.002\"],[\"79039.80\",\"0.003\"],[\"79039.90\",\"0.001\"],[\"79040.00\",\"0.003\"],[\"79040.10\",\"0.010\"],[\"79040.30\",\"0.002\"],[\"79040.60\",\"0.003\"],[\"79040.90\",\"0.001\"],[\"79041.00\",\"0.114\"],[\"79041.10\",\"0.003\"],[\"79041.20\",\"0.146\"],[\"79041.30\",\"0.001\"],[\"79041.40\",\"0.003\"],[\"79041.50\",\"0.001\"],[\"79041.60\",\"0.003\"],[\"79041.80\",\"0.002\"]],\"st\":1}"}
{"received_at_ns": 1787590753533632831, "payload": "{\"e\":\"depthUpdate\",\"E\":1787590753465,\"T\":1787590753464,\"s\":\"BTCUSDT\",\"ps\":\"BTCUSDT\",\"U\":11376697916549,\"u\":11376697994028,\"pu\":11376697916528,\"b\":[[\"79039.00\",\"2.680\"],[\"79038.90\",\"0.254\"],[\"79038.80\",\"0.002\"],[\"79038.70\",\"0.200\"],[\"79037.60\",\"0.002\"],[\"79037.30\",\"0.002\"],[\"79037.20\",\"0.001\"],[\"79036.90\",\"0.146\"],[\"79036.80\",\"0.076\"],[\"79036.50\",\"0.002\"],[\"79036.40\",\"0.001\"],[\"79036.00\",\"0.003\"],[\"79035.90\",\"0.001\"],[\"79035.20\",\"0.001\"],[\"79035.00\",\"0.002\"],[\"79034.80\",\"0.147\"],[\"79034.60\",\"0.003\"],[\"79034.50\",\"0.001\"],[\"79034.40\",\"0.001\"],[\"79034.30\",\"0.001\"]],\"a\":[[\"79039.10\",\"2.344\"],[\"79039.20\",\"0.001\"],[\"79039.30\",\"0.001\"],[\"79039.40\",\"0.001\"],[\"79039.50\",\"0.002\"],[\"79039.80\",\"0.003\"],[\"79039.90\",\"0.001\"],[\"79040.00\",\"0.328\"],[\"79040.10\",\"0.010\"],[\"79040.30\",\"0.002\"],[\"79040.60\",\"0.003\"],[\"79040.90\",\"0.005\"],[\"79041.00\",\"0.480\"],[\"79041.10\",\"0.005\"],[\"79041.30\",\"0.001\"],[\"79041.40\",\"0.003\"],[\"79041.50\",\"0.001\"],[\"79041.60\",\"0.004\"],[\"79041.80\",\"0.186\"],[\"79041.90\",\"1.894\"]],\"st\":1}"}
{"received_at_ns": 1787590754037355005, "payload": "{\"e\":\"depthUpdate\",\"E\":1787590753969,\"T\":1787590753968,\"s\":\"BTCUSDT\",\"ps\":\"BTCUSDT\",\"U\":11376697994217,\"u\":11376698052657,\"pu\":11376697994028,\"b\":[[\"79039.00\",\"2.367\"],[\"79038.90\",\"0.254\"],[\"79038.80\",\"0.003\"],[\"79038.70\",\"0.200\"],[\"79037.60\",\"0.002\"],[\"79037.30\",\"0.002\"],[\"79037.20\",\"0.001\"],[\"79036.90\",\"0.146\"],[\"79036.80\",\"0.076\"],[\"79036.60\",\"0.001\"],[\"79036.50\",\"0.002\"],[\"79036.40\",\"0.001\"],[\"79036.00\",\"0.003\"],[\"79035.90\",\"0.001\"],[\"79035.30\",\"0.001\"],[\"79035.20\",\"0.001\"],[\"79035.00\",\"0.002\"],[\"79034.80\",\"0.147\"],[\"79034.60\",\"0.003\"],[\"79034.50\",\"0.001\"]],\"a\":[[\"79039.10\",\"2.017\"],[\"79039.20\",\"0.001\"],[\"79039.30\",\"0.001\"],[\"79039.40\",\"0.001\"],[\"79039.50\",\"0.002\"],[\"79039.80\",\"0.003\"],[\"79039.90\",\"0.001\"],[\"79040.00\",\"0.328\"],[\"79040.10\",\"0.010\"],[\"79040.30\",\"0.002\"],[\"79040.60\",\"0.003\"],[\"79040.90\",\"0.001\"],[\"79041.00\",\"0.337\"],[\"79041.10\",\"0.005\"],[\"79041.30\",\"0.001\"],[\"79041.40\",\"0.003\"],[\"79041.50\",\"0.001\"],[\"79041.60\",\"0.003\"],[\"79041.70\",\"0.258\"],[\"79041.80\",\"0.263\"]],\"st\":1}"}
{"received_at_ns": 1787590754541453320, "payload": "{\"e\":\"depthUpdate\",\"E\":1787590754473,\"T\":1787590754472,\"s\":\"BTCUSDT\",\"ps\":\"BTCUSDT\",\"U\":11376698052731,\"u\":11376698124343,\"pu\":11376698052657,\"b\":[[\"79039.00\",\"2.612\"],[\"79038.90\",\"0.254\"],[\"79038.80\",\"0.003\"],[\"79038.70\",\"0.200\"],[\"79037.60\",\"0.002\"],[\"79037.30\",\"0.002\"],[\"79037.20\",\"0.001\"],[\"79036.90\",\"0.147\"],[\"79036.80\",\"0.076\"],[\"79036.50\",\"0.002\"],[\"79036.40\",\"0.001\"],[\"79036.00\",\"0.003\"],[\"79035.90\",\"0.001\"],[\"79035.30\",\"0.001\"],[\"79035.20\",\"0.001\"],[\"79035.00\",\"0.002\"],[\"79034.80\",\"0.147\"],[\"79034.60\",\"0.003\"],[\"79034.50\",\"0.001\"],[\"79034.40\",\"0.001\"]],\"a\":[[\"79039.10\",\"1.921\"],[\"79039.20\",\"0.001\"],[\"79039.30\",\"0.001\"],[\"79039.40\",\"0.001\"],[\"79039.50\",\"0.002\"],[\"79039.80\",\"0.003\"],[\"79039.90\",\"0.001\"],[\"79040.00\",\"0.328\"],[\"79040.10\",\"0.010\"],[\"79040.30\",\"0.002\"],[\"79040.60\",\"0.003\"],[\"79040.90\",\"0.001\"],[\"79041.00\",\"0.076\"],[\"79041.10\",\"0.005\"],[\"79041.30\",\"0.001\"],[\"79041.40\",\"0.003\"],[\"79041.50\",\"0.077\"],[\"79041.60\",\"0.149\"],[\"79041.70\",\"0.335\"],[\"79041.80\",\"0.187\"]],\"st\":1}"}
{"received_at_ns": 1787590755045176674, "payload": "{\"e\":\"depthUpdate\",\"E\":1787590754977,\"T\":1787590754976,\"s\":\"BTCUSDT\",\"ps\":\"BTCUSDT\",\"U\":11376698124379,\"u\":11376698170280,\"pu\":11376698124343,\"b\":[[\"79039.00\",\"2.881\"],[\"79038.90\",\"0.254\"],[\"79038.80\",\"0.003\"],[\"79038.70\",\"0.200\"],[\"79037.60\",\"0.002\"],[\"79037.30\",\"0.002\"],[\"79037.20\",\"0.001\"],[\"79036.90\",\"0.146\"],[\"79036.80\",\"0.076\"],[\"79036.60\",\"0.001\"],[\"79036.50\",\"0.002\"],[\"79036.40\",\"0.001\"],[\"79036.00\",\"0.003\"],[\"79035.90\",\"0.001\"],[\"79035.30\",\"0.001\"],[\"79035.20\",\"0.001\"],[\"79035.00\",\"0.002\"],[\"79034.80\",\"0.147\"],[\"79034.60\",\"0.003\"],[\"79034.50\",\"0.001\"]],\"a\":[[\"79039.10\",\"0.695\"],[\"79039.20\",\"0.001\"],[\"79039.30\",\"0.001\"],[\"79039.40\",\"0.001\"],[\"79039.50\",\"0.002\"],[\"79039.80\",\"0.003\"],[\"79040.00\",\"0.328\"],[\"79040.10\",\"0.010\"],[\"79040.30\",\"0.002\"],[\"79040.60\",\"0.003\"],[\"79040.90\",\"0.001\"],[\"79041.10\",\"0.005\"],[\"79041.30\",\"0.001\"],[\"79041.40\",\"0.003\"],[\"79041.50\",\"0.001\"],[\"79041.60\",\"0.007\"],[\"79041.70\",\"0.335\"],[\"79041.80\",\"0.187\"],[\"79041.90\",\"1.895\"],[\"79042.00\",\"0.002\"]],\"st\":1}"}
{"received_at_ns": 1787590755549718149, "payload": "{\"e\":\"depthUpdate\",\"E\":1787590755481,\"T\":1787590755480,\"s\":\"BTCUSDT\",\"ps\":\"BTCUSDT\",\"U\":11376698170443,\"u\":11376698242725,\"pu\":11376698170280,\"b\":[[\"79039.00\",\"3.062\"],[\"79038.90\",\"0.254\"],[\"79038.80\",\"0.003\"],[\"79038.70\",\"0.200\"],[\"79037.60\",\"0.002\"],[\"79037.30\",\"0.002\"],[\"79037.20\",\"0.001\"],[\"79036.80\",\"0.076\"],[\"79036.50\",\"0.002\"],[\"79036.40\",\"0.001\"],[\"79036.00\",\"0.003\"],[\"79035.90\",\"0.001\"],[\"79035.30\",\"0.001\"],[\"79035.20\",\"0.001\"],[\"79035.00\",\"0.002\"],[\"79034.80\",\"0.147\"],[\"79034.60\",\"0.003\"],[\"79034.50\",\"0.001\"],[\"79034.40\",\"0.001\"],[\"79034.30\",\"0.001\"]],\"a\":[[\"79039.10\",\"4.326\"],[\"79039.20\",\"0.001\"],[\"79039.30\",\"0.001\"],[\"79039.40\",\"0.001\"],[\"79039.50\",\"0.002\"],[\"79039.80\",\"0.003\"],[\"79039.90\",\"0.001\"],[\"79040.00\",\"0.328\"],[\"79040.10\",\"0.010\"],[\"79040.30\",\"0.002\"],[\"79040.60\",\"0.003\"],[\"79040.90\",\"0.001\"],[\"79041.10\",\"0.003\"],[\"79041.20\",\"0.254\"],[\"79041.30\",\"0.001\"],[\"79041.40\",\"0.257\"],[\"79041.50\",\"0.001\"],[\"79041.60\",\"0.003\"],[\"79041.70\",\"0.339\"],[\"79041.80\",\"0.187\"]],\"st\":1}"}
{"received_at_ns": 1787590756052985573, "payload": "{\"e\":\"depthUpdate\",\"E\":1787590755985,\"T\":1787590755984,\"s\":\"BTCUSDT\",\"ps\":\"BTCUSDT\",\"U\":11376698242754,\"u\":11376698297491,\"pu\":11376698242725,\"b\":[[\"79039.00\",\"2.120\"],[\"79038.90\",\"0.255\"],[\"79038.80\",\"0.003\"],[\"79038.70\",\"0.200\"],[\"79037.60\",\"0.002\"],[\"79037.30\",\"0.002\"],[\"79037.20\",\"0.001\"],[\"79036.80\",\"0.076\"],[\"79036.50\",\"0.002\"],[\"79036.40\",\"0.001\"],[\"79036.00\",\"0.003\"],[\"79035.90\",\"0.001\"],[\"79035.30\",\"0.001\"],[\"79035.20\",\"0.001\"],[\"79035.00\",\"0.002\"],[\"79034.80\",\"0.001\"],[\"79034.60\",\"0.003\"],[\"79034.50\",\"0.001\"],[\"79034.40\",\"0.001\"],[\"79034.30\",\"0.001\"]],\"a\":[[\"79039.10\",\"4.654\"],[\"79039.20\",\"0.001\"],[\"79039.30\",\"0.001\"],[\"79039.40\",\"0.001\"],[\"79039.50\",\"0.002\"],[\"79039.80\",\"0.003\"],[\"79039.90\",\"0.001\"],[\"79040.00\",\"0.003\"],[\"79040.10\",\"0.010\"],[\"79040.60\",\"0.003\"],[\"79040.90\",\"0.001\"],[\"79041.20\",\"0.254\"],[\"79041.30\",\"0.001\"],[\"79041.40\",\"0.257\"],[\"79041.50\",\"0.001\"],[\"79041.60\",\"0.003\"],[\"79041.70\",\"0.339\"],[\"79041.80\",\"0.187\"],[\"79041.90\",\"1.895\"],[\"79042.00\",\"0.005\"]],\"st\":1}"}
{"received_at_ns": 1787590756557351088, "payload": "{\"e\":\"depthUpdate\",\"E\":1787590756489,\"T\":1787590756488,\"s\":\"BTCUSDT\",\"ps\":\"BTCUSDT\",\"U\":11376698297522,\"u\":11376698350372,\"pu\":11376698297491,\"b\":[[\"79039.00\",\"2.417\"],[\"79038.90\",\"0.255\"],[\"79038.80\",\"0.003\"],[\"79038.70\",\"0.200\"],[\"79038.10\",\"0.003\"],[\"79037.60\",\"0.002\"],[\"79037.30\",\"0.002\"],[\"79037.20\",\"0.001\"],[\"79036.90\",\"0.146\"],[\"79036.80\",\"0.002\"],[\"79036.50\",\"0.002\"],[\"79036.40\",\"0.001\"],[\"79036.00\",\"0.003\"],[\"79035.90\",\"0.001\"],[\"79035.30\",\"0.001\"],[\"79035.20\",\"0.001\"],[\"79035.00\",\"0.002\"],[\"79034.80\",\"0.147\"],[\"79034.60\",\"0.003\"],[\"79034.50\",\"0.001\"]],\"a\":[[\"79039.10\",\"3.816\"],[\"79039.20\",\"0.001\"],[\"79039.30\",\"0.001\"],[\"79039.40\",\"0.001\"],[\"79039.50\",\"0.078\"],[\"79039.80\",\"0.003\"],[\"79039.90\",\"0.001\"],[\"79040.00\",\"0.003\"],[\"79040.10\",\"0.086\"],[\"79040.60\",\"0.003\"],[\"79040.90\",\"0.001\"],[\"79041.20\",\"0.254\"],[\"79041.30\",\"0.001\"],[\"79041.40\",\"0.260\"],[\"79041.50\",\"0.001\"],[\"79041.60\",\"0.003\"],[\"79041.70\",\"0.339\"],[\"79041.80\",\"0.187\"],[\"79041.90\",\"1.895\"],[\"79042.00\",\"0.003\"]],\"st\":1}"}
{"received_at_ns": 1787590757061268863, "payload": "{\"e\":\"depthUpdate\",\"E\":1787590756993,\"T\":1787590756991,\"s\":\"BTCUSDT\",\"ps\":\"BTCUSDT\",\"U\":11376698350408,\"u\":11376698392063,\"pu\":11376698350372,\"b\":[[\"79039.00\",\"2.298\"],[\"79038.90\",\"0.255\"],[\"79038.80\",\"0.003\"],[\"79038.70\",\"0.200\"],[\"79038.10\",\"0.003\"],[\"79037.60\",\"0.002\"],[\"79037.30\",\"0.002\"],[\"79037.20\",\"0.001\"],[\"79036.90\",\"0.146\"],[\"79036.80\",\"0.002\"],[\"79036.50\",\"0.002\"],[\"79036.40\",\"0.001\"],[\"79036.00\",\"0.003\"],[\"79035.90\",\"0.001\"],[\"79035.30\",\"0.001\"],[\"79035.20\",\"0.001\"],[\"79035.00\",\"0.002\"],[\"79034.80\",\"0.147\"],[\"79034.60\",\"0.003\"],[\"79034.50\",\"0.001\"]],\"a\":[[\"79039.10\",\"3.306\"],[\"79039.20\",\"0.001\"],[\"79039.30\",\"0.001\"],[\"79039.40\",\"0.001\"],[\"79039.50\",\"0.078\"],[\"79039.80\",\"0.003\"],[\"79039.90\",\"0.001\"],[\"79040.00\",\"0.003\"],[\"79040.10\",\"0.086\"],[\"79040.30\",\"0.002\"],[\"79040.60\",\"0.003\"],[\"79040.90\",\"0.001\"],[\"79041.10\",\"0.033\"],[\"79041.20\",\"0.254\"],[\"79041.30\",\"0.001\"],[\"79041.40\",\"0.260\"],[\"79041.50\",\"0.001\"],[\"79041.60\",\"0.003\"],[\"79041.70\",\"0.339\"],[\"79041.80\",\"0.003\"]],\"st\":1}"}
{"received_at_ns": 1787590757565464877, "payload": "{\"e\":\"depthUpdate\",\"E\":1787590757497,\"T\":1787590757496,\"s\":\"BTCUSDT\",\"ps\":\"BTCUSDT\",\"U\":11376698392325,\"u\":11376698486380,\"pu\":11376698392063,\"b\":[[\"79039.00\",\"3.177\"],[\"79038.90\",\"0.255\"],[\"79038.80\",\"0.003\"],[\"79038.70\",\"0.200\"],[\"79038.40\",\"0.003\"],[\"79038.20\",\"0.076\"],[\"79038.10\",\"0.003\"],[\"79037.60\",\"0.002\"],[\"79037.30\",\"0.078\"],[\"79037.20\",\"0.001\"],[\"79037.00\",\"0.001\"],[\"79036.90\",\"0.146\"],[\"79036.80\",\"0.078\"],[\"79036.50\",\"0.002\"],[\"79036.40\",\"0.002\"],[\"79036.10\",\"0.076\"],[\"79036.00\",\"0.003\"],[\"79035.90\",\"0.001\"],[\"79035.60\",\"0.002\"],[\"79035.30\",\"0.001\"]],\"a\":[[\"79039.10\",\"2.275\"],[\"79039.20\",\"0.001\"],[\"79039.30\",\"0.001\"],[\"79039.40\",\"0.001\"],[\"79039.50\",\"0.002\"],[\"79039.80\",\"0.003\"],[\"79040.00\",\"0.003\"],[\"79040.10\",\"0.010\"],[\"79040.60\",\"0.003\"],[\"79040.90\",\"0.001\"],[\"79041.30\",\"0.001\"],[\"79041.40\",\"0.003\"],[\"79041.50\",\"0.001\"],[\"79041.60\",\"0.003\"],[\"79041.80\",\"0.002\"],[\"79041.90\",\"0.002\"],[\"79042.00\",\"0.001\"],[\"79042.10\",\"0.001\"],[\"79042.20\",\"0.009\"],[\"79042.30\",\"0.004\"]],\"st\":1}"}
{"received_at_ns": 1787590758070753531, "payload": "{\"e\":\"depthUpdate\",\"E\":1787590758001,\"T\":1787590757999,\"s\":\"BTCUSDT\",\"ps\":\"BTCUSDT\",\"U\":11376698486395,\"u\":11376698522694,\"pu\":11376698486380,\"b\":[[\"79039.00\",\"2.114\"],[\"79038.90\",\"0.255\"],[\"79038.80\",\"0.003\"],[\"79038.70\",\"0.200\"],[\"79038.10\",\"0.003\"],[\"79037.60\",\"0.002\"],[\"79037.30\",\"0.002\"],[\"79037.20\",\"0.001\"],[\"79037.00\",\"0.001\"],[\"79036.90\",\"0.136\"],[\"79036.80\",\"0.002\"],[\"79036.50\",\"0.002\"],[\"79036.40\",\"0.001\"],[\"79036.00\",\"0.003\"],[\"79035.90\",\"0.001\"],[\"79035.70\",\"0.003\"],[\"79035.30\",\"0.001\"],[\"79035.20\",\"0.001\"],[\"79035.00\",\"0.014\"],[\"79034.80\",\"0.147\"]],\"a\":[[\"79039.10\",\"2.753\"],[\"79039.20\",\"0.001\"],[\"79039.30\",\"0.001\"],[\"79039.40\",\"0.001\"],[\"79039.50\",\"0.002\"],[\"79039.80\",\"0.003\"],[\"79039.90\",\"0.001\"],[\"79040.00\",\"0.003\"],[\"79040.10\",\"0.010\"],[\"79040.60\",\"0.003\"],[\"79040.90\",\"0.001\"],[\"79041.30\",\"0.001\"],[\"79041.40\",\"0.003\"],[\"79041.50\",\"0.001\"],[\"79041.60\",\"0.003\"],[\"79041.80\",\"0.002\"],[\"79041.90\",\"0.103\"],[\"79042.00\",\"0.255\"],[\"79042.10\",\"0.001\"],[\"79042.20\",\"0.009\"]],\"st\":1}"}
{"received_at_ns": 1787590758573097926, "payload": "{\"e\":\"depthUpdate\",\"E\":1787590758505,\"T\":1787590758502,\"s\":\"BTCUSDT\",\"ps\":\"BTCUSDT\",\"U\":11376698522874,\"u\":11376698558610,\"pu\":11376698522694,\"b\":[[\"79039.00\",\"2.372\"],[\"79038.90\",\"0.255\"],[\"79038.80\",\"0.003\"],[\"79038.70\",\"0.200\"],[\"79038.10\",\"0.003\"],[\"79037.60\",\"0.002\"],[\"79037.30\",\"0.002\"],[\"79037.20\",\"0.001\"],[\"79036.90\",\"0.135\"],[\"79036.80\",\"0.002\"],[\"79036.50\",\"0.002\"],[\"79036.40\",\"0.001\"],[\"79036.00\",\"0.003\"],[\"79035.90\",\"0.001\"],[\"79035.70\",\"0.003\"],[\"79035.30\",\"0.001\"],[\"79035.20\",\"0.001\"],[\"79035.00\",\"0.014\"],[\"79034.80\",\"0.147\"],[\"79034.60\",\"0.003\"]],\"a\":[[\"79039.10\",\"2.851\"],[\"79039.20\",\"0.001\"],[\"79039.30\",\"0.001\"],[\"79039.40\",\"0.001\"],[\"79039.50\",\"0.002\"],[\"79039.80\",\"0.003\"],[\"79039.90\",\"0.001\"],[\"79040.00\",\"0.003\"],[\"79040.10\",\"0.010\"],[\"79040.60\",\"0.003\"],[\"79040.90\",\"0.001\"],[\"79041.30\",\"0.001\"],[\"79041.40\",\"0.006\"],[\"79041.50\",\"0.001\"],[\"79041.60\",\"0.003\"],[\"79041.80\",\"0.002\"],[\"79041.90\",\"0.103\"],[\"79042.00\",\"0.255\"],[\"79042.10\",\"0.001\"],[\"79042.20\",\"0.009\"]],\"st\":1}"}
{"received_at_ns": 1787590759077019551, "payload": "{\"e\":\"depthUpdate\",\"E\":1787590759009,\"T\":1787590759007,\"s\":\"BTCUSDT\",\"ps\":\"BTCUSDT\",\"U\":11376698558810,\"u\":11376698595544,\"pu\":11376698558610,\"b\":[[\"79039.00\",\"2.029\"],[\"79038.90\",\"0.255\"],[\"79038.80\",\"0.003\"],[\"79038.70\",\"0.200\"],[\"79037.60\",\"0.002\"],[\"79037.30\",\"0.002\"],[\"79037.20\",\"0.001\"],[\"79036.90\",\"0.135\"],[\"79036.80\",\"0.037\"],[\"79036.50\",\"0.002\"],[\"79036.40\",\"0.001\"],[\"79036.00\",\"0.003\"],[\"79035.90\",\"0.001\"],[\"79035.70\",\"0.003\"],[\"79035.30\",\"0.001\"],[\"79035.20\",\"0.001\"],[\"79035.00\",\"0.002\"],[\"79034.80\",\"0.147\"],[\"79034.60\",\"0.003\"],[\"79034.50\",\"0.001\"]],\"a\":[[\"79039.10\",\"2.814\"],[\"79039.20\",\"0.001\"],[\"79039.30\",\"0.001\"],[\"79039.40\",\"0.001\"],[\"79039.50\",\"0.002\"],[\"79039.80\",\"0.003\"],[\"79039.90\",\"0.001\"],[\"79040.00\",\"0.003\"],[\"79040.10\",\"0.010\"],[\"79040.60\",\"0.003\"],[\"79040.90\",\"0.001\"],[\"79041.30\",\"0.001\"],[\"79041.40\",\"0.006\"],[\"79041.50\",\"0.001\"],[\"79041.60\",\"0.003\"],[\"79041.80\",\"0.002\"],[\"79041.90\",\"0.103\"],[\"79042.00\",\"0.255\"],[\"79042.10\",\"0.001\"],[\"79042.20\",\"0.009\"]],\"st\":1}"}
{"received_at_ns": 1787590759581587565, "payload": "{\"e\":\"depthUpdate\",\"E\":1787590759513,\"T\":1787590759511,\"s\":\"BTCUSDT\",\"ps\":\"BTCUSDT\",\"U\":11376698595709,\"u\":11376698651971,\"pu\":11376698595544,\"b\":[[\"79039.00\",\"1.968\"],[\"79038.90\",\"0.255\"],[\"79038.80\",\"0.003\"],[\"79038.70\",\"0.200\"],[\"79037.60\",\"0.002\"],[\"79037.30\",\"0.002\"],[\"79037.20\",\"0.001\"],[\"79036.90\",\"0.135\"],[\"79036.80\",\"0.002\"],[\"79036.50\",\"0.035\"],[\"79036.40\",\"0.001\"],[\"79036.00\",\"0.003\"],[\"79035.90\",\"0.001\"],[\"79035.30\",\"0.001\"],[\"79035.20\",\"0.001\"],[\"79035.00\",\"0.002\"],[\"79034.80\",\"0.147\"],[\"79034.60\",\"0.003\"],[\"79034.50\",\"0.001\"],[\"79034.40\",\"0.001\"]],\"a\":[[\"79039.10\",\"3.151\"],[\"79039.20\",\"0.001\"],[\"79039.30\",\"0.001\"],[\"79039.40\",\"0.001\"],[\"79039.50\",\"0.002\"],[\"79039.80\",\"0.003\"],[\"79039.90\",\"0.001\"],[\"79040.00\",\"0.003\"],[\"79040.10\",\"0.010\"],[\"79040.50\",\"0.001\"],[\"79040.60\",\"0.003\"],[\"79040.80\",\"0.076\"],[\"79040.90\",\"0.001\"],[\"79041.30\",\"0.077\"],[\"79041.40\",\"0.006\"],[\"79041.50\",\"0.001\"],[\"79041.60\",\"0.003\"],[\"79041.80\",\"0.078\"],[\"79041.90\",\"0.103\"],[\"79042.00\",\"0.255\"]],\"st\":1}"}
{"received_at_ns": 1787590760085573440, "payload": "{\"e\":\"depthUpdate\",\"E\":1787590760017,\"T\":1787590760016,\"s\":\"BTCUSDT\",\"ps\":\"BTCUSDT\",\"U\":11376698652098,\"u\":11376698692162,\"pu\":11376698651971,\"b\":[[\"79039.00\",\"1.952\"],[\"79038.90\",\"0.255\"],[\"79038.80\",\"0.003\"],[\"79038.70\",\"0.200\"],[\"79037.60\",\"0.002\"],[\"79037.30\",\"0.002\"],[\"79037.20\",\"0.001\"],[\"79036.80\",\"0.002\"],[\"79036.50\",\"0.002\"],[\"79036.40\",\"0.001\"],[\"79036.00\",\"0.003\"],[\"79035.90\",\"0.001\"],[\"79035.30\",\"0.001\"],[\"79035.20\",\"0.001\"],[\"79035.00\",\"0.002\"],[\"79034.80\",\"0.001\"],[\"79034.60\",\"0.003\"],[\"79034.50\",\"0.001\"],[\"79034.40\",\"0.001\"],[\"79034.30\",\"0.075\"]],\"a\":[[\"79039.10\",\"3.476\"],[\"79039.20\",\"0.001\"],[\"79039.30\",\"0.001\"],[\"79039.40\",\"0.004\"],[\"79039.50\",\"0.002\"],[\"79039.80\",\"0.003\"],[\"79039.90\",\"0.001\"],[\"79040.00\",\"0.079\"],[\"79040.10\",\"0.010\"],[\"79040.50\",\"0.001\"],[\"79040.60\",\"0.079\"],[\"79040.90\",\"0.001\"],[\"79041.10\",\"0.163\"],[\"79041.20\",\"0.129\"],[\"79041.30\",\"0.001\"],[\"79041.40\",\"0.003\"],[\"79041.50\",\"0.077\"],[\"79041.60\",\"0.003\"],[\"79041.80\",\"0.002\"],[\"79041.90\",\"0.005\"]],\"st\":1}"}
{"received_at_ns": 1787590760589259545, "payload": "{\"e\":\"depthUpdate\",\"E\":1787590760521,\"T\":1787590760519,\"s\":\"BTCUSDT\",\"ps\":\"BTCUSDT\",\"U\":11376698692291,\"u\":11376698736585,\"pu\":11376698692162,\"b\":[[\"79039.00\",\"1.979\"],[\"79038.90\",\"0.255\"],[\"79038.80\",\"0.003\"],[\"79038.70\",\"0.200\"],[\"79037.60\",\"0.002\"],[\"79037.30\",\"0.002\"],[\"79037.20\",\"0.001\"],[\"79036.80\",\"0.002\"],[\"79036.50\",\"0.002\"],[\"79036.40\",\"0.001\"],[\"79036.00\",\"0.003\"],[\"79035.90\",\"0.001\"],[\"79035.30\",\"0.001\"],[\"79035.20\",\"0.001\"],[\"79035.00\",\"0.002\"],[\"79034.80\",\"0.147\"],[\"79034.60\",\"0.003\"],[\"79034.50\",\"0.001\"],[\"79034.40\",\"0.001\"],[\"79034.30\",\"0.075\"]],\"a\":[[\"79039.10\",\"3.255\"],[\"79039.20\",\"0.001\"],[\"79039.30\",\"0.001\"],[\"79039.40\",\"0.080\"],[\"79039.50\",\"0.002\"],[\"79039.80\",\"0.003\"],[\"79039.90\",\"0.077\"],[\"79040.00\",\"0.003\"],[\"79040.10\",\"0.010\"],[\"79040.60\",\"0.079\"],[\"79040.90\",\"0.001\"],[\"79041.10\",\"0.163\"],[\"79041.30\",\"0.001\"],[\"79041.40\",\"0.003\"],[\"79041.50\",\"0.077\"],[\"79041.60\",\"0.003\"],[\"79041.80\",\"0.002\"],[\"79041.90\",\"0.005\"],[\"79042.00\",\"0.331\"],[\"79042.10\",\"0.001\"]],\"st\":1}"}
{"received_at_ns": 1787590761093256329, "payload": "{\"e\":\"depthUpdate\",\"E\":1787590761025,\"T\":1787590761024,\"s\":\"BTCUSDT\",\"ps\":\"BTCUSDT\",\"U\":11376698736666,\"u\":11376698781580,\"pu\":11376698736585,\"b\":[[\"79039.00\",\"2.258\"],[\"79038.90\",\"0.255\"],[\"79038.80\",\"0.003\"],[\"79038.70\",\"0.200\"],[\"79037.60\",\"0.002\"],[\"79037.30\",\"0.002\"],[\"79037.20\",\"0.001\"],[\"79036.80\",\"0.002\"],[\"79036.50\",\"0.002\"],[\"79036.40\",\"0.001\"],[\"79036.00\",\"0.003\"],[\"79035.90\",\"0.001\"],[\"79035.30\",\"0.001\"],[\"79035.20\",\"0.001\"],[\"79035.00\",\"0.002\"],[\"79034.80\",\"0.147\"],[\"79034.60\",\"0.003\"],[\"79034.50\",\"0.001\"],[\"79034.40\",\"0.001\"],[\"79034.30\",\"0.075\"]],\"a\":[[\"79039.10\",\"3.466\"],[\"79039.20\",\"0.001\"],[\"79039.30\",\"0.001\"],[\"79039.40\",\"0.080\"],[\"79039.50\",\"0.002\"],[\"79039.80\",\"0.003\"],[\"79039.90\",\"0.077\"],[\"79040.00\",\"0.003\"],[\"79040.10\",\"0.010\"],[\"79040.30\",\"0.002\"],[\"79040.60\",\"0.079\"],[\"79040.90\",\"0.001\"],[\"79041.00\",\"0.146\"],[\"79041.10\",\"0.163\"],[\"79041.30\",\"0.001\"],[\"79041.40\",\"0.003\"],[\"79041.50\",\"0.077\"],[\"79041.60\",\"0.003\"],[\"79041.80\",\"0.002\"],[\"79041.90\",\"0.005\"]],\"st\":1}"}
{"received_at_ns": 1787590761597376273, "payload": "{\"e\":\"depthUpdate\",\"E\":1787590761529,\"T\":1787590761526,\"s\":\"BTCUSDT\",\"ps\":\"BTCUSDT\",\"U\":11376698781713,\"u\":11376698822502,\"pu\":11376698781580,\"b\":[[\"79039.00\",\"2.472\"],[\"79038.90\",\"0.255\"],[\"79038.80\",\"0.003\"],[\"79038.70\",\"0.200\"],[\"79038.60\",\"0.002\"],[\"79037.60\",\"0.002\"],[\"79037.30\",\"0.002\"],[\"79037.20\",\"0.001\"],[\"79036.90\",\"0.146\"],[\"79036.80\",\"0.002\"],[\"79036.50\",\"0.002\"],[\"79036.40\",\"0.001\"],[\"79036.00\",\"0.003\"],[\"79035.90\",\"0.001\"],[\"79035.30\",\"0.001\"],[\"79035.20\",\"0.001\"],[\"79035.00\",\"0.002\"],[\"79034.80\",\"0.147\"],[\"79034.60\",\"0.003\"],[\"79034.50\",\"0.001\"]],\"a\":[[\"79039.10\",\"3.178\"],[\"79039.20\",\"0.001\"],[\"79039.30\",\"0.077\"],[\"79039.40\",\"0.004\"],[\"79039.50\",\"0.002\"],[\"79039.80\",\"0.003\"],[\"79039.90\",\"0.077\"],[\"79040.00\",\"0.003\"],[\"79040.10\",\"0.010\"],[\"79040.30\",\"0.002\"],[\"79040.60\",\"0.003\"],[\"79040.80\",\"0.076\"],[\"79040.90\",\"0.001\"],[\"79041.10\",\"0.122\"],[\"79041.30\",\"0.001\"],[\"79041.40\",\"0.003\"],[\"79041.50\",\"0.077\"],[\"79041.60\",\"0.003\"],[\"79041.80\",\"0.002\"],[\"79041.90\",\"0.005\"]],\"st\":1}"}
{"received_at_ns": 1787590762101388368, "payload": "{\"e\":\"depthUpdate\",\"E\":1787590762033,\"T\":1787590762032,\"s\":\"BTCUSDT\",\"ps\":\"BTCUSDT\",\"U\":11376698822745,\"u\":11376698861903,\"pu\":11376698822502,\"b\":[[\"79039.00\",\"2.201\"],[\"79038.90\",\"0.255\"],[\"79038.80\",\"0.003\"],[\"79038.70\",\"0.314\"],[\"79038.60\",\"0.002\"],[\"79037.60\",\"0.002\"],[\"79037.30\",\"0.002\"],[\"79037.20\",\"0.001\"],[\"79036.80\",\"0.002\"],[\"79036.50\",\"0.002\"],[\"79036.40\",\"0.001\"],[\"79036.00\",\"0.003\"],[\"79035.90\",\"0.001\"],[\"79035.30\",\"0.001\"],[\"79035.20\",\"0.001\"],[\"79035.00\",\"0.002\"],[\"79034.80\",\"0.001\"],[\"79034.60\",\"0.003\"],[\"79034.50\",\"0.001\"],[\"79034.40\",\"0.001\"]],\"a\":[[\"79039.10\",\"3.535\"],[\"79039.20\",\"0.077\"],[\"79039.30\",\"0.001\"],[\"79039.40\",\"0.004\"],[\"79039.50\",\"0.002\"],[\"79039.80\",\"0.003\"],[\"79039.90\",\"0.001\"],[\"79040.00\",\"0.003\"],[\"79040.10\",\"0.010\"],[\"79040.60\",\"0.003\"],[\"79040.90\",\"0.001\"],[\"79041.00\",\"0.076\"],[\"79041.10\",\"0.122\"],[\"79041.20\",\"0.146\"],[\"79041.30\",\"0.001\"],[\"79041.40\",\"0.003\"],[\"79041.50\",\"0.077\"],[\"79041.60\",\"0.003\"],[\"79041.80\",\"0.002\"],[\"79041.90\",\"0.005\"]],\"st\":1}"}
{"received_at_ns": 1787590762605491043, "payload": "{\"e\":\"depthUpdate\",\"E\":1787590762537,\"T\":1787590762533,\"s\":\"BTCUSDT\",\"ps\":\"BTCUSDT\",\"U\":11376698861914,\"u\":11376698902045,\"pu\":11376698861903,\"b\":[[\"79039.00\",\"2.201\"],[\"79038.90\",\"0.255\"],[\"79038.80\",\"0.003\"],[\"79038.70\",\"0.314\"],[\"79038.60\",\"0.002\"],[\"79037.60\",\"0.002\"],[\"79037.30\",\"0.002\"],[\"79037.20\",\"0.001\"],[\"79036.80\",\"0.002\"],[\"79036.60\",\"0.001\"],[\"79036.50\",\"0.002\"],[\"79036.40\",\"0.001\"],[\"79036.00\",\"0.003\"],[\"79035.90\",\"0.001\"],[\"79035.30\",\"0.001\"],[\"79035.20\",\"0.001\"],[\"79035.00\",\"0.002\"],[\"79034.80\",\"0.147\"],[\"79034.60\",\"0.003\"],[\"79034.50\",\"0.001\"]],\"a\":[[\"79039.10\",\"2.989\"],[\"79039.20\",\"0.001\"],[\"79039.30\",\"0.001\"],[\"79039.40\",\"0.001\"],[\"79039.50\",\"0.002\"],[\"79039.80\",\"0.003\"],[\"79039.90\",\"0.001\"],[\"79040.00\",\"0.003\"],[\"79040.10\",\"0.086\"],[\"79040.60\",\"0.003\"],[\"79040.70\",\"0.076\"],[\"79040.90\",\"0.001\"],[\"79041.10\",\"0.122\"],[\"79041.30\",\"0.001\"],[\"79041.40\",\"0.079\"],[\"79041.50\",\"0.001\"],[\"79041.60\",\"0.003\"],[\"79041.70\",\"0.003\"],[\"79041.80\",\"0.002\"],[\"79041.90\",\"0.005\"]],\"st\":1}"}
{"received_at_ns": 1787590763109231797, "payload": "{\"e\":\"depthUpdate\",\"E\":1787590763041,\"T\":1787590763039,\"s\":\"BTCUSDT\",\"ps\":\"BTCUSDT\",\"U\":11376698902328,\"u\":11376698943589,\"pu\":11376698902045,\"b\":[[\"79039.00\",\"2.413\"],[\"79038.90\",\"0.255\"],[\"79038.80\",\"0.003\"],[\"79038.70\",\"0.314\"],[\"79038.60\",\"0.002\"],[\"79037.60\",\"0.002\"],[\"79037.30\",\"0.002\"],[\"79037.20\",\"0.001\"],[\"79036.80\",\"0.002\"],[\"79036.50\",\"0.002\"],[\"79036.40\",\"0.001\"],[\"79036.00\",\"0.003\"],[\"79035.90\",\"0.001\"],[\"79035.30\",\"0.001\"],[\"79035.20\",\"0.001\"],[\"79035.00\",\"0.002\"],[\"79034.80\",\"0.147\"],[\"79034.60\",\"0.003\"],[\"79034.50\",\"0.001\"],[\"79034.40\",\"0.001\"]],\"a\":[[\"79039.10\",\"3.905\"],[\"79039.20\",\"0.001\"],[\"79039.30\",\"0.001\"],[\"79039.40\",\"0.001\"],[\"79039.50\",\"0.002\"],[\"79039.60\",\"0.076\"],[\"79039.80\",\"0.003\"],[\"79039.90\",\"0.001\"],[\"79040.00\",\"0.003\"],[\"79040.10\",\"0.086\"],[\"79040.30\",\"0.002\"],[\"79040.60\",\"0.003\"],[\"79040.70\",\"0.076\"],[\"79040.90\",\"0.001\"],[\"79041.10\",\"0.122\"],[\"79041.30\",\"0.001\"],[\"79041.40\",\"0.079\"],[\"79041.50\",\"0.001\"],[\"79041.60\",\"0.003\"],[\"79041.70\",\"0.003\"]],\"st\":1}"}
{"received_at_ns": 1787590763613638611, "payload": "{\"e\":\"depthUpdate\",\"E\":1787590763545,\"T\":1787590763541,\"s\":\"BTCUSDT\",\"ps\":\"BTCUSDT\",\"U\":11376698943749,\"u\":11376698993262,\"pu\":11376698943589,\"b\":[[\"79039.00\",\"2.411\"],[\"79038.90\",\"0.255\"],[\"79038.80\",\"0.003\"],[\"79038.70\",\"0.314\"],[\"79038.60\",\"0.002\"],[\"79037.60\",\"0.002\"],[\"79037.40\",\"0.004\"],[\"79037.30\",\"0.002\"],[\"79037.20\",\"0.001\"],[\"79037.00\",\"0.003\"],[\"79036.90\",\"0.146\"],[\"79036.80\",\"0.004\"],[\"79036.50\",\"0.002\"],[\"79036.40\",\"0.001\"],[\"79036.00\",\"0.003\"],[\"79035.90\",\"0.001\"],[\"79035.30\",\"0.001\"],[\"79035.20\",\"0.001\"],[\"79035.00\",\"0.012\"],[\"79034.80\",\"0.147\"]],\"a\":[[\"79039.10\",\"3.518\"],[\"79039.20\",\"0.001\"],[\"79039.30\",\"0.001\"],[\"79039.40\",\"0.001\"],[\"79039.50\",\"0.002\"],[\"79039.80\",\"0.003\"],[\"79040.00\",\"0.003\"],[\"79040.10\",\"0.010\"],[\"79040.60\",\"0.003\"],[\"79040.90\",\"0.001\"],[\"79041.30\",\"0.001\"],[\"79041.40\",\"0.003\"],[\"79041.50\",\"0.001\"],[\"79041.60\",\"0.003\"],[\"79041.80\",\"0.025\"],[\"79041.90\",\"0.004\"],[\"79042.00\",\"0.001\"],[\"79042.10\",\"0.001\"],[\"79042.20\",\"0.009\"],[\"79042.30\",\"0.004\"]],\"st\":1}"}
{"received_at_ns": 1787590764117324776, "payload": "{\"e\":\"depthUpdate\",\"E\":1787590764049,\"T\":1787590764048,\"s\":\"BTCUSDT\",\"ps\":\"BTCUSDT\",\"U\":11376698993472,\"u\":11376699035993,\"pu\":11376698993262,\"b\":[[\"79039.00\",\"1.847\"],[\"79038.90\",\"0.255\"],[\"79038.80\",\"0.003\"],[\"79038.70\",\"0.314\"],[\"79038.60\",\"0.002\"],[\"79037.60\",\"0.002\"],[\"79037.40\",\"0.004\"],[\"79037.30\",\"0.002\"],[\"79037.20\",\"0.001\"],[\"79036.80\",\"0.002\"],[\"79036.50\",\"0.002\"],[\"79036.40\",\"0.002\"],[\"79036.00\",\"0.003\"],[\"79035.90\",\"0.001\"],[\"79035.30\",\"0.001\"],[\"79035.20\",\"0.001\"],[\"79035.00\",\"0.002\"],[\"79034.80\",\"0.147\"],[\"79034.60\",\"0.003\"],[\"79034.50\",\"0.001\"]],\"a\":[[\"79039.10\",\"3.941\"],[\"79039.20\",\"0.001\"],[\"79039.30\",\"0.001\"],[\"79039.40\",\"0.001\"],[\"79039.50\",\"0.002\"],[\"79039.70\",\"0.003\"],[\"79039.80\",\"0.003\"],[\"79039.90\",\"0.001\"],[\"79040.00\",\"0.003\"],[\"79040.10\",\"0.010\"],[\"79040.60\",\"0.003\"],[\"79040.90\",\"0.001\"],[\"79041.20\",\"0.146\"],[\"79041.30\",\"0.131\"],[\"79041.40\",\"0.257\"],[\"79041.50\",\"0.001\"],[\"79041.60\",\"0.003\"],[\"79041.80\",\"0.002\"],[\"79041.90\",\"0.004\"],[\"79042.00\",\"0.001\"]],\"st\":1}"}
{"received_at_ns": 1787590764627996150, "payload": "{\"e\":\"depthUpdate\",\"E\":1787590764553,\"T\":1787590764552,\"s\":\"BTCUSDT\",\"ps\":\"BTCUSDT\",\"U\":11376699036011,\"u\":11376699141257,\"pu\":11376699035993,\"b\":[[\"79047.50\",\"9.268\"],[\"79047.40\",\"0.017\"],[\"79047.30\",\"0.002\"],[\"79047.10\",\"0.008\"],[\"79047.00\",\"1.370\"],[\"79046.90\",\"2.860\"],[\"79046.80\",\"0.510\"],[\"79046.60\",\"4.800\"],[\"79046.40\",\"2.678\"],[\"79046.30\",\"1.007\"],[\"79046.20\",\"0.883\"],[\"79045.90\",\"0.016\"],[\"79045.80\",\"0.851\"],[\"79045.70\",\"0.036\"],[\"79045.60\",\"0.018\"],[\"79045.40\",\"2.806\"],[\"79045.30\",\"2.646\"],[\"79045.20\",\"0.077\"],[\"79045.00\",\"0.173\"],[\"79044.90\",\"0.049\"]],\"a\":[[\"79047.60\",\"0.014\"],[\"79047.80\",\"0.002\"],[\"79048.00\",\"0.105\"],[\"79048.20\",\"0.102\"],[\"79048.30\",\"0.003\"],[\"79048.50\",\"0.001\"],[\"79048.60\",\"0.002\"],[\"79048.70\",\"0.001\"],[\"79048.80\",\"0.001\"],[\"79049.10\",\"0.007\"],[\"79049.20\",\"0.015\"],[\"79049.40\",\"0.004\"],[\"79049.50\",\"0.001\"],[\"79049.60\",\"0.001\"],[\"79049.70\",\"0.002\"],[\"79049.90\",\"0.002\"],[\"79050.00\",\"0.002\"],[\"79050.10\",\"0.002\"],[\"79050.20\",\"0.003\"],[\"79050.40\",\"0.002\"]],\"st\":1}"}
{"received_at_ns": 1787590765125470845, "payload": "{\"e\":\"depthUpdate\",\"E\":1787590765057,\"T\":1787590765056,\"s\":\"BTCUSDT\",\"ps\":\"BTCUSDT\",\"U\":11376699141265,\"u\":11376699298802,\"pu\":11376699141257,\"b\":[[\"79060.30\",\"3.472\"],[\"79060.20\",\"0.003\"],[\"79060.10\",\"0.002\"],[\"79060.00\",\"0.001\"],[\"79059.50\",\"0.002\"],[\"79058.80\",\"0.001\"],[\"79058.60\",\"0.001\"],[\"79058.50\",\"0.001\"],[\"79058.40\",\"0.019\"],[\"79057.90\",\"0.001\"],[\"79057.20\",\"0.001\"],[\"79057.00\",\"0.001\"],[\"79056.90\",\"0.001\"],[\"79056.80\",\"0.001\"],[\"79056.70\",\"0.001\"],[\"79056.00\",\"0.002\"],[\"79055.70\",\"0.012\"],[\"79055.50\",\"0.001\"],[\"79055.20\",\"0.002\"],[\"79055.10\",\"0.001\"]],\"a\":[[\"79060.40\",\"3.091\"],[\"79060.50\",\"0.001\"],[\"79060.60\",\"0.079\"],[\"79060.70\",\"0.001\"],[\"79060.80\",\"0.004\"],[\"79060.90\",\"0.001\"],[\"79061.00\",\"0.006\"],[\"79061.20\",\"0.001\"],[\"79061.40\",\"0.006\"],[\"79061.50\",\"0.002\"],[\"79061.70\",\"0.006\"],[\"79061.80\",\"0.064\"],[\"79061.90\",\"0.094\"],[\"79062.10\",\"0.001\"],[\"79062.30\",\"0.001\"],[\"79062.40\",\"0.132\"],[\"79062.50\",\"0.076\"],[\"79062.70\",\"0.001\"],[\"79062.80\",\"0.003\"],[\"79062.90\",\"0.001\"]],\"st\":1}"}
{"received_at_ns": 1787590765629447690, "payload": "{\"e\":\"depthUpdate\",\"E\":1787590765561,\"T\":1787590765560,\"s\":\"BTCUSDT\",\"ps\":\"BTCUSDT\",\"U\":11376699298842,\"u\":11376699373774,\"pu\":11376699298802,\"b\":[[\"79052.30\",\"2.988\"],[\"79052.20\",\"0.002\"],[\"79052.10\",\"0.200\"],[\"79051.80\",\"0.001\"],[\"79051.60\",\"0.077\"],[\"79051.40\",\"0.001\"],[\"79051.30\",\"0.001\"],[\"79051.00\",\"0.076\"],[\"79050.80\",\"0.005\"],[\"79050.70\",\"0.002\"],[\"79050.60\",\"0.001\"],[\"79050.30\",\"0.063\"],[\"79050.20\",\"0.146\"],[\"79050.00\",\"0.002\"],[\"79049.90\",\"0.190\"],[\"79049.60\",\"0.076\"],[\"79049.50\",\"0.001\"],[\"79049.40\",\"0.001\"],[\"79049.10\",\"0.007\"],[\"79049.00\",\"0.077\"]],\"a\":[[\"79052.40\",\"3.995\"],[\"79052.50\",\"0.002\"],[\"79052.60\",\"0.002\"],[\"79052.70\",\"0.001\"],[\"79052.90\",\"0.001\"],[\"79053.70\",\"0.001\"],[\"79054.00\",\"0.001\"],[\"79054.10\",\"0.003\"],[\"79054.20\",\"1.891\"],[\"79054.30\",\"0.001\"],[\"79054.90\",\"0.002\"],[\"79055.00\",\"0.001\"],[\"79055.50\",\"0.001\"],[\"79055.60\",\"0.002\"],[\"79055.70\",\"2.505\"],[\"79055.80\",\"1.487\"],[\"79055.90\",\"0.003\"],[\"79056.00\",\"2.501\"],[\"79056.10\",\"1.256\"],[\"79056.20\",\"1.000\"]],\"st\":1}"}
{"received_at_ns": 1787590766133518014, "payload": "{\"e\":\"depthUpdate\",\"E\":1787590766065,\"T\":1787590766064,\"s\":\"BTCUSDT\",\"ps\":\"BTCUSDT\",\"U\":11376699373825,\"u\":11376699412917,\"pu\":11376699373774,\"b\":[[\"79052.30\",\"2.700\"],[\"79052.20\",\"0.002\"],[\"79052.10\",\"0.200\"],[\"79051.90\",\"0.002\"],[\"79051.80\",\"0.001\"],[\"79051.60\",\"0.001\"],[\"79051.50\",\"0.002\"],[\"79051.40\",\"0.001\"],[\"79051.30\",\"0.001\"],[\"79050.70\",\"0.002\"],[\"79050.60\",\"0.001\"],[\"79050.30\",\"0.063\"],[\"79050.20\",\"0.001\"],[\"79050.00\",\"0.002\"],[\"79049.90\",\"0.190\"],[\"79049.50\",\"0.001\"],[\"79049.40\",\"0.004\"],[\"79049.10\",\"0.004\"],[\"79049.00\",\"0.001\"],[\"79048.80\",\"0.001\"]],\"a\":[[\"79052.40\",\"2.814\"],[\"79052.50\",\"0.002\"],[\"79052.80\",\"0.002\"],[\"79052.90\",\"0.001\"],[\"79053.50\",\"0.076\"],[\"79053.70\",\"0.001\"],[\"79054.00\",\"0.001\"],[\"79054.10\",\"0.079\"],[\"79054.90\",\"0.002\"],[\"79055.00\",\"0.001\"],[\"79055.50\",\"0.001\"],[\"79055.60\",\"0.151\"],[\"79055.70\",\"2.577\"],[\"79055.80\",\"1.483\"],[\"79055.90\",\"0.002\"],[\"79056.00\",\"2.502\"],[\"79056.10\",\"1.257\"],[\"79056.20\",\"1.078\"],[\"79056.30\",\"0.002\"],[\"79056.90\",\"0.001\"]],\"st\":1}"}
{"received_at_ns": 1787590766637450209, "payload": "{\"e\":\"depthUpdate\",\"E\":1787590766569,\"T\":1787590766566,\"s\":\"BTCUSDT\",\"ps\":\"BTCUSDT\",\"U\":11376699413044,\"u\":11376699462526,\"pu\":11376699412917,\"b\":[[\"79052.30\",\"3.603\"],[\"79052.20\",\"0.269\"],[\"79052.10\",\"0.200\"],[\"79051.90\",\"0.002\"],[\"79051.80\",\"0.001\"],[\"79051.60\",\"0.001\"],[\"79051.50\",\"0.078\"],[\"79051.40\",\"0.001\"],[\"79051.30\",\"0.001\"],[\"79051.10\",\"0.002\"],[\"79050.80\",\"0.076\"],[\"79050.70\",\"0.002\"],[\"79050.60\",\"0.001\"],[\"79050.20\",\"0.001\"],[\"79050.00\",\"0.004\"],[\"79049.90\",\"0.001\"],[\"79049.70\",\"0.076\"],[\"79049.50\",\"0.001\"],[\"79049.40\",\"0.004\"],[\"79049.10\",\"0.004\"]],\"a\":[[\"79052.40\",\"2.397\"],[\"79052.50\",\"0.002\"],[\"79053.60\",\"0.002\"],[\"79053.70\",\"0.001\"],[\"79054.00\",\"0.001\"],[\"79054.10\",\"0.003\"],[\"79054.90\",\"0.002\"],[\"79055.00\",\"0.001\"],[\"79055.50\",\"0.001\"],[\"79055.80\",\"0.002\"],[\"79056.00\",\"0.005\"],[\"79056.10\",\"1.002\"],[\"79056.20\",\"1.003\"],[\"79056.30\",\"0.002\"],[\"79056.90\",\"0.001\"],[\"79057.00\",\"0.004\"],[\"79057.10\",\"0.001\"],[\"79057.30\",\"0.002\"],[\"79057.60\",\"0.003\"],[\"79057.70\",\"0.002\"]],\"st\":1}"}
