{"received_at_ns": 1787949667941823511, "payload": "{\"result\":null,\"id\":1}"}
{"received_at_ns": 1787949667945048141, "payload": "{\"e\":\"depthUpdate\",\"E\":1787949667876,\"T\":1787949667875,\"s\":\"BTCUSDT\",\"ps\":\"BTCUSDT\",\"U\":11417388845787,\"u\":11417388875728,\"pu\":11417388845634,\"b\":[[\"77397.90\",\"4.748\"],[\"77397.80\",\"0.004\"],[\"77397.70\",\"0.020\"],[\"77397.60\",\"0.006\"],[\"77397.50\",\"0.011\"],[\"77397.20\",\"0.013\"],[\"77397.10\",\"0.021\"],[\"77396.90\",\"0.002\"],[\"77396.30\",\"0.002\"],[\"77396.20\",\"0.001\"],[\"77396.10\",\"0.036\"],[\"77396.00\",\"0.044\"],[\"77395.60\",\"0.003\"],[\"77395.50\",\"0.001\"],[\"77395.40\",\"0.001\"],[\"77395.30\",\"0.009\"],[\"77395.20\",\"0.001\"],[\"77395.00\",\"0.004\"],[\"77394.90\",\"0.001\"],[\"77394.80\",\"0.002\"]],\"a\":[[\"77398.00\",\"3.482\"],[\"77398.10\",\"0.153\"],[\"77398.20\",\"0.001\"],[\"77398.30\",\"0.081\"],[\"77398.40\",\"0.003\"],[\"77398.50\",\"0.078\"],[\"77398.60\",\"0.034\"],[\"77398.80\",\"0.089\"],[\"77399.10\",\"0.080\"],[\"77399.40\",\"0.082\"],[\"77399.60\",\"0.079\"],[\"77399.70\",\"0.005\"],[\"77400.00\",\"0.222\"],[\"77400.20\",\"0.016\"],[\"77400.30\",\"0.080\"],[\"77400.50\",\"0.078\"],[\"77400.60\",\"0.006\"],[\"77400.70\",\"0.007\"],[\"77400.80\",\"0.077\"],[\"77400.90\",\"0.125\"]],\"st\":1}"}
{"received_at_ns": 1787949668447869080, "payload": "{\"e\":\"depthUpdate\",\"E\":1787949668380,\"T\":1787949668377,\"s\":\"BTCUSDT\",\"ps\":\"BTCUSDT\",\"U\":11417388875831,\"u\":11417388901729,\"pu\":11417388875728,\"b\":[[\"77397.90\",\"4.794\"],[\"77397.80\",\"0.004\"],[\"77397.70\",\"0.020\"],[\"77397.60\",\"0.006\"],[\"77397.50\",\"0.089\"],[\"77397.30\",\"0.040\"],[\"77397.20\",\"0.078\"],[\"77397.10\",\"0.021\"],[\"77396.90\",\"0.080\"],[\"77396.30\",\"0.002\"],[\"77396.20\",\"0.001\"],[\"77396.10\",\"0.036\"],[\"77396.00\",\"0.044\"],[\"77395.60\",\"0.003\"],[\"77395.50\",\"0.001\"],[\"77395.40\",\"0.001\"],[\"77395.30\",\"0.009\"],[\"77395.20\",\"0.001\"],[\"77395.00\",\"0.004\"],[\"77394.90\",\"0.001\"]],\"a\":[[\"77398.00\",\"3.404\"],[\"77398.10\",\"0.154\"],[\"77398.20\",\"0.001\"],[\"77398.30\",\"0.003\"],[\"77398.40\",\"0.003\"],[\"77398.60\",\"0.034\"],[\"77398.80\",\"0.011\"],[\"77399.10\",\"0.002\"],[\"77399.40\",\"0.004\"],[\"77399.60\",\"0.001\"],[\"77399.70\",\"0.004\"],[\"77400.00\",\"0.222\"],[\"77400.20\",\"0.016\"],[\"77400.30\",\"0.080\"],[\"77400.50\",\"0.078\"],[\"77400.60\",\"0.006\"],[\"77400.70\",\"0.005\"],[\"77400.80\",\"0.077\"],[\"77400.90\",\"0.125\"],[\"77401.00\",\"0.001\"]],\"st\":1}"}
{"received_at_ns": 1787949668952296459, "payload": "{\"e\":\"depthUpdate\",\"E\":1787949668884,\"T\":1787949668882,\"s\":\"BTCUSDT\",\"ps\":\"BTCUSDT\",\"U\":11417388901891,\"u\":11417388933884,\"pu\":11417388901729,\"b\":[[\"77397.90\",\"4.630\"],[\"77397.80\",\"0.004\"],[\"77397.70\",\"0.020\"],[\"77397.60\",\"0.006\"],[\"77397.50\",\"0.011\"],[\"77397.30\",\"0.040\"],[\"77397.20\",\"0.078\"],[\"77397.10\",\"0.021\"],[\"77396.90\",\"0.080\"],[\"77396.30\",\"0.002\"],[\"77396.20\",\"0.001\"],[\"77396.10\",\"0.036\"],[\"77396.00\",\"0.044\"],[\"77395.60\",\"0.003\"],[\"77395.50\",\"0.001\"],[\"77395.40\",\"0.001\"],[\"77395.30\",\"0.009\"],[\"77395.20\",\"0.001\"],[\"77395.00\",\"0.004\"],[\"77394.90\",\"0.001\"]],\"a\":[[\"77398.00\",\"3.522\"],[\"77398.10\",\"0.154\"],[\"77398.20\",\"0.001\"],[\"77398.30\",\"0.003\"],[\"77398.40\",\"0.003\"],[\"77398.60\",\"0.265\"],[\"77398.80\",\"0.011\"],[\"77399.10\",\"0.002\"],[\"77399.40\",\"0.004\"],[\"77399.50\",\"0.078\"],[\"77399.60\",\"0.001\"],[\"77399.70\",\"0.004\"],[\"77400.00\",\"0.222\"],[\"77400.20\",\"0.016\"],[\"77400.30\",\"0.080\"],[\"77400.50\",\"0.078\"],[\"77400.60\",\"0.008\"],[\"77400.70\",\"0.005\"],[\"77400.80\",\"0.155\"],[\"77400.90\",\"0.125\"]],\"st\":1}"}
{"received_at_ns": 1787949669455635888, "payload": "{\"e\":\"depthUpdate\",\"E\":1787949669388,\"T\":1787949669387,\"s\":\"BTCUSDT\",\"ps\":\"BTCUSDT\",\"U\":11417388934162,\"u\":11417388962381,\"pu\":11417388933884,\"b\":[[\"77397.90\",\"4.636\"],[\"77397.80\",\"0.004\"],[\"77397.70\",\"0.020\"],[\"77397.60\",\"0.006\"],[\"77397.50\",\"0.011\"],[\"77397.30\",\"0.016\"],[\"77397.10\",\"0.021\"],[\"77396.90\",\"0.002\"],[\"77396.30\",\"0.002\"],[\"77396.20\",\"0.001\"],[\"77396.10\",\"0.036\"],[\"77396.00\",\"0.044\"],[\"77395.60\",\"0.081\"],[\"77395.50\",\"0.001\"],[\"77395.40\",\"0.001\"],[\"77395.30\",\"0.087\"],[\"77395.20\",\"0.001\"],[\"77395.00\",\"0.004\"],[\"77394.90\",\"0.001\"],[\"77394.80\",\"0.002\"]],\"a\":[[\"77398.00\",\"3.601\"],[\"77398.10\",\"0.154\"],[\"77398.20\",\"0.001\"],[\"77398.30\",\"0.003\"],[\"77398.40\",\"0.003\"],[\"77398.60\",\"0.265\"],[\"77398.70\",\"0.078\"],[\"77398.80\",\"0.011\"],[\"77398.90\",\"0.078\"],[\"77399.10\",\"0.002\"],[\"77399.40\",\"0.004\"],[\"77399.60\",\"0.001\"],[\"77399.70\",\"0.004\"],[\"77400.00\",\"0.144\"],[\"77400.10\",\"0.078\"],[\"77400.20\",\"0.016\"],[\"77400.30\",\"0.002\"],[\"77400.40\",\"0.078\"],[\"77400.60\",\"0.008\"],[\"77400.70\",\"0.005\"]],\"st\":1}"}
{"received_at_ns": 1787949669960171636, "payload": "{\"e\":\"depthUpdate\",\"E\":1787949669892,\"T\":1787949669890,\"s\":\"BTCUSDT\",\"ps\":\"BTCUSDT\",\"U\":11417388962536,\"u\":11417388993529,\"pu\":11417388962381,\"b\":[[\"77397.90\",\"4.899\"],[\"77397.80\",\"0.004\"],[\"77397.70\",\"0.070\"],[\"77397.60\",\"0.006\"],[\"77397.50\",\"0.011\"],[\"77397.30\",\"0.004\"],[\"77397.10\",\"0.021\"],[\"77397.00\",\"0.078\"],[\"77396.90\",\"0.002\"],[\"77396.30\",\"0.002\"],[\"77396.20\",\"0.079\"],[\"77396.10\",\"0.036\"],[\"77396.00\",\"0.122\"],[\"77395.60\",\"0.081\"],[\"77395.50\",\"0.001\"],[\"77395.40\",\"0.001\"],[\"77395.30\",\"0.087\"],[\"77395.20\",\"0.001\"],[\"77395.00\",\"0.004\"],[\"77394.90\",\"0.001\"]],\"a\":[[\"77398.00\",\"3.419\"],[\"77398.10\",\"0.153\"],[\"77398.20\",\"0.001\"],[\"77398.30\",\"0.003\"],[\"77398.40\",\"0.004\"],[\"77398.60\",\"0.265\"],[\"77398.80\",\"0.011\"],[\"77399.10\",\"0.002\"],[\"77399.40\",\"0.004\"],[\"77399.60\",\"0.001\"],[\"77399.70\",\"0.004\"],[\"77400.00\",\"0.144\"],[\"77400.10\",\"0.078\"],[\"77400.20\",\"0.016\"],[\"77400.30\",\"0.004\"],[\"77400.40\",\"2.032\"],[\"77400.60\",\"0.006\"],[\"77400.70\",\"0.005\"],[\"77400.80\",\"0.155\"],[\"77400.90\",\"0.125\"]],\"st\":1}"}
{"received_at_ns": 1787949670463797896, "payload": "{\"e\":\"depthUpdate\",\"E\":1787949670396,\"T\":1787949670393,\"s\":\"BTCUSDT\",\"ps\":\"BTCUSDT\",\"U\":11417388993627,\"u\":11417389022374,\"pu\":11417388993529,\"b\":[[\"77397.90\",\"4.955\"],[\"77397.80\",\"0.003\"],[\"77397.70\",\"0.091\"],[\"77397.60\",\"0.006\"],[\"77397.50\",\"0.011\"],[\"77397.30\",\"0.004\"],[\"77397.10\",\"0.021\"],[\"77397.00\",\"0.078\"],[\"77396.90\",\"0.002\"],[\"77396.50\",\"0.078\"],[\"77396.30\",\"0.002\"],[\"77396.20\",\"0.079\"],[\"77396.10\",\"0.036\"],[\"77396.00\",\"0.122\"],[\"77395.60\",\"0.081\"],[\"77395.50\",\"0.001\"],[\"77395.40\",\"0.001\"],[\"77395.30\",\"0.087\"],[\"77395.20\",\"0.001\"],[\"77395.00\",\"0.004\"]],\"a\":[[\"77398.00\",\"3.421\"],[\"77398.10\",\"0.153\"],[\"77398.20\",\"0.001\"],[\"77398.30\",\"0.003\"],[\"77398.40\",\"0.004\"],[\"77398.60\",\"0.265\"],[\"77398.80\",\"0.011\"],[\"77399.10\",\"0.002\"],[\"77399.40\",\"0.004\"],[\"77399.60\",\"0.001\"],[\"77399.70\",\"0.004\"],[\"77399.80\",\"0.078\"],[\"77400.00\",\"0.144\"],[\"77400.10\",\"0.078\"],[\"77400.20\",\"0.011\"],[\"77400.30\",\"0.004\"],[\"77400.40\",\"2.032\"],[\"77400.60\",\"0.006\"],[\"77400.70\",\"0.005\"],[\"77400.80\",\"0.155\"]],\"st\":1}"}
{"received_at_ns": 1787949670968163595, "payload": "{\"e\":\"depthUpdate\",\"E\":1787949670900,\"T\":1787949670898,\"s\":\"BTCUSDT\",\"ps\":\"BTCUSDT\",\"U\":11417389022539,\"u\":11417389049063,\"pu\":11417389022374,\"b\":[[\"77397.90\",\"4.963\"],[\"77397.80\",\"0.003\"],[\"77397.70\",\"0.091\"],[\"77397.60\",\"0.006\"],[\"77397.50\",\"0.011\"],[\"77397.30\",\"0.004\"],[\"77397.10\",\"0.016\"],[\"77396.90\",\"0.002\"],[\"77396.50\",\"0.078\"],[\"77396.30\",\"0.002\"],[\"77396.20\",\"0.079\"],[\"77396.10\",\"0.051\"],[\"77396.00\",\"0.078\"],[\"77395.60\",\"0.081\"],[\"77395.50\",\"0.001\"],[\"77395.40\",\"0.001\"],[\"77395.30\",\"0.102\"],[\"77395.20\",\"0.001\"],[\"77395.10\",\"0.078\"],[\"77395.00\",\"0.004\"]],\"a\":[[\"77398.00\",\"3.436\"],[\"77398.10\",\"0.154\"],[\"77398.20\",\"0.001\"],[\"77398.30\",\"0.003\"],[\"77398.40\",\"0.004\"],[\"77398.60\",\"0.265\"],[\"77398.80\",\"0.089\"],[\"77399.10\",\"0.002\"],[\"77399.20\",\"0.078\"],[\"77399.40\",\"0.004\"],[\"77399.60\",\"0.001\"],[\"77399.70\",\"0.003\"],[\"77399.80\",\"0.078\"],[\"77400.00\",\"0.144\"],[\"77400.10\",\"0.078\"],[\"77400.20\",\"0.011\"],[\"77400.30\",\"0.004\"],[\"77400.40\",\"2.032\"],[\"77400.60\",\"0.006\"],[\"77400.70\",\"0.005\"]],\"st\":1}"}
{"received_at_ns": 1787949671472162973, "payload": "{\"e\":\"depthUpdate\",\"E\":1787949671404,\"T\":1787949671403,\"s\":\"BTCUSDT\",\"ps\":\"BTCUSDT\",\"U\":11417389049206,\"u\":11417389074715,\"pu\":11417389049063,\"b\":[[\"77397.90\",\"4.912\"],[\"77397.80\",\"0.003\"],[\"77397.70\",\"0.091\"],[\"77397.60\",\"0.006\"],[\"77397.50\",\"0.011\"],[\"77397.30\",\"0.004\"],[\"77397.10\",\"0.016\"],[\"77396.90\",\"0.002\"],[\"77396.50\",\"0.078\"],[\"77396.30\",\"0.002\"],[\"77396.20\",\"0.079\"],[\"77396.10\",\"0.051\"],[\"77396.00\",\"0.078\"],[\"77395.60\",\"0.081\"],[\"77395.50\",\"0.001\"],[\"77395.40\",\"0.001\"],[\"77395.30\",\"0.102\"],[\"77395.20\",\"0.001\"],[\"77395.10\",\"0.078\"],[\"77395.00\",\"0.004\"]],\"a\":[[\"77398.00\",\"3.668\"],[\"77398.10\",\"0.153\"],[\"77398.20\",\"0.001\"],[\"77398.30\",\"0.003\"],[\"77398.40\",\"0.004\"],[\"77398.60\",\"0.265\"],[\"77398.80\",\"0.011\"],[\"77399.10\",\"0.002\"],[\"77399.20\",\"0.078\"],[\"77399.40\",\"0.002\"],[\"77399.50\",\"0.078\"],[\"77399.60\",\"0.001\"],[\"77399.70\",\"0.003\"],[\"77400.00\",\"0.144\"],[\"77400.10\",\"0.078\"],[\"77400.20\",\"0.011\"],[\"77400.30\",\"0.004\"],[\"77400.40\",\"2.032\"],[\"77400.60\",\"0.006\"],[\"77400.70\",\"0.005\"]],\"st\":1}"}
{"received_at_ns": 1787949671976106062, "payload": "{\"e\":\"depthUpdate\",\"E\":1787949671908,\"T\":1787949671906,\"s\":\"BTCUSDT\",\"ps\":\"BTCUSDT\",\"U\":11417389074728,\"u\":11417389099434,\"pu\":11417389074715,\"b\":[[\"77397.90\",\"4.650\"],[\"77397.80\",\"0.003\"],[\"77397.70\",\"0.034\"],[\"77397.60\",\"0.006\"],[\"77397.50\",\"0.011\"],[\"77397.30\",\"0.004\"],[\"77397.10\",\"0.016\"],[\"77396.90\",\"0.002\"],[\"77396.30\",\"0.002\"],[\"77396.20\",\"0.001\"],[\"77396.10\",\"0.051\"],[\"77395.60\",\"0.003\"],[\"77395.50\",\"0.001\"],[\"77395.40\",\"0.001\"],[\"77395.30\",\"0.024\"],[\"77395.20\",\"0.001\"],[\"77395.00\",\"0.004\"],[\"77394.90\",\"0.001\"],[\"77394.80\",\"0.002\"],[\"77394.70\",\"0.001\"]],\"a\":[[\"77398.00\",\"3.717\"],[\"77398.10\",\"0.153\"],[\"77398.20\",\"0.001\"],[\"77398.30\",\"0.003\"],[\"77398.40\",\"0.004\"],[\"77398.50\",\"0.078\"],[\"77398.60\",\"0.265\"],[\"77398.80\",\"0.011\"],[\"77398.90\",\"0.078\"],[\"77399.10\",\"0.002\"],[\"77399.20\",\"0.078\"],[\"77399.40\",\"0.002\"],[\"77399.50\",\"0.078\"],[\"77399.60\",\"0.001\"],[\"77399.70\",\"0.003\"],[\"77399.90\",\"0.002\"],[\"77400.00\",\"0.144\"],[\"77400.10\",\"0.078\"],[\"77400.20\",\"0.011\"],[\"77400.30\",\"0.002\"]],\"st\":1}"}
{"received_at_ns": 1787949672479834091, "payload": "{\"e\":\"depthUpdate\",\"E\":1787949672412,\"T\":1787949672411,\"s\":\"BTCUSDT\",\"ps\":\"BTCUSDT\",\"U\":11417389099675,\"u\":11417389124390,\"pu\":11417389099434,\"b\":[[\"77397.90\",\"4.923\"],[\"77397.80\",\"0.003\"],[\"77397.70\",\"0.034\"],[\"77397.60\",\"0.006\"],[\"77397.50\",\"0.011\"],[\"77397.30\",\"0.004\"],[\"77397.10\",\"0.016\"],[\"77396.90\",\"0.002\"],[\"77396.30\",\"0.002\"],[\"77396.20\",\"0.001\"],[\"77396.10\",\"0.051\"],[\"77395.60\",\"0.003\"],[\"77395.50\",\"0.001\"],[\"77395.40\",\"0.001\"],[\"77395.30\",\"0.024\"],[\"77395.20\",\"0.001\"],[\"77395.00\",\"0.004\"],[\"77394.90\",\"0.001\"],[\"77394.80\",\"0.002\"],[\"77394.70\",\"0.001\"]],\"a\":[[\"77398.00\",\"3.501\"],[\"77398.10\",\"0.153\"],[\"77398.20\",\"0.001\"],[\"77398.30\",\"0.003\"],[\"77398.40\",\"0.004\"],[\"77398.50\",\"0.078\"],[\"77398.60\",\"0.265\"],[\"77398.80\",\"0.011\"],[\"77398.90\",\"0.078\"],[\"77399.10\",\"0.002\"],[\"77399.20\",\"0.078\"],[\"77399.40\",\"0.002\"],[\"77399.50\",\"0.078\"],[\"77399.60\",\"0.001\"],[\"77399.70\",\"0.003\"],[\"77400.00\",\"0.146\"],[\"77400.10\",\"0.078\"],[\"77400.20\",\"0.011\"],[\"77400.30\",\"0.002\"],[\"77400.40\",\"2.032\"]],\"st\":1}"}
{"received_at_ns": 1787949672984062310, "payload": "{\"e\":\"depthUpdate\",\"E\":1787949672916,\"T\":1787949672914,\"s\":\"BTCUSDT\",\"ps\":\"BTCUSDT\",\"U\":11417389124446,\"u\":11417389147278,\"pu\":11417389124390,\"b\":[[\"77397.90\",\"4.715\"],[\"77397.80\",\"0.003\"],[\"77397.70\",\"0.034\"],[\"77397.60\",\"0.006\"],[\"77397.50\",\"0.011\"],[\"77397.30\",\"0.004\"],[\"77397.10\",\"0.016\"],[\"77396.90\",\"0.002\"],[\"77396.30\",\"0.002\"],[\"77396.20\",\"0.001\"],[\"77396.10\",\"0.051\"],[\"77395.60\",\"0.003\"],[\"77395.50\",\"0.001\"],[\"77395.40\",\"0.001\"],[\"77395.30\",\"0.024\"],[\"77395.20\",\"0.001\"],[\"77395.00\",\"0.004\"],[\"77394.90\",\"0.001\"],[\"77394.80\",\"0.002\"],[\"77394.70\",\"0.001\"]],\"a\":[[\"77398.00\",\"3.688\"],[\"77398.10\",\"0.153\"],[\"77398.20\",\"0.001\"],[\"77398.30\",\"0.003\"],[\"77398.40\",\"0.004\"],[\"77398.50\",\"0.078\"],[\"77398.60\",\"0.265\"],[\"77398.80\",\"0.011\"],[\"77398.90\",\"0.078\"],[\"77399.10\",\"0.002\"],[\"77399.20\",\"0.078\"],[\"77399.40\",\"0.002\"],[\"77399.50\",\"0.078\"],[\"77399.60\",\"0.001\"],[\"77399.70\",\"0.003\"],[\"77400.00\",\"0.146\"],[\"77400.10\",\"0.078\"],[\"77400.20\",\"0.011\"],[\"77400.30\",\"0.004\"],[\"77400.40\",\"2.032\"]],\"st\":1}"}
{"received_at_ns": 1787949673487772459, "payload": "{\"e\":\"depthUpdate\",\"E\":1787949673420,\"T\":1787949673417,\"s\":\"BTCUSDT\",\"ps\":\"BTCUSDT\",\"U\":11417389147409,\"u\":11417389171096,\"pu\":11417389147278,\"b\":[[\"77397.90\",\"4.722\"],[\"77397.80\",\"0.003\"],[\"77397.70\",\"0.034\"],[\"77397.60\",\"0.006\"],[\"77397.50\",\"0.011\"],[\"77397.30\",\"0.004\"],[\"77397.10\",\"0.016\"],[\"77396.90\",\"0.002\"],[\"77396.30\",\"0.002\"],[\"77396.20\",\"0.001\"],[\"77396.10\",\"0.051\"],[\"77395.60\",\"0.003\"],[\"77395.50\",\"0.001\"],[\"77395.40\",\"0.001\"],[\"77395.30\",\"0.024\"],[\"77395.20\",\"0.001\"],[\"77395.00\",\"0.004\"],[\"77394.90\",\"0.001\"],[\"77394.80\",\"0.002\"],[\"77394.70\",\"0.001\"]],\"a\":[[\"77398.00\",\"3.721\"],[\"77398.10\",\"0.153\"],[\"77398.20\",\"0.001\"],[\"77398.30\",\"0.003\"],[\"77398.40\",\"0.005\"],[\"77398.50\",\"0.078\"],[\"77398.60\",\"0.265\"],[\"77398.80\",\"0.011\"],[\"77398.90\",\"0.078\"],[\"77399.10\",\"0.002\"],[\"77399.20\",\"0.078\"],[\"77399.40\",\"0.002\"],[\"77399.50\",\"0.078\"],[\"77399.60\",\"0.001\"],[\"77399.70\",\"0.003\"],[\"77400.00\",\"0.146\"],[\"77400.10\",\"0.078\"],[\"77400.20\",\"0.011\"],[\"77400.30\",\"0.004\"],[\"77400.40\",\"2.032\"]],\"st\":1}"}
{"received_at_ns": 1787949673992179908, "payload": "{\"e\":\"depthUpdate\",\"E\":1787949673924,\"T\":1787949673921,\"s\":\"BTCUSDT\",\"ps\":\"BTCUSDT\",\"U\":11417389171280,\"u\":11417389193405,\"pu\":11417389171096,\"b\":[[\"77397.90\",\"4.960\"],[\"77397.80\",\"0.003\"],[\"77397.70\",\"0.034\"],[\"77397.60\",\"0.006\"],[\"77397.50\",\"0.011\"],[\"77397.30\",\"0.004\"],[\"77397.10\",\"0.016\"],[\"77396.90\",\"0.002\"],[\"77396.30\",\"0.002\"],[\"77396.20\",\"0.001\"],[\"77396.10\",\"0.051\"],[\"77395.60\",\"0.003\"],[\"77395.50\",\"0.001\"],[\"77395.40\",\"0.001\"],[\"77395.30\",\"0.007\"],[\"77395.20\",\"0.016\"],[\"77395.00\",\"0.004\"],[\"77394.90\",\"0.001\"],[\"77394.80\",\"0.002\"],[\"77394.70\",\"0.001\"]],\"a\":[[\"77398.00\",\"3.567\"],[\"77398.10\",\"0.153\"],[\"77398.20\",\"0.001\"],[\"77398.30\",\"0.003\"],[\"77398.40\",\"0.005\"],[\"77398.50\",\"0.078\"],[\"77398.60\",\"0.265\"],[\"77398.80\",\"0.011\"],[\"77398.90\",\"0.078\"],[\"77399.10\",\"0.002\"],[\"77399.20\",\"0.078\"],[\"77399.40\",\"0.002\"],[\"77399.50\",\"0.078\"],[\"77399.60\",\"0.001\"],[\"77399.70\",\"0.003\"],[\"77400.00\",\"0.146\"],[\"77400.10\",\"0.078\"],[\"77400.20\",\"0.011\"],[\"77400.30\",\"0.004\"],[\"77400.40\",\"2.032\"]],\"st\":1}"}
{"received_at_ns": 1787949674496020727, "payload": "{\"e\":\"depthUpdate\",\"E\":1787949674428,\"T\":1787949674427,\"s\":\"BTCUSDT\",\"ps\":\"BTCUSDT\",\"U\":11417389193546,\"u\":11417389216869,\"pu\":11417389193405,\"b\":[[\"77397.90\",\"4.964\"],[\"77397.80\",\"0.003\"],[\"77397.70\",\"0.034\"],[\"77397.60\",\"0.006\"],[\"77397.50\",\"0.011\"],[\"77397.30\",\"0.004\"],[\"77397.10\",\"0.016\"],[\"77396.90\",\"0.002\"],[\"77396.30\",\"0.002\"],[\"77396.20\",\"0.001\"],[\"77396.10\",\"0.051\"],[\"77395.60\",\"0.003\"],[\"77395.50\",\"0.001\"],[\"77395.40\",\"0.001\"],[\"77395.30\",\"0.007\"],[\"77395.20\",\"0.016\"],[\"77395.00\",\"0.004\"],[\"77394.90\",\"0.001\"],[\"77394.80\",\"0.002\"],[\"77394.70\",\"0.001\"]],\"a\":[[\"77398.00\",\"3.866\"],[\"77398.10\",\"0.154\"],[\"77398.20\",\"0.001\"],[\"77398.30\",\"0.003\"],[\"77398.40\",\"0.004\"],[\"77398.50\",\"0.078\"],[\"77398.60\",\"0.265\"],[\"77398.80\",\"0.011\"],[\"77398.90\",\"0.078\"],[\"77399.10\",\"0.002\"],[\"77399.20\",\"0.078\"],[\"77399.40\",\"0.002\"],[\"77399.50\",\"0.078\"],[\"77399.60\",\"0.001\"],[\"77399.70\",\"0.003\"],[\"77399.80\",\"0.006\"],[\"77400.00\",\"0.146\"],[\"77400.10\",\"0.078\"],[\"77400.20\",\"0.011\"],[\"77400.30\",\"0.002\"]],\"st\":1}"}
{"received_at_ns": 1787949675000279536, "payload": "{\"e\":\"depthUpdate\",\"E\":1787949674932,\"T\":1787949674929,\"s\":\"BTCUSDT\",\"ps\":\"BTCUSDT\",\"U\":11417389216920,\"u\":11417389244352,\"pu\":11417389216869,\"b\":[[\"77397.90\",\"10.186\"],[\"77397.80\",\"0.004\"],[\"77397.70\",\"0.034\"],[\"77397.60\",\"0.006\"],[\"77397.50\",\"0.011\"],[\"77397.30\",\"0.004\"],[\"77397.10\",\"0.016\"],[\"77396.90\",\"0.002\"],[\"77396.30\",\"0.002\"],[\"77396.20\",\"0.001\"],[\"77396.10\",\"0.051\"],[\"77395.60\",\"0.003\"],[\"77395.50\",\"0.001\"],[\"77395.40\",\"0.001\"],[\"77395.30\",\"0.007\"],[\"77395.20\",\"0.016\"],[\"77395.00\",\"0.004\"],[\"77394.90\",\"0.001\"],[\"77394.80\",\"0.002\"],[\"77394.70\",\"0.001\"]],\"a\":[[\"77398.00\",\"4.406\"],[\"77398.10\",\"0.153\"],[\"77398.20\",\"0.001\"],[\"77398.30\",\"0.003\"],[\"77398.40\",\"0.004\"],[\"77398.50\",\"0.078\"],[\"77398.60\",\"0.265\"],[\"77398.80\",\"0.011\"],[\"77398.90\",\"0.078\"],[\"77399.10\",\"0.002\"],[\"77399.20\",\"0.078\"],[\"77399.40\",\"0.002\"],[\"77399.50\",\"0.078\"],[\"77399.60\",\"0.001\"],[\"77399.70\",\"0.003\"],[\"77400.00\",\"0.146\"],[\"77400.10\",\"0.083\"],[\"77400.20\",\"0.011\"],[\"77400.30\",\"0.004\"],[\"77400.40\",\"2.032\"]],\"st\":1}"}
{"received_at_ns": 1787949675503950315, "payload": "{\"e\":\"depthUpdate\",\"E\":1787949675436,\"T\":1787949675434,\"s\":\"BTCUSDT\",\"ps\":\"BTCUSDT\",\"U\":11417389244584,\"u\":11417389282835,\"pu\":11417389244352,\"b\":[[\"77397.90\",\"10.201\"],[\"77397.80\",\"0.004\"],[\"77397.70\",\"0.034\"],[\"77397.60\",\"0.006\"],[\"77397.50\",\"0.011\"],[\"77397.30\",\"0.004\"],[\"77397.10\",\"0.016\"],[\"77396.90\",\"0.002\"],[\"77396.30\",\"0.002\"],[\"77396.20\",\"0.001\"],[\"77396.10\",\"0.051\"],[\"77395.60\",\"0.003\"],[\"77395.50\",\"0.001\"],[\"77395.40\",\"0.001\"],[\"77395.30\",\"0.007\"],[\"77395.20\",\"0.016\"],[\"77395.00\",\"0.004\"],[\"77394.90\",\"0.001\"],[\"77394.80\",\"0.002\"],[\"77394.70\",\"0.001\"]],\"a\":[[\"77398.00\",\"4.410\"],[\"77398.10\",\"0.153\"],[\"77398.20\",\"0.001\"],[\"77398.30\",\"0.003\"],[\"77398.40\",\"0.004\"],[\"77398.50\",\"0.078\"],[\"77398.60\",\"0.265\"],[\"77398.80\",\"0.011\"],[\"77398.90\",\"0.078\"],[\"77399.10\",\"0.002\"],[\"77399.20\",\"0.078\"],[\"77399.40\",\"0.002\"],[\"77399.50\",\"0.078\"],[\"77399.60\",\"0.001\"],[\"77399.70\",\"0.003\"],[\"77400.00\",\"0.146\"],[\"77400.10\",\"0.078\"],[\"77400.20\",\"0.011\"],[\"77400.30\",\"0.004\"],[\"77400.40\",\"2.032\"]],\"st\":1}"}
{"received_at_ns": 1787949676008308014, "payload": "{\"e\":\"depthUpdate\",\"E\":1787949675940,\"T\":1787949675938,\"s\":\"BTCUSDT\",\"ps\":\"BTCUSDT\",\"U\":11417389283009,\"u\":11417389318180,\"pu\":11417389282835,\"b\":[[\"77397.90\",\"10.163\"],[\"77397.80\",\"0.004\"],[\"77397.70\",\"0.020\"],[\"77397.60\",\"0.006\"],[\"77397.50\",\"0.011\"],[\"77397.40\",\"0.024\"],[\"77397.30\",\"0.004\"],[\"77397.10\",\"0.016\"],[\"77396.90\",\"0.002\"],[\"77396.30\",\"0.002\"],[\"77396.20\",\"0.001\"],[\"77396.10\",\"0.051\"],[\"77395.60\",\"0.081\"],[\"77395.50\",\"0.001\"],[\"77395.40\",\"0.001\"],[\"77395.30\",\"0.007\"],[\"77395.20\",\"0.094\"],[\"77395.00\",\"0.004\"],[\"77394.90\",\"0.001\"],[\"77394.80\",\"0.080\"]],\"a\":[[\"77398.00\",\"4.374\"],[\"77398.10\",\"0.153\"],[\"77398.20\",\"0.001\"],[\"77398.30\",\"0.003\"],[\"77398.40\",\"0.004\"],[\"77398.60\",\"0.265\"],[\"77398.80\",\"0.089\"],[\"77399.10\",\"0.002\"],[\"77399.20\",\"0.078\"],[\"77399.40\",\"0.002\"],[\"77399.50\",\"0.078\"],[\"77399.60\",\"0.001\"],[\"77399.70\",\"0.003\"],[\"77400.00\",\"0.146\"],[\"77400.10\",\"0.078\"],[\"77400.20\",\"0.011\"],[\"77400.30\",\"0.004\"],[\"77400.40\",\"2.032\"],[\"77400.50\",\"0.002\"],[\"77400.70\",\"0.003\"]],\"st\":1}"}
{"received_at_ns": 1787949676511836883, "payload": "{\"e\":\"depthUpdate\",\"E\":1787949676444,\"T\":1787949676441,\"s\":\"BTCUSDT\",\"ps\":\"BTCUSDT\",\"U\":11417389318288,\"u\":11417389350948,\"pu\":11417389318180,\"b\":[[\"77397.90\",\"10.188\"],[\"77397.80\",\"0.004\"],[\"77397.70\",\"0.034\"],[\"77397.60\",\"0.006\"],[\"77397.50\",\"0.011\"],[\"77397.30\",\"0.004\"],[\"77397.10\",\"0.016\"],[\"77396.90\",\"0.002\"],[\"77396.30\",\"0.002\"],[\"77396.20\",\"0.001\"],[\"77396.10\",\"0.051\"],[\"77395.60\",\"0.003\"],[\"77395.50\",\"0.001\"],[\"77395.40\",\"0.079\"],[\"77395.30\",\"0.007\"],[\"77395.20\",\"0.001\"],[\"77395.10\",\"0.078\"],[\"77395.00\",\"0.004\"],[\"77394.90\",\"0.001\"],[\"77394.80\",\"0.002\"]],\"a\":[[\"77398.00\",\"4.332\"],[\"77398.10\",\"0.154\"],[\"77398.20\",\"0.001\"],[\"77398.30\",\"0.003\"],[\"77398.40\",\"0.004\"],[\"77398.60\",\"0.265\"],[\"77398.80\",\"0.089\"],[\"77399.10\",\"0.002\"],[\"77399.20\",\"0.078\"],[\"77399.40\",\"0.002\"],[\"77399.50\",\"0.078\"],[\"77399.60\",\"0.001\"],[\"77399.70\",\"0.003\"],[\"77400.00\",\"0.146\"],[\"77400.10\",\"0.078\"],[\"77400.20\",\"0.011\"],[\"77400.30\",\"0.002\"],[\"77400.40\",\"2.032\"],[\"77400.50\",\"0.002\"],[\"77400.70\",\"0.003\"]],\"st\":1}"}
{"received_at_ns": 1787949677016407032, "payload": "{\"e\":\"depthUpdate\",\"E\":1787949676948,\"T\":1787949676945,\"s\":\"BTCUSDT\",\"ps\":\"BTCUSDT\",\"U\":11417389351154,\"u\":11417389385776,\"pu\":11417389350948,\"b\":[[\"77397.90\",\"9.865\"],[\"77397.80\",\"0.017\"],[\"77397.70\",\"0.020\"],[\"77397.60\",\"0.006\"],[\"77397.50\",\"0.011\"],[\"77397.30\",\"0.004\"],[\"77397.10\",\"0.016\"],[\"77396.90\",\"0.002\"],[\"77396.50\",\"0.001\"],[\"77396.30\",\"0.002\"],[\"77396.20\",\"0.001\"],[\"77396.10\",\"0.016\"],[\"77395.60\",\"0.003\"],[\"77395.50\",\"0.001\"],[\"77395.40\",\"0.001\"],[\"77395.30\",\"0.010\"],[\"77395.20\",\"0.001\"],[\"77395.00\",\"0.004\"],[\"77394.90\",\"0.001\"],[\"77394.80\",\"0.002\"]],\"a\":[[\"77398.00\",\"3.435\"],[\"77398.10\",\"0.154\"],[\"77398.20\",\"0.001\"],[\"77398.30\",\"0.003\"],[\"77398.40\",\"0.003\"],[\"77398.60\",\"0.034\"],[\"77398.80\",\"0.011\"],[\"77399.10\",\"0.002\"],[\"77399.40\",\"0.002\"],[\"77399.60\",\"0.001\"],[\"77399.70\",\"0.003\"],[\"77400.00\",\"0.146\"],[\"77400.20\",\"0.011\"],[\"77400.30\",\"0.003\"],[\"77400.40\",\"1.954\"],[\"77400.70\",\"0.003\"],[\"77400.80\",\"0.077\"],[\"77400.90\",\"0.125\"],[\"77401.00\",\"0.001\"],[\"77401.10\",\"0.020\"]],\"st\":1}"}
{"received_at_ns": 1787949677519750271, "payload": "{\"e\":\"depthUpdate\",\"E\":1787949677452,\"T\":1787949677449,\"s\":\"BTCUSDT\",\"ps\":\"BTCUSDT\",\"U\":11417389386029,\"u\":11417389415470,\"pu\":11417389385776,\"b\":[[\"77397.90\",\"9.882\"],[\"77397.80\",\"0.004\"],[\"77397.70\",\"0.020\"],[\"77397.60\",\"0.026\"],[\"77397.50\",\"0.011\"],[\"77397.30\",\"0.004\"],[\"77397.10\",\"0.016\"],[\"77396.90\",\"0.002\"],[\"77396.50\",\"0.001\"],[\"77396.30\",\"0.002\"],[\"77396.20\",\"0.001\"],[\"77396.10\",\"0.018\"],[\"77395.60\",\"0.003\"],[\"77395.50\",\"0.079\"],[\"77395.40\",\"0.001\"],[\"77395.30\",\"0.010\"],[\"77395.20\",\"0.001\"],[\"77395.10\",\"0.080\"],[\"77395.00\",\"0.004\"],[\"77394.90\",\"0.079\"]],\"a\":[[\"77398.00\",\"3.411\"],[\"77398.10\",\"0.154\"],[\"77398.20\",\"0.001\"],[\"77398.30\",\"0.003\"],[\"77398.40\",\"0.003\"],[\"77398.60\",\"0.034\"],[\"77398.80\",\"0.011\"],[\"77399.10\",\"0.002\"],[\"77399.40\",\"0.002\"],[\"77399.60\",\"0.001\"],[\"77399.70\",\"0.003\"],[\"77400.00\",\"0.146\"],[\"77400.20\",\"0.020\"],[\"77400.30\",\"0.003\"],[\"77400.40\",\"1.954\"],[\"77400.70\",\"0.003\"],[\"77400.80\",\"0.077\"],[\"77400.90\",\"0.125\"],[\"77401.00\",\"0.001\"],[\"77401.10\",\"0.020\"]],\"st\":1}"}
{"received_at_ns": 1787949678024332080, "payload": "{\"e\":\"depthUpdate\",\"E\":1787949677956,\"T\":1787949677954,\"s\":\"BTCUSDT\",\"ps\":\"BTCUSDT\",\"U\":11417389415606,\"u\":11417389443941,\"pu\":11417389415470,\"b\":[[\"77397.90\",\"9.867\"],[\"77397.80\",\"0.004\"],[\"77397.70\",\"0.020\"],[\"77397.60\",\"0.026\"],[\"77397.50\",\"0.011\"],[\"77397.30\",\"0.004\"],[\"77397.10\",\"0.016\"],[\"77396.90\",\"0.002\"],[\"77396.50\",\"0.001\"],[\"77396.30\",\"0.002\"],[\"77396.20\",\"0.001\"],[\"77396.10\",\"0.096\"],[\"77395.60\",\"0.081\"],[\"77395.50\",\"0.001\"],[\"77395.40\",\"0.001\"],[\"77395.30\",\"0.025\"],[\"77395.20\",\"0.001\"],[\"77395.10\",\"0.002\"],[\"77395.00\",\"0.082\"],[\"77394.90\",\"0.001\"]],\"a\":[[\"77398.00\",\"3.333\"],[\"77398.10\",\"0.255\"],[\"77398.20\",\"0.001\"],[\"77398.30\",\"0.003\"],[\"77398.40\",\"0.003\"],[\"77398.60\",\"0.034\"],[\"77398.80\",\"0.011\"],[\"77399.10\",\"0.002\"],[\"77399.40\",\"0.002\"],[\"77399.60\",\"0.001\"],[\"77399.70\",\"0.003\"],[\"77399.90\",\"0.078\"],[\"77400.00\",\"0.146\"],[\"77400.10\",\"0.078\"],[\"77400.20\",\"0.020\"],[\"77400.30\",\"0.003\"],[\"77400.70\",\"0.003\"],[\"77400.80\",\"0.077\"],[\"77400.90\",\"0.125\"],[\"77401.00\",\"0.001\"]],\"st\":1}"}
{"received_at_ns": 1787949678527751619, "payload": "{\"e\":\"depthUpdate\",\"E\":1787949678460,\"T\":1787949678459,\"s\":\"BTCUSDT\",\"ps\":\"BTCUSDT\",\"U\":11417389444045,\"u\":11417389513511,\"pu\":11417389443941,\"b\":[[\"77397.90\",\"9.883\"],[\"77397.80\",\"0.017\"],[\"77397.70\",\"0.020\"],[\"77397.60\",\"0.006\"],[\"77397.50\",\"0.011\"],[\"77397.30\",\"0.004\"],[\"77397.10\",\"0.016\"],[\"77396.90\",\"0.002\"],[\"77396.30\",\"0.002\"],[\"77396.20\",\"0.001\"],[\"77396.10\",\"0.018\"],[\"77395.60\",\"0.003\"],[\"77395.50\",\"0.001\"],[\"77395.40\",\"0.001\"],[\"77395.30\",\"0.025\"],[\"77395.20\",\"0.001\"],[\"77395.10\",\"0.002\"],[\"77395.00\",\"0.004\"],[\"77394.90\",\"0.001\"],[\"77394.80\",\"0.002\"]],\"a\":[[\"77398.00\",\"3.685\"],[\"77398.10\",\"0.255\"],[\"77398.20\",\"0.001\"],[\"77398.30\",\"0.003\"],[\"77398.40\",\"0.003\"],[\"77398.60\",\"0.112\"],[\"77398.80\",\"0.011\"],[\"77398.90\",\"0.078\"],[\"77399.10\",\"0.080\"],[\"77399.40\",\"0.080\"],[\"77399.60\",\"0.079\"],[\"77399.70\",\"0.003\"],[\"77399.90\",\"0.078\"],[\"77400.00\",\"0.146\"],[\"77400.10\",\"0.078\"],[\"77400.20\",\"0.020\"],[\"77400.30\",\"0.002\"],[\"77400.70\",\"0.003\"],[\"77400.80\",\"0.077\"],[\"77400.90\",\"0.125\"]],\"st\":1}"}
{"received_at_ns": 1787949679032330217, "payload": "{\"e\":\"depthUpdate\",\"E\":1787949678964,\"T\":1787949678962,\"s\":\"BTCUSDT\",\"ps\":\"BTCUSDT\",\"U\":11417389513709,\"u\":11417389568491,\"pu\":11417389513511,\"b\":[[\"77397.90\",\"9.916\"],[\"77397.80\",\"0.082\"],[\"77397.70\",\"0.020\"],[\"77397.60\",\"0.026\"],[\"77397.50\",\"0.011\"],[\"77397.30\",\"0.004\"],[\"77397.10\",\"0.015\"],[\"77396.90\",\"0.002\"],[\"77396.30\",\"0.002\"],[\"77396.20\",\"0.001\"],[\"77396.10\",\"0.016\"],[\"77395.70\",\"0.078\"],[\"77395.60\",\"0.004\"],[\"77395.50\",\"0.001\"],[\"77395.40\",\"0.001\"],[\"77395.30\",\"0.024\"],[\"77395.20\",\"0.001\"],[\"77395.10\",\"0.002\"],[\"77395.00\",\"0.004\"],[\"77394.90\",\"0.001\"]],\"a\":[[\"77398.00\",\"3.601\"],[\"77398.10\",\"0.154\"],[\"77398.20\",\"0.001\"],[\"77398.30\",\"0.003\"],[\"77398.40\",\"0.003\"],[\"77398.60\",\"0.034\"],[\"77398.80\",\"0.011\"],[\"77399.10\",\"0.002\"],[\"77399.40\",\"0.002\"],[\"77399.60\",\"0.001\"],[\"77399.70\",\"0.003\"],[\"77400.00\",\"0.146\"],[\"77400.10\",\"0.078\"],[\"77400.20\",\"0.020\"],[\"77400.30\",\"0.004\"],[\"77400.70\",\"0.003\"],[\"77400.80\",\"0.077\"],[\"77400.90\",\"0.125\"],[\"77401.00\",\"0.001\"],[\"77401.10\",\"0.020\"]],\"st\":1}"}
{"received_at_ns": 1787949679535611107, "payload": "{\"e\":\"depthUpdate\",\"E\":1787949679468,\"T\":1787949679466,\"s\":\"BTCUSDT\",\"ps\":\"BTCUSDT\",\"U\":11417389568803,\"u\":11417389602382,\"pu\":11417389568491,\"b\":[[\"77397.90\",\"9.922\"],[\"77397.80\",\"0.082\"],[\"77397.70\",\"0.020\"],[\"77397.60\",\"0.026\"],[\"77397.50\",\"0.011\"],[\"77397.30\",\"0.004\"],[\"77397.10\",\"0.015\"],[\"77396.90\",\"0.002\"],[\"77396.50\",\"0.001\"],[\"77396.30\",\"0.002\"],[\"77396.20\",\"0.001\"],[\"77396.10\",\"0.018\"],[\"77395.80\",\"0.001\"],[\"77395.70\",\"0.078\"],[\"77395.60\",\"0.003\"],[\"77395.50\",\"0.001\"],[\"77395.40\",\"0.001\"],[\"77395.30\",\"0.024\"],[\"77395.20\",\"0.003\"],[\"77395.10\",\"0.259\"]],\"a\":[[\"77398.00\",\"3.387\"],[\"77398.10\",\"0.154\"],[\"77398.20\",\"0.001\"],[\"77398.30\",\"0.003\"],[\"77398.40\",\"0.003\"],[\"77398.50\",\"0.002\"],[\"77398.60\",\"0.034\"],[\"77398.80\",\"0.011\"],[\"77399.10\",\"0.002\"],[\"77399.40\",\"0.002\"],[\"77399.60\",\"0.001\"],[\"77399.70\",\"0.003\"],[\"77400.00\",\"0.144\"],[\"77400.20\",\"0.020\"],[\"77400.30\",\"0.002\"],[\"77400.70\",\"0.003\"],[\"77400.80\",\"0.077\"],[\"77400.90\",\"0.125\"],[\"77401.00\",\"0.001\"],[\"77401.10\",\"0.020\"]],\"st\":1}"}
{"received_at_ns": 1787949680040189726, "payload": "{\"e\":\"depthUpdate\",\"E\":1787949679972,\"T\":1787949679971,\"s\":\"BTCUSDT\",\"ps\":\"BTCUSDT\",\"U\":11417389602481,\"u\":11417389642880,\"pu\":11417389602382,\"b\":[[\"77397.90\",\"10.047\"],[\"77397.80\",\"0.082\"],[\"77397.70\",\"0.020\"],[\"77397.60\",\"0.026\"],[\"77397.50\",\"0.011\"],[\"77397.30\",\"0.004\"],[\"77397.10\",\"0.015\"],[\"77396.90\",\"0.002\"],[\"77396.60\",\"0.004\"],[\"77396.50\",\"0.001\"],[\"77396.30\",\"0.002\"],[\"77396.20\",\"0.001\"],[\"77396.10\",\"0.018\"],[\"77395.80\",\"0.005\"],[\"77395.70\",\"0.096\"],[\"77395.60\",\"0.003\"],[\"77395.50\",\"0.001\"],[\"77395.40\",\"0.001\"],[\"77395.30\",\"0.024\"],[\"77395.20\",\"0.003\"]],\"a\":[[\"77398.00\",\"1.547\"],[\"77398.10\",\"0.154\"],[\"77398.20\",\"0.001\"],[\"77398.30\",\"0.003\"],[\"77398.40\",\"0.003\"],[\"77398.60\",\"0.034\"],[\"77398.80\",\"0.011\"],[\"77399.10\",\"0.002\"],[\"77399.40\",\"0.002\"],[\"77399.60\",\"0.001\"],[\"77399.70\",\"0.003\"],[\"77400.00\",\"0.146\"],[\"77400.20\",\"0.020\"],[\"77400.30\",\"0.002\"],[\"77400.70\",\"0.003\"],[\"77400.80\",\"0.001\"],[\"77400.90\",\"0.125\"],[\"77401.00\",\"0.001\"],[\"77401.10\",\"0.020\"],[\"77401.20\",\"0.231\"]],\"st\":1}"}
{"received_at_ns": 1787949680543828704, "payload": "{\"e\":\"depthUpdate\",\"E\":1787949680476,\"T\":1787949680475,\"s\":\"BTCUSDT\",\"ps\":\"BTCUSDT\",\"U\":11417389643025,\"u\":11417389682207,\"pu\":11417389642880,\"b\":[[\"77397.90\",\"10.061\"],[\"77397.80\",\"0.082\"],[\"77397.70\",\"0.020\"],[\"77397.60\",\"0.026\"],[\"77397.50\",\"0.011\"],[\"77397.30\",\"0.004\"],[\"77397.10\",\"0.015\"],[\"77397.00\",\"0.049\"],[\"77396.90\",\"0.002\"],[\"77396.60\",\"0.003\"],[\"77396.50\",\"0.001\"],[\"77396.30\",\"0.002\"],[\"77396.20\",\"0.001\"],[\"77396.10\",\"0.018\"],[\"77395.70\",\"0.078\"],[\"77395.60\",\"0.027\"],[\"77395.50\",\"0.001\"],[\"77395.40\",\"0.003\"],[\"77395.30\",\"0.024\"],[\"77395.20\",\"0.001\"]],\"a\":[[\"77398.00\",\"1.797\"],[\"77398.10\",\"0.154\"],[\"77398.20\",\"0.001\"],[\"77398.30\",\"0.003\"],[\"77398.40\",\"0.003\"],[\"77398.60\",\"0.034\"],[\"77398.80\",\"0.011\"],[\"77399.10\",\"0.002\"],[\"77399.40\",\"0.002\"],[\"77399.60\",\"0.001\"],[\"77399.70\",\"0.003\"],[\"77400.00\",\"0.146\"],[\"77400.20\",\"0.035\"],[\"77400.30\",\"0.002\"],[\"77400.70\",\"0.003\"],[\"77400.80\",\"0.001\"],[\"77400.90\",\"0.125\"],[\"77401.00\",\"0.001\"],[\"77401.10\",\"0.020\"],[\"77401.20\",\"0.231\"]],\"st\":1}"}
{"received_at_ns": 1787949681048049124, "payload": "{\"e\":\"depthUpdate\",\"E\":1787949680980,\"T\":1787949680977,\"s\":\"BTCUSDT\",\"ps\":\"BTCUSDT\",\"U\":11417389682239,\"u\":11417389748757,\"pu\":11417389682207,\"b\":[[\"77397.90\",\"10.073\"],[\"77397.80\",\"0.082\"],[\"77397.70\",\"0.021\"],[\"77397.60\",\"0.006\"],[\"77397.50\",\"0.017\"],[\"77397.30\",\"0.004\"],[\"77397.20\",\"0.032\"],[\"77397.10\",\"0.015\"],[\"77397.00\",\"0.048\"],[\"77396.90\",\"0.002\"],[\"77396.60\",\"0.003\"],[\"77396.50\",\"0.001\"],[\"77396.40\",\"0.018\"],[\"77396.30\",\"0.002\"],[\"77396.20\",\"0.001\"],[\"77396.10\",\"0.018\"],[\"77395.90\",\"0.019\"],[\"77395.70\",\"0.078\"],[\"77395.60\",\"0.003\"],[\"77395.50\",\"0.001\"]],\"a\":[[\"77398.00\",\"0.735\"],[\"77398.10\",\"0.153\"],[\"77398.20\",\"0.001\"],[\"77398.30\",\"0.003\"],[\"77398.40\",\"0.003\"],[\"77398.60\",\"0.034\"],[\"77398.80\",\"0.011\"],[\"77399.10\",\"0.002\"],[\"77399.40\",\"0.002\"],[\"77399.60\",\"0.001\"],[\"77400.00\",\"0.146\"],[\"77400.20\",\"0.035\"],[\"77400.30\",\"0.002\"],[\"77400.70\",\"0.003\"],[\"77400.80\",\"0.001\"],[\"77400.90\",\"0.125\"],[\"77401.10\",\"0.020\"],[\"77401.20\",\"0.231\"],[\"77401.40\",\"0.002\"],[\"77401.60\",\"0.001\"]],\"st\":1}"}
{"received_at_ns": 1787949681551725502, "payload": "{\"e\":\"depthUpdate\",\"E\":1787949681484,\"T\":1787949681482,\"s\":\"BTCUSDT\",\"ps\":\"BTCUSDT\",\"U\":11417389749228,\"u\":11417389810719,\"pu\":11417389748757,\"b\":[[\"77397.90\",\"10.075\"],[\"77397.80\",\"0.082\"],[\"77397.70\",\"0.027\"],[\"77397.60\",\"0.006\"],[\"77397.50\",\"0.011\"],[\"77397.30\",\"0.004\"],[\"77397.20\",\"0.132\"],[\"77397.10\",\"0.015\"],[\"77397.00\",\"0.048\"],[\"77396.90\",\"0.002\"],[\"77396.80\",\"0.018\"],[\"77396.60\",\"0.003\"],[\"77396.50\",\"0.020\"],[\"77396.30\",\"0.002\"],[\"77396.20\",\"0.001\"],[\"77396.10\",\"0.018\"],[\"77396.00\",\"0.051\"],[\"77395.80\",\"0.703\"],[\"77395.70\",\"0.078\"],[\"77395.60\",\"0.005\"]],\"a\":[[\"77398.00\",\"0.681\"],[\"77398.10\",\"0.153\"],[\"77398.20\",\"0.001\"],[\"77398.30\",\"0.003\"],[\"77398.40\",\"0.003\"],[\"77398.60\",\"0.034\"],[\"77398.80\",\"0.011\"],[\"77399.10\",\"0.002\"],[\"77399.40\",\"0.002\"],[\"77399.60\",\"0.001\"],[\"77400.00\",\"0.146\"],[\"77400.20\",\"0.035\"],[\"77400.30\",\"0.002\"],[\"77400.70\",\"0.003\"],[\"77400.80\",\"0.001\"],[\"77400.90\",\"0.125\"],[\"77401.10\",\"0.020\"],[\"77401.20\",\"0.231\"],[\"77401.40\",\"0.002\"],[\"77401.60\",\"0.001\"]],\"st\":1}"}
{"received_at_ns": 1787949682055964112, "payload": "{\"e\":\"depthUpdate\",\"E\":1787949681988,\"T\":1787949681985,\"s\":\"BTCUSDT\",\"ps\":\"BTCUSDT\",\"U\":11417389810993,\"u\":11417389889078,\"pu\":11417389810719,\"b\":[[\"77397.90\",\"10.070\"],[\"77397.80\",\"0.082\"],[\"77397.70\",\"0.027\"],[\"77397.60\",\"0.006\"],[\"77397.50\",\"0.011\"],[\"77397.30\",\"0.004\"],[\"77397.20\",\"0.132\"],[\"77397.10\",\"0.015\"],[\"77397.00\",\"0.066\"],[\"77396.90\",\"0.002\"],[\"77396.60\",\"0.003\"],[\"77396.50\",\"0.020\"],[\"77396.30\",\"0.002\"],[\"77396.20\",\"0.001\"],[\"77396.10\",\"0.018\"],[\"77396.00\",\"0.051\"],[\"77395.90\",\"0.001\"],[\"77395.80\",\"0.703\"],[\"77395.70\",\"0.078\"],[\"77395.60\",\"0.005\"]],\"a\":[[\"77398.00\",\"0.678\"],[\"77398.10\",\"0.153\"],[\"77398.20\",\"0.001\"],[\"77398.30\",\"0.003\"],[\"77398.40\",\"0.003\"],[\"77398.60\",\"0.034\"],[\"77398.80\",\"0.011\"],[\"77399.10\",\"0.002\"],[\"77399.40\",\"0.002\"],[\"77399.60\",\"0.001\"],[\"77400.00\",\"0.146\"],[\"77400.20\",\"0.035\"],[\"77400.30\",\"0.002\"],[\"77400.70\",\"0.003\"],[\"77400.80\",\"0.001\"],[\"77400.90\",\"0.125\"],[\"77401.10\",\"0.020\"],[\"77401.20\",\"0.231\"],[\"77401.40\",\"0.002\"],[\"77401.60\",\"0.001\"]],\"st\":1}"}
{"received_at_ns": 1787949682560281590, "payload": "{\"e\":\"depthUpdate\",\"E\":1787949682492,\"T\":1787949682490,\"s\":\"BTCUSDT\",\"ps\":\"BTCUSDT\",\"U\":11417389889356,\"u\":11417389935124,\"pu\":11417389889078,\"b\":[[\"77397.90\",\"10.304\"],[\"77397.80\",\"0.082\"],[\"77397.70\",\"0.027\"],[\"77397.60\",\"0.006\"],[\"77397.50\",\"0.011\"],[\"77397.30\",\"0.004\"],[\"77397.20\",\"0.132\"],[\"77397.10\",\"0.015\"],[\"77397.00\",\"0.048\"],[\"77396.90\",\"0.020\"],[\"77396.60\",\"0.003\"],[\"77396.50\",\"0.020\"],[\"77396.30\",\"0.002\"],[\"77396.20\",\"0.003\"],[\"77396.10\",\"0.018\"],[\"77396.00\",\"0.051\"],[\"77395.90\",\"0.001\"],[\"77395.80\",\"0.703\"],[\"77395.70\",\"0.078\"],[\"77395.60\",\"0.003\"]],\"a\":[[\"77398.00\",\"0.974\"],[\"77398.10\",\"0.153\"],[\"77398.20\",\"0.001\"],[\"77398.30\",\"0.003\"],[\"77398.40\",\"0.003\"],[\"77398.60\",\"0.034\"],[\"77398.80\",\"0.011\"],[\"77399.10\",\"0.002\"],[\"77399.40\",\"0.002\"],[\"77399.60\",\"0.001\"],[\"77400.00\",\"0.146\"],[\"77400.20\",\"0.035\"],[\"77400.30\",\"0.002\"],[\"77400.70\",\"0.003\"],[\"77400.80\",\"0.001\"],[\"77400.90\",\"0.125\"],[\"77401.10\",\"0.020\"],[\"77401.20\",\"0.231\"],[\"77401.40\",\"0.002\"],[\"77401.60\",\"0.001\"]],\"st\":1}"}
{"received_at_ns": 1787949683063914599, "payload": "{\"e\":\"depthUpdate\",\"E\":1787949682996,\"T\":1787949682994,\"s\":\"BTCUSDT\",\"ps\":\"BTCUSDT\",\"U\":11417389935332,\"u\":11417389978538,\"pu\":11417389935124,\"b\":[[\"77397.90\",\"10.346\"],[\"77397.80\",\"0.082\"],[\"77397.70\",\"0.027\"],[\"77397.60\",\"0.006\"],[\"77397.50\",\"0.011\"],[\"77397.30\",\"0.004\"],[\"77397.20\",\"0.132\"],[\"77397.10\",\"0.015\"],[\"77397.00\",\"0.048\"],[\"77396.90\",\"0.002\"],[\"77396.60\",\"0.003\"],[\"77396.50\",\"0.020\"],[\"77396.30\",\"0.002\"],[\"77396.20\",\"0.003\"],[\"77396.10\",\"0.018\"],[\"77396.00\",\"0.051\"],[\"77395.90\",\"0.001\"],[\"77395.80\",\"0.700\"],[\"77395.70\",\"0.081\"],[\"77395.60\",\"0.003\"]],\"a\":[[\"77398.00\",\"0.999\"],[\"77398.10\",\"0.153\"],[\"77398.20\",\"0.001\"],[\"77398.30\",\"0.003\"],[\"77398.40\",\"0.003\"],[\"77398.60\",\"0.034\"],[\"77398.80\",\"0.011\"],[\"77399.10\",\"0.002\"],[\"77399.40\",\"0.002\"],[\"77399.60\",\"0.001\"],[\"77400.00\",\"0.146\"],[\"77400.20\",\"0.035\"],[\"77400.30\",\"0.002\"],[\"77400.70\",\"0.003\"],[\"77400.80\",\"0.001\"],[\"77400.90\",\"0.125\"],[\"77401.10\",\"0.020\"],[\"77401.20\",\"0.231\"],[\"77401.40\",\"0.002\"],[\"77401.60\",\"0.001\"]],\"st\":1}"}
{"received_at_ns": 1787949683567768628, "payload": "{\"e\":\"depthUpdate\",\"E\":1787949683500,\"T\":1787949683498,\"s\":\"BTCUSDT\",\"ps\":\"BTCUSDT\",\"U\":11417389978860,\"u\":11417390016961,\"pu\":11417389978538,\"b\":[[\"77397.90\",\"10.363\"],[\"77397.80\",\"0.084\"],[\"77397.70\",\"0.026\"],[\"77397.60\",\"0.006\"],[\"77397.50\",\"0.011\"],[\"77397.30\",\"0.004\"],[\"77397.20\",\"0.149\"],[\"77397.10\",\"0.015\"],[\"77397.00\",\"0.048\"],[\"77396.90\",\"0.002\"],[\"77396.60\",\"0.003\"],[\"77396.50\",\"0.020\"],[\"77396.30\",\"0.002\"],[\"77396.20\",\"0.001\"],[\"77396.10\",\"0.018\"],[\"77396.00\",\"0.051\"],[\"77395.90\",\"0.003\"],[\"77395.80\",\"0.700\"],[\"77395.70\",\"0.081\"],[\"77395.60\",\"0.003\"]],\"a\":[[\"77398.00\",\"0.990\"],[\"77398.10\",\"0.153\"],[\"77398.20\",\"0.001\"],[\"77398.30\",\"0.003\"],[\"77398.40\",\"0.003\"],[\"77398.60\",\"0.034\"],[\"77398.80\",\"0.011\"],[\"77399.10\",\"0.002\"],[\"77399.40\",\"0.002\"],[\"77399.60\",\"0.001\"],[\"77400.00\",\"0.146\"],[\"77400.20\",\"0.035\"],[\"77400.30\",\"0.002\"],[\"77400.70\",\"0.003\"],[\"77400.80\",\"0.001\"],[\"77400.90\",\"0.125\"],[\"77401.10\",\"0.020\"],[\"77401.20\",\"0.231\"],[\"77401.40\",\"0.002\"],[\"77401.60\",\"0.001\"]],\"st\":1}"}
{"received_at_ns": 1787949684071762077, "payload": "{\"e\":\"depthUpdate\",\"E\":1787949684004,\"T\":1787949684003,\"s\":\"BTCUSDT\",\"ps\":\"BTCUSDT\",\"U\":11417390017231,\"u\":11417390051531,\"pu\":11417390016961,\"b\":[[\"77397.90\",\"10.392\"],[\"77397.80\",\"0.084\"],[\"77397.70\",\"0.026\"],[\"77397.60\",\"0.006\"],[\"77397.50\",\"0.011\"],[\"77397.30\",\"0.004\"],[\"77397.20\",\"0.149\"],[\"77397.10\",\"0.015\"],[\"77397.00\",\"0.048\"],[\"77396.90\",\"0.002\"],[\"77396.70\",\"0.018\"],[\"77396.60\",\"0.003\"],[\"77396.50\",\"0.020\"],[\"77396.30\",\"0.002\"],[\"77396.20\",\"0.001\"],[\"77396.10\",\"0.018\"],[\"77396.00\",\"0.102\"],[\"77395.90\",\"0.003\"],[\"77395.80\",\"0.700\"],[\"77395.70\",\"0.081\"]],\"a\":[[\"77398.00\",\"0.989\"],[\"77398.10\",\"0.153\"],[\"77398.20\",\"0.001\"],[\"77398.30\",\"0.003\"],[\"77398.40\",\"0.003\"],[\"77398.60\",\"0.034\"],[\"77398.80\",\"0.011\"],[\"77399.10\",\"0.002\"],[\"77399.40\",\"0.002\"],[\"77399.60\",\"0.001\"],[\"77400.00\",\"0.146\"],[\"77400.20\",\"0.035\"],[\"77400.30\",\"0.002\"],[\"77400.70\",\"0.003\"],[\"77400.80\",\"0.001\"],[\"77400.90\",\"0.125\"],[\"77401.10\",\"0.020\"],[\"77401.20\",\"0.231\"],[\"77401.40\",\"0.002\"],[\"77401.60\",\"0.001\"]],\"st\":1}"}
{"received_at_ns": 1787949684576472486, "payload": "{\"e\":\"depthUpdate\",\"E\":1787949684508,\"T\":1787949684506,\"s\":\"BTCUSDT\",\"ps\":\"BTCUSDT\",\"U\":11417390051569,\"u\":11417390082237,\"pu\":11417390051531,\"b\":[[\"77397.90\",\"10.395\"],[\"77397.80\",\"0.084\"],[\"77397.70\",\"0.026\"],[\"77397.60\",\"0.006\"],[\"77397.50\",\"0.011\"],[\"77397.30\",\"0.004\"],[\"77397.20\",\"0.148\"],[\"77397.10\",\"0.015\"],[\"77397.00\",\"0.048\"],[\"77396.90\",\"0.002\"],[\"77396.70\",\"0.018\"],[\"77396.60\",\"0.003\"],[\"77396.50\",\"0.020\"],[\"77396.30\",\"0.002\"],[\"77396.20\",\"0.001\"],[\"77396.10\",\"0.018\"],[\"77396.00\",\"0.051\"],[\"77395.90\",\"0.003\"],[\"77395.80\",\"0.700\"],[\"77395.70\",\"0.078\"]],\"a\":[[\"77398.00\",\"1.254\"],[\"77398.10\",\"0.153\"],[\"77398.20\",\"0.001\"],[\"77398.30\",\"0.003\"],[\"77398.40\",\"0.003\"],[\"77398.60\",\"0.034\"],[\"77398.80\",\"0.011\"],[\"77399.10\",\"0.002\"],[\"77399.40\",\"0.002\"],[\"77399.60\",\"0.001\"],[\"77400.00\",\"0.146\"],[\"77400.20\",\"0.035\"],[\"77400.30\",\"0.002\"],[\"77400.70\",\"0.003\"],[\"77400.80\",\"0.001\"],[\"77400.90\",\"0.125\"],[\"77401.10\",\"0.020\"],[\"77401.20\",\"0.231\"],[\"77401.40\",\"0.002\"],[\"77401.60\",\"0.001\"]],\"st\":1}"}
{"received_at_ns": 1787949685079789555, "payload": "{\"e\":\"depthUpdate\",\"E\":1787949685012,\"T\":1787949685011,\"s\":\"BTCUSDT\",\"ps\":\"BTCUSDT\",\"U\":11417390082352,\"u\":11417390113064,\"pu\":11417390082237,\"b\":[[\"77397.90\",\"10.393\"],[\"77397.80\",\"0.084\"],[\"77397.70\",\"0.026\"],[\"77397.60\",\"0.006\"],[\"77397.50\",\"0.011\"],[\"77397.30\",\"0.004\"],[\"77397.20\",\"0.148\"],[\"77397.10\",\"0.015\"],[\"77397.00\",\"0.048\"],[\"77396.90\",\"0.020\"],[\"77396.70\",\"0.018\"],[\"77396.60\",\"0.003\"],[\"77396.50\",\"0.001\"],[\"77396.30\",\"0.002\"],[\"77396.20\",\"0.001\"],[\"77396.10\",\"0.018\"],[\"77396.00\",\"0.051\"],[\"77395.90\",\"0.003\"],[\"77395.80\",\"0.700\"],[\"77395.70\",\"0.078\"]],\"a\":[[\"77398.00\",\"1.256\"],[\"77398.10\",\"0.153\"],[\"77398.20\",\"0.001\"],[\"77398.30\",\"0.003\"],[\"77398.40\",\"0.003\"],[\"77398.60\",\"0.034\"],[\"77398.80\",\"0.011\"],[\"77399.10\",\"0.002\"],[\"77399.40\",\"0.002\"],[\"77399.60\",\"0.001\"],[\"77400.00\",\"0.146\"],[\"77400.20\",\"0.035\"],[\"77400.30\",\"0.002\"],[\"77400.70\",\"0.003\"],[\"77400.80\",\"0.001\"],[\"77400.90\",\"0.125\"],[\"77401.10\",\"0.020\"],[\"77401.20\",\"0.231\"],[\"77401.40\",\"0.002\"],[\"77401.60\",\"0.001\"]],\"st\":1}"}
{"received_at_ns": 1787949685583830274, "payload": "{\"e\":\"depthUpdate\",\"E\":1787949685516,\"T\":1787949685513,\"s\":\"BTCUSDT\",\"ps\":\"BTCUSDT\",\"U\":11417390113114,\"u\":11417390162171,\"pu\":11417390113064,\"b\":[[\"77398.00\",\"13.846\"],[\"77397.90\",\"7.539\"],[\"77397.80\",\"0.081\"],[\"77397.70\",\"0.019\"],[\"77397.60\",\"0.001\"],[\"77397.50\",\"0.010\"],[\"77397.40\",\"0.006\"],[\"77397.30\",\"0.004\"],[\"77397.10\",\"0.015\"],[\"77397.00\",\"0.048\"],[\"77396.90\",\"0.002\"],[\"77396.60\",\"0.003\"],[\"77396.50\",\"0.020\"],[\"77396.30\",\"0.002\"],[\"77396.20\",\"0.020\"],[\"77396.10\",\"0.018\"],[\"77395.90\",\"0.002\"],[\"77395.70\",\"0.078\"],[\"77395.60\",\"0.003\"],[\"77395.50\",\"0.001\"]],\"a\":[[\"77398.10\",\"0.774\"],[\"77398.30\",\"0.004\"],[\"77398.40\",\"0.003\"],[\"77398.60\",\"0.034\"],[\"77398.80\",\"0.011\"],[\"77399.10\",\"0.002\"],[\"77399.40\",\"0.002\"],[\"77399.60\",\"0.001\"],[\"77400.00\",\"0.144\"],[\"77400.20\",\"0.011\"],[\"77400.30\",\"0.002\"],[\"77400.40\",\"0.002\"],[\"77400.50\",\"0.259\"],[\"77400.70\",\"0.019\"],[\"77400.80\",\"0.033\"],[\"77400.90\",\"0.125\"],[\"77401.10\",\"0.020\"],[\"77401.20\",\"0.231\"],[\"77401.40\",\"0.002\"],[\"77401.60\",\"0.001\"]],\"st\":1}"}
{"received_at_ns": 1787949686087673683, "payload": "{\"e\":\"depthUpdate\",\"E\":1787949686020,\"T\":1787949686019,\"s\":\"BTCUSDT\",\"ps\":\"BTCUSDT\",\"U\":11417390162339,\"u\":11417390196114,\"pu\":11417390162171,\"b\":[[\"77398.00\",\"14.874\"],[\"77397.90\",\"6.680\"],[\"77397.80\",\"0.081\"],[\"77397.70\",\"0.019\"],[\"77397.60\",\"0.001\"],[\"77397.50\",\"0.010\"],[\"77397.40\",\"0.006\"],[\"77397.30\",\"0.004\"],[\"77397.10\",\"0.015\"],[\"77397.00\",\"0.048\"],[\"77396.90\",\"0.002\"],[\"77396.60\",\"0.003\"],[\"77396.50\",\"0.020\"],[\"77396.30\",\"0.002\"],[\"77396.20\",\"0.020\"],[\"77396.10\",\"0.018\"],[\"77395.90\",\"0.002\"],[\"77395.70\",\"0.078\"],[\"77395.60\",\"0.005\"],[\"77395.50\",\"0.001\"]],\"a\":[[\"77398.10\",\"0.484\"],[\"77398.30\",\"0.004\"],[\"77398.40\",\"0.003\"],[\"77398.60\",\"0.034\"],[\"77398.80\",\"0.011\"],[\"77399.10\",\"0.002\"],[\"77399.40\",\"0.002\"],[\"77399.60\",\"0.001\"],[\"77400.00\",\"0.144\"],[\"77400.20\",\"0.011\"],[\"77400.30\",\"0.002\"],[\"77400.40\",\"0.002\"],[\"77400.50\",\"0.259\"],[\"77400.70\",\"0.019\"],[\"77400.80\",\"0.033\"],[\"77400.90\",\"0.125\"],[\"77401.10\",\"0.020\"],[\"77401.20\",\"0.231\"],[\"77401.40\",\"0.002\"],[\"77401.60\",\"0.001\"]],\"st\":1}"}
{"received_at_ns": 1787949686591948952, "payload": "{\"e\":\"depthUpdate\",\"E\":1787949686524,\"T\":1787949686523,\"s\":\"BTCUSDT\",\"ps\":\"BTCUSDT\",\"U\":11417390196152,\"u\":11417390228283,\"pu\":11417390196114,\"b\":[[\"77398.00\",\"14.917\"],[\"77397.90\",\"6.656\"],[\"77397.80\",\"0.081\"],[\"77397.70\",\"0.024\"],[\"77397.60\",\"0.001\"],[\"77397.50\",\"0.010\"],[\"77397.40\",\"0.006\"],[\"77397.30\",\"0.004\"],[\"77397.10\",\"0.015\"],[\"77397.00\",\"0.048\"],[\"77396.90\",\"0.002\"],[\"77396.80\",\"0.076\"],[\"77396.60\",\"0.003\"],[\"77396.50\",\"0.020\"],[\"77396.30\",\"0.002\"],[\"77396.20\",\"0.020\"],[\"77396.10\",\"0.018\"],[\"77395.90\",\"0.002\"],[\"77395.70\",\"0.078\"],[\"77395.60\",\"0.005\"]],\"a\":[[\"77398.10\",\"0.487\"],[\"77398.30\",\"0.004\"],[\"77398.40\",\"0.003\"],[\"77398.60\",\"0.034\"],[\"77398.80\",\"0.011\"],[\"77399.10\",\"0.002\"],[\"77399.40\",\"0.002\"],[\"77399.60\",\"0.001\"],[\"77400.00\",\"0.144\"],[\"77400.20\",\"0.011\"],[\"77400.30\",\"0.002\"],[\"77400.40\",\"0.002\"],[\"77400.70\",\"0.019\"],[\"77400.80\",\"0.033\"],[\"77400.90\",\"0.125\"],[\"77401.10\",\"0.020\"],[\"77401.20\",\"0.231\"],[\"77401.40\",\"0.002\"],[\"77401.50\",\"0.259\"],[\"77401.60\",\"0.001\"]],\"st\":1}"}
{"received_at_ns": 1787949687095676541, "payload": "{\"e\":\"depthUpdate\",\"E\":1787949687028,\"T\":1787949687027,\"s\":\"BTCUSDT\",\"ps\":\"BTCUSDT\",\"U\":11417390228285,\"u\":11417390268596,\"pu\":11417390228283,\"b\":[[\"77398.00\",\"14.414\"],[\"77397.90\",\"6.652\"],[\"77397.80\",\"0.081\"],[\"77397.70\",\"0.024\"],[\"77397.60\",\"0.001\"],[\"77397.50\",\"0.010\"],[\"77397.40\",\"0.006\"],[\"77397.30\",\"0.004\"],[\"77397.10\",\"0.015\"],[\"77397.00\",\"0.048\"],[\"77396.90\",\"0.002\"],[\"77396.80\",\"0.076\"],[\"77396.60\",\"0.003\"],[\"77396.50\",\"0.020\"],[\"77396.30\",\"0.002\"],[\"77396.20\",\"0.020\"],[\"77396.10\",\"0.018\"],[\"77395.90\",\"0.002\"],[\"77395.70\",\"0.078\"],[\"77395.60\",\"0.003\"]],\"a\":[[\"77398.10\",\"0.489\"],[\"77398.30\",\"0.004\"],[\"77398.40\",\"0.003\"],[\"77398.60\",\"0.034\"],[\"77398.80\",\"0.011\"],[\"77399.10\",\"0.002\"],[\"77399.40\",\"0.002\"],[\"77399.60\",\"0.001\"],[\"77400.00\",\"0.144\"],[\"77400.20\",\"0.011\"],[\"77400.30\",\"0.002\"],[\"77400.40\",\"0.002\"],[\"77400.70\",\"0.019\"],[\"77400.80\",\"0.033\"],[\"77400.90\",\"0.125\"],[\"77401.10\",\"0.020\"],[\"77401.40\",\"0.002\"],[\"77401.60\",\"0.001\"],[\"77401.70\",\"0.001\"],[\"77402.00\",\"0.003\"]],\"st\":1}"}
