{"received_at_ns": 1787590744822629728, "payload": "{\"topic\":\"orderbook.50.BTCUSDT\",\"type\":\"snapshot\",\"ts\":1787590744628,\"data\":{\"s\":\"BTCUSDT\",\"b\":[[\"79017.20\",\"5.779\"],[\"79017.10\",\"0.192\"],[\"79017.00\",\"0.842\"],[\"79016.50\",\"0.002\"],[\"79016.40\",\"0.011\"],[\"79016.20\",\"0.004\"],[\"79016.10\",\"0.002\"],[\"79016.00\",\"0.002\"],[\"79015.50\",\"0.002\"],[\"79015.40\",\"0.003\"],[\"79015.30\",\"0.002\"],[\"79015.10\",\"0.261\"],[\"79014.70\",\"0.004\"],[\"79014.60\",\"0.020\"],[\"79014.40\",\"0.001\"],[\"79014.10\",\"0.012\"],[\"79014.00\",\"0.003\"],[\"79013.80\",\"0.131\"],[\"79013.40\",\"0.040\"],[\"79013.30\",\"0.002\"],[\"79013.20\",\"0.086\"],[\"79013.00\",\"0.294\"],[\"79012.60\",\"0.002\"],[\"79012.40\",\"0.001\"],[\"79012.30\",\"0.030\"],[\"79012.20\",\"0.001\"],[\"79012.00\",\"0.002\"],[\"79011.90\",\"0.003\"],[\"79011.80\",\"0.292\"],[\"79011.70\",\"1.668\"],[\"79011.20\",\"0.002\"],[\"79011.00\",\"0.001\"],[\"79010.90\",\"0.032\"],[\"79010.80\",\"0.003\"],[\"79010.60\",\"0.001\"],[\"79010.50\",\"0.002\"],[\"79010.20\",\"0.002\"],[\"79010.10\",\"0.003\"],[\"79010.00\",\"0.002\"],[\"79009.90\",\"1.265\"],[\"79009.80\",\"3.680\"],[\"79009.70\",\"0.003\"],[\"79009.60\",\"0.004\"],[\"79009.10\",\"0.088\"],[\"79009.00\",\"0.382\"],[\"79008.60\",\"0.002\"],[\"79008.40\",\"0.049\"],[\"79008.20\",\"0.004\"],[\"79007.80\",\"0.131\"],[\"79007.70\",\"0.203\"]],\"a\":[[\"79017.30\",\"0.011\"],[\"79017.40\",\"0.002\"],[\"79017.70\",\"0.002\"],[\"79018.70\",\"0.001\"],[\"79019.20\",\"0.001\"],[\"79019.30\",\"0.001\"],[\"79021.50\",\"0.001\"],[\"79022.00\",\"0.002\"],[\"79022.50\",\"0.002\"],[\"79023.00\",\"0.001\"],[\"79023.10\",\"0.004\"],[\"79023.40\",\"0.002\"],[\"79024.10\",\"0.002\"],[\"79024.80\",\"0.002\"],[\"79025.30\",\"0.002\"],[\"79025.50\",\"0.293\"],[\"79025.60\",\"0.831\"],[\"79025.70\",\"0.001\"],[\"79025.80\",\"1.083\"],[\"79026.00\",\"0.001\"],[\"79026.10\",\"0.001\"],[\"79026.70\",\"0.070\"],[\"79026.80\",\"0.002\"],[\"79027.20\",\"0.001\"],[\"79027.40\",\"0.002\"],[\"79027.80\",\"0.592\"],[\"79027.90\",\"0.711\"],[\"79028.20\",\"0.083\"],[\"79028.80\",\"0.003\"],[\"79028.90\",\"1.117\"],[\"79029.50\",\"0.001\"],[\"79029.60\",\"0.961\"],[\"79029.70\",\"0.963\"],[\"79029.80\",\"0.102\"],[\"79030.00\",\"0.063\"],[\"79030.50\",\"0.004\"],[\"79030.60\",\"0.002\"],[\"79030.80\",\"0.002\"],[\"79031.00\",\"0.153\"],[\"79031.20\",\"1.710\"],[\"79031.80\",\"0.001\"],[\"79032.00\",\"0.552\"],[\"79032.20\",\"1.311\"],[\"79032.30\",\"0.550\"],[\"79032.40\",\"0.552\"],[\"79032.70\",\"0.170\"],[\"79032.80\",\"0.553\"],[\"79032.90\",\"0.311\"],[\"79033.00\",\"0.003\"],[\"79033.50\",\"0.001\"]],\"u\":87733754,\"seq\":793104138135},\"cts\":1787590744627}"}
{"received_at_ns": 1787590744822673258, "payload": "{\"topic\":\"orderbook.50.BTCUSDT\",\"type\":\"delta\",\"ts\":1787590744648,\"data\":{\"s\":\"BTCUSDT\",\"b\":[[\"79017.20\",\"5.782\"],[\"79017.00\",\"0.840\"]],\"a\":[[\"79033.40\",\"0.001\"],[\"79033.50\",\"0\"]],\"u\":87733755,\"seq\":793104139001},\"cts\":1787590744646}"}
{"received_at_ns": 1787590744822681178, "payload": "{\"topic\":\"orderbook.50.BTCUSDT\",\"type\":\"delta\",\"ts\":1787590744668,\"data\":{\"s\":\"BTCUSDT\",\"b\":[],\"a\":[[\"79033.30\",\"0.001\"],[\"79033.40\",\"0\"]],\"u\":87733756,\"seq\":793104139762},\"cts\":1787590744667}"}
{"received_at_ns": 1787590744822688218, "payload": "{\"topic\":\"orderbook.50.BTCUSDT\",\"type\":\"delta\",\"ts\":1787590744688,\"data\":{\"s\":\"BTCUSDT\",\"b\":[[\"79017.10\",\"0.193\"]],\"a\":[[\"79017.50\",\"0.001\"],[\"79018.50\",\"0.002\"],[\"79033.00\",\"0\"],[\"79033.30\",\"0\"]],\"u\":87733757,\"seq\":793104140623},\"cts\":1787590744687}"}
{"received_at_ns": 1787590744822694058, "payload": "{\"topic\":\"orderbook.50.BTCUSDT\",\"type\":\"delta\",\"ts\":1787590744708,\"data\":{\"s\":\"BTCUSDT\",\"b\":[[\"79017.10\",\"0.192\"],[\"79010.90\",\"0.034\"],[\"79010.20\",\"0\"],[\"79007.60\",\"0.002\"]],\"a\":[[\"79017.50\",\"0\"],[\"79025.80\",\"1.073\"],[\"79033.00\",\"0.003\"]],\"u\":87733758,\"seq\":793104141446},\"cts\":1787590744706}"}
{"received_at_ns": 1787590744822699408, "payload": "{\"topic\":\"orderbook.50.BTCUSDT\",\"type\":\"delta\",\"ts\":1787590744728,\"data\":{\"s\":\"BTCUSDT\",\"b\":[[\"79017.20\",\"5.775\"],[\"79010.90\",\"0.032\"]],\"a\":[[\"79017.30\",\"0.021\"],[\"79025.50\",\"0.001\"]],\"u\":87733759,\"seq\":793104142354},\"cts\":1787590744726}"}
{"received_at_ns": 1787590744822705268, "payload": "{\"topic\":\"orderbook.50.BTCUSDT\",\"type\":\"delta\",\"ts\":1787590744768,\"data\":{\"s\":\"BTCUSDT\",\"b\":[[\"79017.20\",\"5.774\"],[\"79014.90\",\"0.012\"],[\"79010.00\",\"0.331\"],[\"79007.60\",\"0\"]],\"a\":[[\"79025.50\",\"0\"],[\"79025.60\",\"0\"],[\"79026.70\",\"0\"],[\"79027.90\",\"0.641\"],[\"79029.70\",\"0.783\"],[\"79031.20\",\"1.670\"],[\"79033.00\",\"0.002\"],[\"79033.50\",\"0.001\"],[\"79033.60\",\"0.003\"],[\"79033.90\",\"0.002\"]],\"u\":87733760,\"seq\":793104144009},\"cts\":1787590744767}"}
{"received_at_ns": 1787590744822709848, "payload": "{\"success\":true,\"ret_msg\":\"\",\"conn_id\":\"d9tca0r5ksr6ef8uu02g-3wp0j\",\"req_id\":\"subscribe-1\",\"op\":\"subscribe\"}"}
{"received_at_ns": 1787590744822715228, "payload": "{\"topic\":\"orderbook.50.BTCUSDT\",\"type\":\"delta\",\"ts\":1787590744788,\"data\":{\"s\":\"BTCUSDT\",\"b\":[[\"79017.20\",\"5.779\"],[\"79010.10\",\"0.034\"],[\"79010.00\",\"0.300\"],[\"79009.60\",\"0\"],[\"79007.60\",\"0.002\"]],\"a\":[[\"79031.50\",\"0.002\"],[\"79033.90\",\"0\"]],\"u\":87733761,\"seq\":793104144822},\"cts\":1787590744787}"}
{"received_at_ns": 1787590744841444547, "payload": "{\"topic\":\"orderbook.50.BTCUSDT\",\"type\":\"delta\",\"ts\":1787590744808,\"data\":{\"s\":\"BTCUSDT\",\"b\":[[\"79017.20\",\"5.841\"],[\"79017.10\",\"0.193\"],[\"79017.00\",\"0.812\"],[\"79011.00\",\"0.003\"],[\"79010.10\",\"1.299\"],[\"79009.90\",\"0\"],[\"79007.40\",\"0.002\"]],\"a\":[[\"79017.50\",\"0.001\"],[\"79025.70\",\"0.691\"],[\"79033.60\",\"0\"]],\"u\":87733762,\"seq\":793104145721},\"cts\":1787590744807}"}
{"received_at_ns": 1787590744861579917, "payload": "{\"topic\":\"orderbook.50.BTCUSDT\",\"type\":\"delta\",\"ts\":1787590744828,\"data\":{\"s\":\"BTCUSDT\",\"b\":[[\"79017.20\",\"5.837\"],[\"79017.10\",\"0.192\"],[\"79015.10\",\"0\"],[\"79014.90\",\"0\"],[\"79010.10\",\"1.268\"],[\"79010.00\",\"0.002\"],[\"79007.00\",\"0.001\"],[\"79006.90\",\"0.001\"]],\"a\":[[\"79017.50\",\"0\"],[\"79025.60\",\"0.293\"],[\"79027.70\",\"0.292\"],[\"79033.50\",\"0\"]],\"u\":87733763,\"seq\":793104146524},\"cts\":1787590744827}"}
{"received_at_ns": 1787590744882107726, "payload": "{\"topic\":\"orderbook.50.BTCUSDT\",\"type\":\"delta\",\"ts\":1787590744848,\"data\":{\"s\":\"BTCUSDT\",\"b\":[[\"79017.20\",\"5.802\"],[\"79013.00\",\"0.002\"],[\"79011.00\",\"0.001\"],[\"79010.20\",\"0.002\"],[\"79006.90\",\"0\"]],\"a\":[[\"79023.60\",\"0.292\"],[\"79032.60\",\"0.002\"],[\"79032.90\",\"0\"],[\"79033.00\",\"0\"]],\"u\":87733764,\"seq\":793104147271},\"cts\":1787590744847}"}
{"received_at_ns": 1787590744901502616, "payload": "{\"topic\":\"orderbook.50.BTCUSDT\",\"type\":\"delta\",\"ts\":1787590744868,\"data\":{\"s\":\"BTCUSDT\",\"b\":[[\"79017.20\",\"5.800\"],[\"79013.80\",\"0.051\"]],\"a\":[[\"79032.00\",\"0.554\"]],\"u\":87733765,\"seq\":793104147950},\"cts\":1787590744867}"}
{"received_at_ns": 1787590744921579455, "payload": "{\"topic\":\"orderbook.50.BTCUSDT\",\"type\":\"delta\",\"ts\":1787590744888,\"data\":{\"s\":\"BTCUSDT\",\"b\":[[\"79017.20\",\"5.807\"],[\"79013.00\",\"0.294\"]],\"a\":[[\"79023.60\",\"0\"],[\"79027.70\",\"0\"],[\"79032.90\",\"0.311\"],[\"79033.00\",\"0.002\"]],\"u\":87733766,\"seq\":793104148665},\"cts\":1787590744886}"}
{"received_at_ns": 1787590744941461554, "payload": "{\"topic\":\"orderbook.50.BTCUSDT\",\"type\":\"delta\",\"ts\":1787590744908,\"data\":{\"s\":\"BTCUSDT\",\"b\":[[\"79013.80\",\"0.131\"],[\"79011.90\",\"1.268\"],[\"79010.10\",\"0.003\"]],\"a\":[],\"u\":87733767,\"seq\":793104149425},\"cts\":1787590744907}"}
{"received_at_ns": 1787590744962116774, "payload": "{\"topic\":\"orderbook.50.BTCUSDT\",\"type\":\"delta\",\"ts\":1787590744928,\"data\":{\"s\":\"BTCUSDT\",\"b\":[[\"79017.20\",\"5.736\"],[\"79017.00\",\"0.810\"],[\"79016.50\",\"0\"],[\"79016.00\",\"0\"],[\"79015.00\",\"0.002\"],[\"79014.50\",\"0.002\"],[\"79014.00\",\"0.005\"],[\"79013.00\",\"0.002\"],[\"79012.00\",\"1.267\"],[\"79011.90\",\"0.003\"],[\"79011.80\",\"0\"],[\"79011.50\",\"0.071\"]],\"a\":[[\"79017.30\",\"0.258\"],[\"79022.00\",\"0\"],[\"79023.60\",\"0.292\"],[\"79025.80\",\"0.838\"],[\"79027.70\",\"0.279\"],[\"79028.50\",\"0.002\"],[\"79029.20\",\"0.002\"],[\"79029.90\",\"0.002\"],[\"79032.70\",\"0\"],[\"79032.80\",\"0\"],[\"79032.90\",\"0\"],[\"79033.00\",\"0\"]],\"u\":87733768,\"seq\":793104150148},\"cts\":1787590744927}"}
{"received_at_ns": 1787590744982293123, "payload": "{\"topic\":\"orderbook.50.BTCUSDT\",\"type\":\"delta\",\"ts\":1787590744948,\"data\":{\"s\":\"BTCUSDT\",\"b\":[[\"79017.20\",\"5.737\"],[\"79015.50\",\"0\"],[\"79015.00\",\"0\"],[\"79013.80\",\"0.412\"],[\"79013.60\",\"0.002\"],[\"79013.10\",\"0.002\"],[\"79012.10\",\"1.265\"],[\"79012.00\",\"0.002\"],[\"79007.00\",\"0\"]],\"a\":[[\"79025.60\",\"0.292\"],[\"79027.80\",\"0.594\"],[\"79032.60\",\"0\"],[\"79032.70\",\"0.170\"]],\"u\":87733769,\"seq\":793104150791},\"cts\":1787590744947}"}
{"received_at_ns": 1787590745001927883, "payload": "{\"topic\":\"orderbook.50.BTCUSDT\",\"type\":\"delta\",\"ts\":1787590744968,\"data\":{\"s\":\"BTCUSDT\",\"b\":[[\"79017.10\",\"0.193\"],[\"79012.20\",\"1.266\"],[\"79012.10\",\"0\"],[\"79007.00\",\"0.001\"]],\"a\":[[\"79017.50\",\"0.001\"],[\"79029.20\",\"0.003\"],[\"79032.70\",\"0\"]],\"u\":87733770,\"seq\":793104151418},\"cts\":1787590744966}"}
{"received_at_ns": 1787590745021456162, "payload": "{\"topic\":\"orderbook.50.BTCUSDT\",\"type\":\"delta\",\"ts\":1787590744988,\"data\":{\"s\":\"BTCUSDT\",\"b\":[[\"79017.20\",\"5.740\"],[\"79017.10\",\"0.192\"],[\"79012.30\",\"1.295\"],[\"79012.20\",\"0.001\"]],\"a\":[[\"79017.50\",\"0\"],[\"79029.20\",\"0.004\"],[\"79032.70\",\"0.170\"]],\"u\":87733771,\"seq\":793104152087},\"cts\":1787590744986}"}
{"received_at_ns": 1787590745042157391, "payload": "{\"topic\":\"orderbook.50.BTCUSDT\",\"type\":\"delta\",\"ts\":1787590745008,\"data\":{\"s\":\"BTCUSDT\",\"b\":[[\"79017.20\",\"5.739\"],[\"79017.10\",\"0.193\"],[\"79012.40\",\"1.266\"],[\"79012.30\",\"0.030\"]],\"a\":[[\"79017.50\",\"0.001\"],[\"79030.60\",\"0.003\"],[\"79032.70\",\"0\"]],\"u\":87733772,\"seq\":793104152784},\"cts\":1787590745007}"}
{"received_at_ns": 1787590745061520301, "payload": "{\"topic\":\"orderbook.50.BTCUSDT\",\"type\":\"delta\",\"ts\":1787590745028,\"data\":{\"s\":\"BTCUSDT\",\"b\":[[\"79017.10\",\"0.192\"],[\"79014.70\",\"0.023\"],[\"79012.50\",\"1.265\"],[\"79012.40\",\"0.001\"],[\"79007.00\",\"0\"]],\"a\":[[\"79017.50\",\"0\"],[\"79027.80\",\"0.592\"],[\"79032.70\",\"0.170\"]],\"u\":87733773,\"seq\":793104153353},\"cts\":1787590745027}"}
{"received_at_ns": 1787590745081621830, "payload": "{\"topic\":\"orderbook.50.BTCUSDT\",\"type\":\"delta\",\"ts\":1787590745048,\"data\":{\"s\":\"BTCUSDT\",\"b\":[[\"79017.20\",\"5.812\"],[\"79015.90\",\"0.002\"],[\"79012.50\",\"0\"],[\"79011.50\",\"0\"],[\"79009.90\",\"1.265\"]],\"a\":[[\"79028.50\",\"0\"],[\"79030.40\",\"0.002\"]],\"u\":87733774,\"seq\":793104153987},\"cts\":1787590745047}"}
{"received_at_ns": 1787590745101913640, "payload": "{\"topic\":\"orderbook.50.BTCUSDT\",\"type\":\"delta\",\"ts\":1787590745068,\"data\":{\"s\":\"BTCUSDT\",\"b\":[[\"79017.20\",\"5.808\"],[\"79017.00\",\"0.809\"],[\"79015.90\",\"0\"],[\"79013.80\",\"0.052\"],[\"79007.00\",\"0.001\"]],\"a\":[[\"79017.30\",\"0.341\"],[\"79019.00\",\"0.001\"],[\"79019.80\",\"0.001\"],[\"79027.50\",\"0.002\"],[\"79028.10\",\"0.002\"],[\"79028.20\",\"0\"],[\"79029.20\",\"0.003\"],[\"79032.30\",\"0\"],[\"79032.40\",\"0\"],[\"79032.70\",\"0\"]],\"u\":87733775,\"seq\":793104154639},\"cts\":1787590745067}"}
{"received_at_ns": 1787590745121597939, "payload": "{\"topic\":\"orderbook.50.BTCUSDT\",\"type\":\"delta\",\"ts\":1787590745088,\"data\":{\"s\":\"BTCUSDT\",\"b\":[[\"79017.20\",\"5.810\"],[\"79015.10\",\"0.294\"],[\"79013.00\",\"0.294\"],[\"79011.80\",\"0.292\"],[\"79010.00\",\"0.294\"],[\"79007.40\",\"0\"],[\"79007.00\",\"0\"]],\"a\":[[\"79023.60\",\"0\"],[\"79025.60\",\"0\"],[\"79027.70\",\"0\"],[\"79028.10\",\"0\"],[\"79032.30\",\"0.550\"],[\"79032.40\",\"0.552\"],[\"79032.70\",\"0.170\"],[\"79032.80\",\"0.553\"]],\"u\":87733776,\"seq\":793104155290},\"cts\":1787590745087}"}
{"received_at_ns": 1787590745143818978, "payload": "{\"topic\":\"orderbook.50.BTCUSDT\",\"type\":\"delta\",\"ts\":1787590745109,\"data\":{\"s\":\"BTCUSDT\",\"b\":[[\"79017.20\",\"5.803\"],[\"79016.90\",\"0.002\"],[\"79013.80\",\"0.132\"],[\"79013.10\",\"0\"],[\"79010.10\",\"1.268\"],[\"79010.00\",\"0.002\"],[\"79009.90\",\"0\"],[\"79007.40\",\"0.002\"]],\"a\":[[\"79017.40\",\"0.003\"],[\"79017.50\",\"0.001\"],[\"79019.00\",\"0.002\"],[\"79019.80\",\"0.002\"],[\"79020.40\",\"0.001\"],[\"79021.10\",\"0.001\"],[\"79025.60\",\"0.001\"],[\"79029.20\",\"0\"],[\"79029.90\",\"0\"],[\"79030.80\",\"0.004\"],[\"79031.30\",\"0.002\"],[\"79032.40\",\"0\"],[\"79032.70\",\"0\"],[\"79032.80\",\"0\"]],\"u\":87733777,\"seq\":793104155966},\"cts\":1787590745107}"}
{"received_at_ns": 1787590745162219127, "payload": "{\"topic\":\"orderbook.50.BTCUSDT\",\"type\":\"delta\",\"ts\":1787590745128,\"data\":{\"s\":\"BTCUSDT\",\"b\":[[\"79015.10\",\"0.002\"],[\"79013.00\",\"0.002\"],[\"79011.90\",\"1.268\"],[\"79011.80\",\"0\"],[\"79010.10\",\"0.003\"],[\"79007.00\",\"0.001\"]],\"a\":[[\"79017.30\",\"0.518\"],[\"79017.40\",\"0.002\"],[\"79017.50\",\"0\"],[\"79025.60\",\"0.292\"],[\"79025.80\",\"0.663\"],[\"79027.70\",\"0.292\"]],\"u\":87733778,\"seq\":793104156631},\"cts\":1787590745127}"}
{"received_at_ns": 1787590745181436087, "payload": "{\"topic\":\"orderbook.50.BTCUSDT\",\"type\":\"delta\",\"ts\":1787590745148,\"data\":{\"s\":\"BTCUSDT\",\"b\":[[\"79017.20\",\"5.800\"],[\"79016.90\",\"0\"],[\"79013.80\",\"0.052\"],[\"79012.00\",\"1.267\"],[\"79011.90\",\"0.003\"],[\"79010.10\",\"0.002\"],[\"79009.10\",\"0.089\"],[\"79006.90\",\"0.001\"]],\"a\":[[\"79020.40\",\"0.002\"],[\"79021.10\",\"0.002\"],[\"79023.60\",\"0.292\"],[\"79029.20\",\"0.002\"],[\"79032.20\",\"0\"],[\"79032.30\",\"0\"]],\"u\":87733779,\"seq\":793104157219},\"cts\":1787590745146}"}
{"received_at_ns": 1787590745202163897, "payload": "{\"topic\":\"orderbook.50.BTCUSDT\",\"type\":\"delta\",\"ts\":1787590745168,\"data\":{\"s\":\"BTCUSDT\",\"b\":[[\"79017.20\",\"5.711\"],[\"79016.80\",\"0.002\"],[\"79015.10\",\"0\"],[\"79013.80\",\"0.422\"],[\"79013.10\",\"0.002\"],[\"79012.10\",\"1.265\"],[\"79012.00\",\"0.002\"],[\"79007.00\",\"0\"],[\"79006.90\",\"0\"]],\"a\":[[\"79017.30\",\"0.435\"],[\"79021.80\",\"0.001\"],[\"79027.50\",\"0\"],[\"79029.20\",\"0\"],[\"79031.80\",\"0.003\"],[\"79032.00\",\"0.552\"],[\"79032.20\",\"1.311\"]],\"u\":87733780,\"seq\":793104157881},\"cts\":1787590745167}"}
{"received_at_ns": 1787590745221953686, "payload": "{\"topic\":\"orderbook.50.BTCUSDT\",\"type\":\"delta\",\"ts\":1787590745188,\"data\":{\"s\":\"BTCUSDT\",\"b\":[[\"79012.20\",\"1.266\"],[\"79012.10\",\"0\"],[\"79007.00\",\"0.001\"]],\"a\":[],\"u\":87733781,\"seq\":793104158449},\"cts\":1787590745187}"}
{"received_at_ns": 1787590745242349815, "payload": "{\"topic\":\"orderbook.50.BTCUSDT\",\"type\":\"delta\",\"ts\":1787590745208,\"data\":{\"s\":\"BTCUSDT\",\"b\":[[\"79012.30\",\"1.295\"],[\"79012.20\",\"0.001\"]],\"a\":[],\"u\":87733782,\"seq\":793104158990},\"cts\":1787590745207}"}
{"received_at_ns": 1787590745262342684, "payload": "{\"topic\":\"orderbook.50.BTCUSDT\",\"type\":\"delta\",\"ts\":1787590745228,\"data\":{\"s\":\"BTCUSDT\",\"b\":[[\"79012.40\",\"1.266\"],[\"79012.30\",\"0.030\"],[\"79010.20\",\"0\"],[\"79009.90\",\"0.002\"]],\"a\":[[\"79017.40\",\"0.003\"],[\"79017.50\",\"0.001\"],[\"79021.80\",\"0.002\"],[\"79032.20\",\"0\"]],\"u\":87733783,\"seq\":793104159574},\"cts\":1787590745228}"}
{"received_at_ns": 1787590745282655714, "payload": "{\"topic\":\"orderbook.50.BTCUSDT\",\"type\":\"delta\",\"ts\":1787590745248,\"data\":{\"s\":\"BTCUSDT\",\"b\":[[\"79012.40\",\"0.001\"],[\"79009.90\",\"1.267\"]],\"a\":[[\"79017.40\",\"0.002\"],[\"79017.50\",\"0\"],[\"79032.20\",\"1.311\"]],\"u\":87733784,\"seq\":793104160136},\"cts\":1787590745246}"}
{"received_at_ns": 1787590745302135843, "payload": "{\"topic\":\"orderbook.50.BTCUSDT\",\"type\":\"delta\",\"ts\":1787590745268,\"data\":{\"s\":\"BTCUSDT\",\"b\":[[\"79016.80\",\"0\"],[\"79016.70\",\"0.002\"],[\"79016.20\",\"0.006\"],[\"79013.80\",\"0.052\"],[\"79013.10\",\"0\"],[\"79011.80\",\"0.292\"]],\"a\":[[\"79019.30\",\"0.003\"],[\"79023.50\",\"0.087\"],[\"79027.70\",\"0\"],[\"79029.80\",\"0.104\"]],\"u\":87733785,\"seq\":793104160778},\"cts\":1787590745267}"}
{"received_at_ns": 1787590745321718833, "payload": "{\"topic\":\"orderbook.50.BTCUSDT\",\"type\":\"delta\",\"ts\":1787590745288,\"data\":{\"s\":\"BTCUSDT\",\"b\":[[\"79017.10\",\"0.193\"]],\"a\":[[\"79017.50\",\"0.001\"],[\"79032.20\",\"0\"]],\"u\":87733786,\"seq\":793104161391},\"cts\":1787590745287}"}
{"received_at_ns": 1787590745341523902, "payload": "{\"topic\":\"orderbook.50.BTCUSDT\",\"type\":\"delta\",\"ts\":1787590745308,\"data\":{\"s\":\"BTCUSDT\",\"b\":[[\"79017.20\",\"5.714\"],[\"79013.60\",\"0\"],[\"79006.90\",\"0.001\"]],\"a\":[[\"79029.80\",\"0.102\"]],\"u\":87733787,\"seq\":793104161982},\"cts\":1787590745307}"}
{"received_at_ns": 1787590745363751061, "payload": "{\"topic\":\"orderbook.50.BTCUSDT\",\"type\":\"delta\",\"ts\":1787590745329,\"data\":{\"s\":\"BTCUSDT\",\"b\":[[\"79017.20\",\"5.718\"],[\"79017.10\",\"0.192\"],[\"79015.30\",\"0.022\"],[\"79014.70\",\"0.004\"]],\"a\":[[\"79017.50\",\"0\"],[\"79023.50\",\"0\"],[\"79032.20\",\"1.311\"],[\"79032.30\",\"0.550\"]],\"u\":87733788,\"seq\":793104162537},\"cts\":1787590745327}"}
{"received_at_ns": 1787590745381993571, "payload": "{\"topic\":\"orderbook.50.BTCUSDT\",\"type\":\"delta\",\"ts\":1787590745348,\"data\":{\"s\":\"BTCUSDT\",\"b\":[[\"79017.20\",\"5.721\"],[\"79010.00\",\"0.004\"],[\"79009.90\",\"1.265\"]],\"a\":[],\"u\":87733789,\"seq\":793104163111},\"cts\":1787590745347}"}
{"received_at_ns": 1787590745403772060, "payload": "{\"topic\":\"orderbook.50.BTCUSDT\",\"type\":\"delta\",\"ts\":1787590745368,\"data\":{\"s\":\"BTCUSDT\",\"b\":[[\"79013.00\",\"0.294\"]],\"a\":[[\"79023.60\",\"0\"],[\"79030.40\",\"0\"],[\"79032.30\",\"0.552\"],[\"79032.40\",\"0.552\"],[\"79032.70\",\"0.170\"]],\"u\":87733790,\"seq\":793104163624},\"cts\":1787590745367}"}
{"received_at_ns": 1787590745421745640, "payload": "{\"topic\":\"orderbook.50.BTCUSDT\",\"type\":\"delta\",\"ts\":1787590745388,\"data\":{\"s\":\"BTCUSDT\",\"b\":[[\"79017.20\",\"5.727\"],[\"79015.10\",\"0.292\"],[\"79013.80\",\"0.131\"],[\"79010.00\",\"0.333\"],[\"79006.90\",\"0\"]],\"a\":[[\"79025.60\",\"0\"],[\"79030.80\",\"0.002\"],[\"79031.30\",\"0\"],[\"79031.80\",\"0.001\"],[\"79032.30\",\"0.550\"],[\"79032.80\",\"0.553\"],[\"79032.90\",\"0.311\"]],\"u\":87733791,\"seq\":793104164311},\"cts\":1787590745387}"}
{"received_at_ns": 1787590745441611039, "payload": "{\"topic\":\"orderbook.50.BTCUSDT\",\"type\":\"delta\",\"ts\":1787590745408,\"data\":{\"s\":\"BTCUSDT\",\"b\":[[\"79017.20\",\"5.731\"],[\"79010.10\",\"1.298\"],[\"79010.00\",\"0.300\"],[\"79009.90\",\"0\"],[\"79006.90\",\"0.001\"]],\"a\":[[\"79025.60\",\"0.001\"],[\"79032.90\",\"0\"]],\"u\":87733792,\"seq\":793104165040},\"cts\":1787590745407}"}
