{"received_at_ns": 1787373724828448119, "payload": "{\"topic\":\"orderbook.50.BTCUSDT\",\"type\":\"snapshot\",\"ts\":1787373724629,\"data\":{\"s\":\"BTCUSDT\",\"b\":[[\"78758.20\",\"2.841\"],[\"78758.10\",\"0.003\"],[\"78758.00\",\"0.024\"],[\"78757.00\",\"0.002\"],[\"78756.80\",\"0.002\"],[\"78756.60\",\"0.002\"],[\"78756.50\",\"0.001\"],[\"78756.30\",\"0.002\"],[\"78756.10\",\"0.171\"],[\"78756.00\",\"0.002\"],[\"78755.70\",\"0.002\"],[\"78755.60\",\"0.002\"],[\"78755.30\",\"0.002\"],[\"78755.20\",\"0.002\"],[\"78755.10\",\"0.128\"],[\"78755.00\",\"0.411\"],[\"78754.90\",\"0.002\"],[\"78754.70\",\"0.009\"],[\"78754.30\",\"0.003\"],[\"78754.00\",\"0.001\"],[\"78753.90\",\"0.001\"],[\"78753.70\",\"0.002\"],[\"78753.30\",\"0.008\"],[\"78753.20\",\"0.002\"],[\"78753.00\",\"0.001\"],[\"78752.70\",\"0.001\"],[\"78752.60\",\"0.003\"],[\"78751.90\",\"0.002\"],[\"78751.80\",\"0.416\"],[\"78751.70\",\"0.407\"],[\"78751.60\",\"0.423\"],[\"78751.20\",\"0.005\"],[\"78750.50\",\"0.002\"],[\"78750.30\",\"0.190\"],[\"78750.20\",\"0.101\"],[\"78750.00\",\"0.042\"],[\"78749.90\",\"0.003\"],[\"78749.50\",\"0.001\"],[\"78749.30\",\"0.006\"],[\"78749.20\",\"0.001\"],[\"78749.00\",\"0.001\"],[\"78748.90\",\"0.767\"],[\"78748.80\",\"0.139\"],[\"78748.70\",\"0.002\"],[\"78748.60\",\"0.002\"],[\"78748.40\",\"0.002\"],[\"78748.30\",\"0.374\"],[\"78748.20\",\"0.003\"],[\"78747.90\",\"0.001\"],[\"78747.50\",\"0.002\"]],\"a\":[[\"78758.30\",\"0.512\"],[\"78758.40\",\"0.001\"],[\"78759.80\",\"0.002\"],[\"78760.00\",\"0.004\"],[\"78760.60\",\"0.003\"],[\"78760.70\",\"0.004\"],[\"78761.40\",\"0.002\"],[\"78761.50\",\"0.002\"],[\"78761.60\",\"0.001\"],[\"78762.10\",\"0.004\"],[\"78762.70\",\"0.033\"],[\"78762.80\",\"0.097\"],[\"78762.90\",\"0.002\"],[\"78763.10\",\"0.002\"],[\"78763.30\",\"0.001\"],[\"78763.80\",\"0.002\"],[\"78764.00\",\"0.001\"],[\"78764.10\",\"0.007\"],[\"78764.50\",\"0.002\"],[\"78764.60\",\"0.436\"],[\"78764.70\",\"0.410\"],[\"78764.90\",\"0.001\"],[\"78765.00\",\"0.057\"],[\"78765.10\",\"0.002\"],[\"78765.20\",\"0.001\"],[\"78765.30\",\"0.008\"],[\"78765.60\",\"0.003\"],[\"78766.30\",\"0.002\"],[\"78766.40\",\"0.001\"],[\"78766.50\",\"0.001\"],[\"78766.70\",\"0.075\"],[\"78766.90\",\"0.002\"],[\"78767.00\",\"0.001\"],[\"78767.40\",\"0.002\"],[\"78767.50\",\"0.001\"],[\"78767.70\",\"0.001\"],[\"78767.90\",\"0.411\"],[\"78768.00\",\"0.002\"],[\"78768.30\",\"0.450\"],[\"78768.40\",\"0.008\"],[\"78768.60\",\"0.002\"],[\"78768.80\",\"0.002\"],[\"78768.90\",\"0.380\"],[\"78769.00\",\"0.551\"],[\"78769.30\",\"0.008\"],[\"78769.40\",\"0.002\"],[\"78769.70\",\"0.001\"],[\"78769.80\",\"0.001\"],[\"78769.90\",\"0.002\"],[\"78770.00\",\"1.037\"]],\"u\":79825653,\"seq\":786376053837},\"cts\":1787373724627}"}
{"received_at_ns": 1787373724828471859, "payload": "{\"topic\":\"orderbook.50.BTCUSDT\",\"type\":\"delta\",\"ts\":1787373724688,\"data\":{\"s\":\"BTCUSDT\",\"b\":[],\"a\":[[\"78767.10\",\"0.203\"],[\"78770.00\",\"0\"]],\"u\":79825654,\"seq\":786376055511},\"cts\":1787373724686}"}
{"received_at_ns": 1787373724828478699, "payload": "{\"topic\":\"orderbook.50.BTCUSDT\",\"type\":\"delta\",\"ts\":1787373724728,\"data\":{\"s\":\"BTCUSDT\",\"b\":[[\"78754.20\",\"0.101\"],[\"78747.50\",\"0\"]],\"a\":[[\"78758.30\",\"0.306\"],[\"78762.70\",\"0\"],[\"78764.70\",\"0\"],[\"78766.70\",\"0\"],[\"78770.00\",\"1.037\"],[\"78770.20\",\"0.001\"],[\"78770.80\",\"0.009\"]],\"u\":79825655,\"seq\":786376056737},\"cts\":1787373724727}"}
{"received_at_ns": 1787373724828485809, "payload": "{\"topic\":\"orderbook.50.BTCUSDT\",\"type\":\"delta\",\"ts\":1787373724748,\"data\":{\"s\":\"BTCUSDT\",\"b\":[[\"78756.20\",\"0.216\"],[\"78755.10\",\"0\"]],\"a\":[[\"78766.50\",\"0\"],[\"78766.70\",\"0.001\"],[\"78769.00\",\"0.450\"],[\"78770.30\",\"0.101\"],[\"78770.80\",\"0\"]],\"u\":79825656,\"seq\":786376057397},\"cts\":1787373724747}"}
{"received_at_ns": 1787373724828490749, "payload": "{\"topic\":\"orderbook.50.BTCUSDT\",\"type\":\"delta\",\"ts\":1787373724788,\"data\":{\"s\":\"BTCUSDT\",\"b\":[[\"78754.20\",\"0\"],[\"78747.50\",\"0.002\"]],\"a\":[[\"78758.30\",\"0.383\"]],\"u\":79825657,\"seq\":786376058613},\"cts\":1787373724787}"}
{"received_at_ns": 1787373724828495619, "payload": "{\"success\":true,\"ret_msg\":\"\",\"conn_id\":\"d9tc8gq4p82ckm4tnamg-349n4\",\"req_id\":\"subscribe-1\",\"op\":\"subscribe\"}"}
{"received_at_ns": 1787373724901199860, "payload": "{\"topic\":\"orderbook.50.BTCUSDT\",\"type\":\"delta\",\"ts\":1787373724868,\"data\":{\"s\":\"BTCUSDT\",\"b\":[[\"78758.20\",\"2.976\"],[\"78754.20\",\"0.101\"],[\"78747.50\",\"0\"]],\"a\":[[\"78758.30\",\"0.036\"],[\"78760.00\",\"0.002\"],[\"78760.70\",\"0\"],[\"78766.70\",\"0\"],[\"78767.00\",\"0.002\"],[\"78770.80\",\"0.009\"],[\"78770.90\",\"0.031\"]],\"u\":79825658,\"seq\":786376060998},\"cts\":1787373724867}"}
{"received_at_ns": 1787373724921261739, "payload": "{\"topic\":\"orderbook.50.BTCUSDT\",\"type\":\"delta\",\"ts\":1787373724888,\"data\":{\"s\":\"BTCUSDT\",\"b\":[],\"a\":[[\"78758.30\",\"0.115\"],[\"78767.00\",\"0.001\"],[\"78767.90\",\"0.412\"]],\"u\":79825659,\"seq\":786376062337},\"cts\":1787373724887}"}
{"received_at_ns": 1787373724941213599, "payload": "{\"topic\":\"orderbook.50.BTCUSDT\",\"type\":\"delta\",\"ts\":1787373724908,\"data\":{\"s\":\"BTCUSDT\",\"b\":[],\"a\":[[\"78765.00\",\"0.120\"]],\"u\":79825660,\"seq\":786376063526},\"cts\":1787373724907}"}
{"received_at_ns": 1787373724961258469, "payload": "{\"topic\":\"orderbook.50.BTCUSDT\",\"type\":\"delta\",\"ts\":1787373724928,\"data\":{\"s\":\"BTCUSDT\",\"b\":[[\"78758.20\",\"2.958\"]],\"a\":[[\"78769.20\",\"0.025\"],[\"78770.90\",\"0\"]],\"u\":79825661,\"seq\":786376064615},\"cts\":1787373724926}"}
{"received_at_ns": 1787373725001189538, "payload": "{\"topic\":\"orderbook.50.BTCUSDT\",\"type\":\"delta\",\"ts\":1787373724968,\"data\":{\"s\":\"BTCUSDT\",\"b\":[[\"78758.20\",\"2.866\"]],\"a\":[[\"78758.30\",\"0.099\"],[\"78761.50\",\"0\"],[\"78765.00\",\"0.063\"],[\"78767.10\",\"0\"],[\"78770.90\",\"0.031\"],[\"78771.00\",\"0.063\"]],\"u\":79825662,\"seq\":786376066994},\"cts\":1787373724966}"}
{"received_at_ns": 1787373725021044059, "payload": "{\"topic\":\"orderbook.50.BTCUSDT\",\"type\":\"delta\",\"ts\":1787373724988,\"data\":{\"s\":\"BTCUSDT\",\"b\":[[\"78758.20\",\"2.867\"],[\"78752.30\",\"0.002\"],[\"78748.60\",\"0\"]],\"a\":[[\"78764.60\",\"0\"],[\"78767.80\",\"0.258\"],[\"78768.30\",\"0.180\"],[\"78768.80\",\"0.382\"],[\"78768.90\",\"0\"],[\"78771.10\",\"0.410\"]],\"u\":79825663,\"seq\":786376068503},\"cts\":1787373724987}"}
{"received_at_ns": 1787373725040984599, "payload": "{\"topic\":\"orderbook.50.BTCUSDT\",\"type\":\"delta\",\"ts\":1787373725008,\"data\":{\"s\":\"BTCUSDT\",\"b\":[[\"78758.20\",\"2.866\"]],\"a\":[[\"78767.70\",\"0.007\"],[\"78767.80\",\"0.177\"],[\"78769.00\",\"0.631\"]],\"u\":79825664,\"seq\":786376069819},\"cts\":1787373725007}"}
{"received_at_ns": 1787373725061002529, "payload": "{\"topic\":\"orderbook.50.BTCUSDT\",\"type\":\"delta\",\"ts\":1787373725028,\"data\":{\"s\":\"BTCUSDT\",\"b\":[[\"78758.20\",\"2.867\"]],\"a\":[[\"78762.10\",\"0.002\"],[\"78762.80\",\"0.095\"]],\"u\":79825665,\"seq\":786376071142},\"cts\":1787373725026}"}
{"received_at_ns": 1787373725081077488, "payload": "{\"topic\":\"orderbook.50.BTCUSDT\",\"type\":\"delta\",\"ts\":1787373725048,\"data\":{\"s\":\"BTCUSDT\",\"b\":[[\"78758.20\",\"2.866\"]],\"a\":[],\"u\":79825666,\"seq\":786376072480},\"cts\":1787373725047}"}
{"received_at_ns": 1787373725121210638, "payload": "{\"topic\":\"orderbook.50.BTCUSDT\",\"type\":\"delta\",\"ts\":1787373725088,\"data\":{\"s\":\"BTCUSDT\",\"b\":[[\"78758.20\",\"2.874\"]],\"a\":[[\"78758.30\",\"0.036\"],[\"78763.10\",\"0.001\"],[\"78765.00\",\"0\"],[\"78771.00\",\"0.002\"],[\"78771.30\",\"0.003\"]],\"u\":79825667,\"seq\":786376075035},\"cts\":1787373725087}"}
{"received_at_ns": 1787373725181454548, "payload": "{\"topic\":\"orderbook.50.BTCUSDT\",\"type\":\"delta\",\"ts\":1787373725148,\"data\":{\"s\":\"BTCUSDT\",\"b\":[],\"a\":[[\"78758.30\",\"0.038\"],[\"78763.10\",\"0\"],[\"78769.90\",\"0.001\"],[\"78771.30\",\"0.002\"],[\"78771.40\",\"0.464\"]],\"u\":79825668,\"seq\":786376078788},\"cts\":1787373725147}"}
{"received_at_ns": 1787373725201085908, "payload": "{\"topic\":\"orderbook.50.BTCUSDT\",\"type\":\"delta\",\"ts\":1787373725168,\"data\":{\"s\":\"BTCUSDT\",\"b\":[],\"a\":[[\"78759.00\",\"0.002\"],[\"78762.90\",\"0.003\"],[\"78771.40\",\"0\"]],\"u\":79825669,\"seq\":786376080111},\"cts\":1787373725167}"}
{"received_at_ns": 1787373725220977468, "payload": "{\"topic\":\"orderbook.50.BTCUSDT\",\"type\":\"delta\",\"ts\":1787373725188,\"data\":{\"s\":\"BTCUSDT\",\"b\":[[\"78758.20\",\"2.871\"]],\"a\":[[\"78758.30\",\"0.117\"],[\"78768.30\",\"0.316\"],[\"78769.60\",\"0.002\"],[\"78770.40\",\"0.002\"],[\"78771.10\",\"0\"],[\"78771.30\",\"0\"]],\"u\":79825670,\"seq\":786376081452},\"cts\":1787373725187}"}
{"received_at_ns": 1787373725241346517, "payload": "{\"topic\":\"orderbook.50.BTCUSDT\",\"type\":\"delta\",\"ts\":1787373725208,\"data\":{\"s\":\"BTCUSDT\",\"b\":[[\"78758.20\",\"2.842\"],[\"78758.00\",\"0.025\"],[\"78756.60\",\"0\"],[\"78755.70\",\"0\"],[\"78755.30\",\"0\"],[\"78754.70\",\"0.007\"],[\"78754.20\",\"0\"],[\"78753.80\",\"0.002\"],[\"78753.30\",\"0.010\"],[\"78752.80\",\"0.002\"],[\"78752.30\",\"0.004\"],[\"78747.50\",\"0.002\"],[\"78747.40\",\"0.001\"]],\"a\":[[\"78758.30\",\"0.359\"],[\"78764.60\",\"0.350\"],[\"78764.70\",\"0.409\"],[\"78766.60\",\"0.002\"],[\"78767.60\",\"0.002\"],[\"78767.70\",\"0.001\"],[\"78767.80\",\"0\"],[\"78768.10\",\"0.002\"],[\"78769.10\",\"0.002\"],[\"78770.30\",\"0\"],[\"78770.40\",\"0\"],[\"78770.80\",\"0\"],[\"78770.90\",\"0\"],[\"78771.00\",\"0\"]],\"u\":79825671,\"seq\":786376082578},\"cts\":1787373725207}"}
{"received_at_ns": 1787373725261517627, "payload": "{\"topic\":\"orderbook.50.BTCUSDT\",\"type\":\"delta\",\"ts\":1787373725228,\"data\":{\"s\":\"BTCUSDT\",\"b\":[[\"78758.20\",\"2.802\"],[\"78753.80\",\"0\"],[\"78753.30\",\"0.008\"],[\"78752.80\",\"0\"],[\"78752.30\",\"0.002\"],[\"78751.70\",\"0.409\"],[\"78749.00\",\"0.768\"],[\"78748.90\",\"0\"],[\"78748.80\",\"0.141\"],[\"78748.30\",\"0.376\"],[\"78747.80\",\"0.002\"],[\"78747.40\",\"0.003\"],[\"78747.30\",\"0.020\"],[\"78747.00\",\"0.001\"]],\"a\":[[\"78758.30\",\"0.646\"],[\"78764.80\",\"0.002\"],[\"78765.60\",\"0.005\"],[\"78767.00\",\"0.003\"],[\"78767.10\",\"0.203\"],[\"78767.60\",\"0\"],[\"78768.10\",\"0\"],[\"78768.30\",\"0.450\"],[\"78769.10\",\"0\"],[\"78769.60\",\"0\"],[\"78770.30\",\"0.101\"],[\"78770.80\",\"0.009\"]],\"u\":79825672,\"seq\":786376083168},\"cts\":1787373725227}"}
{"received_at_ns": 1787373725281224227, "payload": "{\"topic\":\"orderbook.50.BTCUSDT\",\"type\":\"delta\",\"ts\":1787373725248,\"data\":{\"s\":\"BTCUSDT\",\"b\":[[\"78751.90\",\"0.004\"],[\"78751.70\",\"0.407\"],[\"78751.10\",\"0.002\"],[\"78747.40\",\"0.001\"],[\"78747.00\",\"0\"]],\"a\":[[\"78764.80\",\"0\"],[\"78765.20\",\"0.010\"],[\"78765.30\",\"0\"],[\"78766.30\",\"0.103\"],[\"78770.90\",\"0.031\"],[\"78771.00\",\"0.002\"]],\"u\":79825673,\"seq\":786376083696},\"cts\":1787373725247}"}
{"received_at_ns": 1787373725301096829, "payload": "{\"topic\":\"orderbook.50.BTCUSDT\",\"type\":\"delta\",\"ts\":1787373725268,\"data\":{\"s\":\"BTCUSDT\",\"b\":[[\"78758.20\",\"1.962\"],[\"78755.10\",\"0.409\"],[\"78755.00\",\"0.001\"],[\"78751.90\",\"0.411\"],[\"78751.80\",\"0.006\"],[\"78751.60\",\"0.001\"],[\"78751.10\",\"0\"],[\"78749.10\",\"0.767\"],[\"78749.00\",\"0.001\"],[\"78748.80\",\"0.139\"],[\"78748.60\",\"0.409\"],[\"78748.30\",\"0.001\"],[\"78747.80\",\"0\"],[\"78747.30\",\"0\"]],\"a\":[[\"78758.30\",\"2.106\"],[\"78758.90\",\"0.002\"],[\"78759.80\",\"0.004\"],[\"78760.00\",\"0.004\"],[\"78760.80\",\"0.004\"],[\"78762.00\",\"0.002\"],[\"78762.70\",\"0.033\"],[\"78764.00\",\"0.003\"],[\"78765.60\",\"0.003\"],[\"78766.60\",\"0\"],[\"78767.00\",\"0.001\"],[\"78770.80\",\"0\"],[\"78770.90\",\"0\"],[\"78771.00\",\"0\"]],\"u\":79825674,\"seq\":786376084307},\"cts\":1787373725267}"}
{"received_at_ns": 1787373725321379208, "payload": "{\"topic\":\"orderbook.50.BTCUSDT\",\"type\":\"delta\",\"ts\":1787373725288,\"data\":{\"s\":\"BTCUSDT\",\"b\":[[\"78758.20\",\"1.948\"],[\"78756.10\",\"0\"],[\"78753.00\",\"0\"],[\"78752.70\",\"0.172\"],[\"78751.70\",\"0.408\"],[\"78751.00\",\"0.014\"],[\"78747.30\",\"0.020\"]],\"a\":[[\"78758.30\",\"1.765\"],[\"78758.90\",\"0\"],[\"78759.80\",\"0.002\"],[\"78760.80\",\"0.002\"],[\"78761.50\",\"0.394\"],[\"78764.00\",\"0.001\"],[\"78766.30\",\"0.002\"],[\"78767.10\",\"0.410\"]],\"u\":79825675,\"seq\":786376084837},\"cts\":1787373725287}"}
{"received_at_ns": 1787373725341292488, "payload": "{\"topic\":\"orderbook.50.BTCUSDT\",\"type\":\"delta\",\"ts\":1787373725308,\"data\":{\"s\":\"BTCUSDT\",\"b\":[[\"78758.20\",\"2.437\"],[\"78754.20\",\"0.101\"],[\"78747.30\",\"0\"]],\"a\":[[\"78758.30\",\"1.003\"],[\"78761.40\",\"0.156\"],[\"78761.50\",\"0\"],[\"78762.00\",\"0\"],[\"78762.10\",\"0.004\"],[\"78762.70\",\"0\"],[\"78770.80\",\"0.009\"],[\"78770.90\",\"0.031\"],[\"78771.00\",\"0.002\"]],\"u\":79825676,\"seq\":786376085351},\"cts\":1787373725307}"}
{"received_at_ns": 1787373725361050558, "payload": "{\"topic\":\"orderbook.50.BTCUSDT\",\"type\":\"delta\",\"ts\":1787373725328,\"data\":{\"s\":\"BTCUSDT\",\"b\":[[\"78758.20\",\"2.465\"],[\"78751.00\",\"0\"],[\"78747.30\",\"0.020\"]],\"a\":[[\"78758.30\",\"0.055\"],[\"78761.40\",\"0.004\"],[\"78764.70\",\"0\"],[\"78771.10\",\"0.410\"]],\"u\":79825677,\"seq\":786376086322},\"cts\":1787373725327}"}
{"received_at_ns": 1787373725381304937, "payload": "{\"topic\":\"orderbook.50.BTCUSDT\",\"type\":\"delta\",\"ts\":1787373725348,\"data\":{\"s\":\"BTCUSDT\",\"b\":[[\"78758.20\",\"2.451\"],[\"78756.20\",\"0.387\"],[\"78754.20\",\"0\"],[\"78752.70\",\"0.001\"],[\"78749.20\",\"0.768\"],[\"78749.10\",\"0\"],[\"78748.80\",\"0.308\"],[\"78747.00\",\"0.001\"],[\"78746.90\",\"0.078\"]],\"a\":[[\"78758.30\",\"1.890\"],[\"78761.50\",\"0.409\"],[\"78764.70\",\"0.409\"],[\"78766.30\",\"0.103\"],[\"78771.00\",\"0\"],[\"78771.10\",\"0\"]],\"u\":79825678,\"seq\":786376087353},\"cts\":1787373725347}"}
{"received_at_ns": 1787373725401124297, "payload": "{\"topic\":\"orderbook.50.BTCUSDT\",\"type\":\"delta\",\"ts\":1787373725368,\"data\":{\"s\":\"BTCUSDT\",\"b\":[[\"78758.20\",\"1.962\"],[\"78756.20\",\"0.303\"],[\"78754.20\",\"0.113\"],[\"78753.30\",\"0\"],[\"78752.30\",\"0\"],[\"78749.20\",\"0.780\"],[\"78748.30\",\"0.003\"],[\"78746.80\",\"0.002\"]],\"a\":[[\"78758.30\",\"1.869\"],[\"78761.40\",\"0.160\"],[\"78762.80\",\"0.097\"],[\"78764.60\",\"0.496\"],[\"78766.30\",\"0.002\"]],\"u\":79825679,\"seq\":786376087897},\"cts\":1787373725367}"}
{"received_at_ns": 1787373725421111267, "payload": "{\"topic\":\"orderbook.50.BTCUSDT\",\"type\":\"delta\",\"ts\":1787373725388,\"data\":{\"s\":\"BTCUSDT\",\"b\":[[\"78758.20\",\"2.595\"]],\"a\":[[\"78758.30\",\"0.039\"],[\"78761.40\",\"0.004\"],[\"78761.50\",\"0\"],[\"78764.70\",\"0\"],[\"78770.30\",\"0\"],[\"78771.00\",\"0.002\"],[\"78771.10\",\"0.410\"],[\"78771.30\",\"0.002\"]],\"u\":79825680,\"seq\":786376088846},\"cts\":1787373725387}"}
{"received_at_ns": 1787373725441296557, "payload": "{\"topic\":\"orderbook.50.BTCUSDT\",\"type\":\"delta\",\"ts\":1787373725408,\"data\":{\"s\":\"BTCUSDT\",\"b\":[[\"78758.20\",\"2.609\"]],\"a\":[[\"78764.60\",\"0.350\"],[\"78767.10\",\"0\"],[\"78771.40\",\"0.464\"]],\"u\":79825681,\"seq\":786376090239},\"cts\":1787373725407}"}
{"received_at_ns": 1787373725461288518, "payload": "{\"topic\":\"orderbook.50.BTCUSDT\",\"type\":\"delta\",\"ts\":1787373725428,\"data\":{\"s\":\"BTCUSDT\",\"b\":[[\"78758.20\",\"2.656\"]],\"a\":[[\"78758.30\",\"0.055\"],[\"78760.00\",\"0.002\"],[\"78760.80\",\"0\"],[\"78761.40\",\"0.002\"],[\"78763.40\",\"0.002\"],[\"78768.90\",\"0.002\"],[\"78771.40\",\"0\"]],\"u\":79825682,\"seq\":786376091549},\"cts\":1787373725427}"}
{"received_at_ns": 1787373725481142698, "payload": "{\"topic\":\"orderbook.50.BTCUSDT\",\"type\":\"delta\",\"ts\":1787373725448,\"data\":{\"s\":\"BTCUSDT\",\"b\":[],\"a\":[[\"78764.70\",\"0.409\"],[\"78768.30\",\"0.402\"],[\"78771.30\",\"0\"]],\"u\":79825683,\"seq\":786376092825},\"cts\":1787373725447}"}
{"received_at_ns": 1787373725521206467, "payload": "{\"topic\":\"orderbook.50.BTCUSDT\",\"type\":\"delta\",\"ts\":1787373725488,\"data\":{\"s\":\"BTCUSDT\",\"b\":[],\"a\":[[\"78764.70\",\"0\"],[\"78767.90\",\"0.002\"],[\"78771.30\",\"0.002\"]],\"u\":79825684,\"seq\":786376095283},\"cts\":1787373725487}"}
{"received_at_ns": 1787373725541186017, "payload": "{\"topic\":\"orderbook.50.BTCUSDT\",\"type\":\"delta\",\"ts\":1787373725508,\"data\":{\"s\":\"BTCUSDT\",\"b\":[[\"78758.20\",\"2.670\"]],\"a\":[[\"78764.60\",\"0.129\"],[\"78767.90\",\"0.411\"],[\"78770.30\",\"0.103\"],[\"78771.30\",\"0\"]],\"u\":79825685,\"seq\":786376096499},\"cts\":1787373725507}"}
{"received_at_ns": 1787373725561259737, "payload": "{\"topic\":\"orderbook.50.BTCUSDT\",\"type\":\"delta\",\"ts\":1787373725528,\"data\":{\"s\":\"BTCUSDT\",\"b\":[[\"78758.20\",\"2.640\"]],\"a\":[[\"78758.30\",\"0.667\"],[\"78761.50\",\"0.397\"],[\"78764.60\",\"0.235\"],[\"78764.70\",\"0.409\"],[\"78767.80\",\"0.037\"],[\"78770.90\",\"0\"],[\"78771.00\",\"0\"],[\"78771.10\",\"0\"]],\"u\":79825686,\"seq\":786376097579},\"cts\":1787373725527}"}
{"received_at_ns": 1787373725581353666, "payload": "{\"topic\":\"orderbook.50.BTCUSDT\",\"type\":\"delta\",\"ts\":1787373725548,\"data\":{\"s\":\"BTCUSDT\",\"b\":[[\"78758.20\",\"2.579\"],[\"78754.20\",\"0.012\"]],\"a\":[[\"78758.30\",\"0.992\"],[\"78760.00\",\"0.004\"],[\"78760.80\",\"0.002\"],[\"78761.40\",\"0.156\"],[\"78764.60\",\"0.354\"],[\"78767.10\",\"0.207\"],[\"78767.80\",\"0\"],[\"78770.80\",\"0\"]],\"u\":79825687,\"seq\":786376098144},\"cts\":1787373725546}"}
{"received_at_ns": 1787373725601140197, "payload": "{\"topic\":\"orderbook.50.BTCUSDT\",\"type\":\"delta\",\"ts\":1787373725568,\"data\":{\"s\":\"BTCUSDT\",\"b\":[[\"78754.20\",\"0.113\"],[\"78749.30\",\"0.773\"],[\"78749.20\",\"0.013\"]],\"a\":[[\"78758.30\",\"0.954\"]],\"u\":79825688,\"seq\":786376098688},\"cts\":1787373725567}"}
{"received_at_ns": 1787373725621294837, "payload": "{\"topic\":\"orderbook.50.BTCUSDT\",\"type\":\"delta\",\"ts\":1787373725588,\"data\":{\"s\":\"BTCUSDT\",\"b\":[],\"a\":[[\"78758.30\",\"0.667\"],[\"78761.50\",\"0\"],[\"78767.10\",\"0.410\"],[\"78770.80\",\"0.009\"]],\"u\":79825689,\"seq\":786376099225},\"cts\":1787373725587}"}
{"received_at_ns": 1787373725641010067, "payload": "{\"topic\":\"orderbook.50.BTCUSDT\",\"type\":\"delta\",\"ts\":1787373725608,\"data\":{\"s\":\"BTCUSDT\",\"b\":[],\"a\":[[\"78761.20\",\"0.063\"],[\"78761.40\",\"0.002\"],[\"78769.10\",\"0.063\"],[\"78770.30\",\"0\"],[\"78770.80\",\"0\"]],\"u\":79825690,\"seq\":786376099866},\"cts\":1787373725607}"}
{"received_at_ns": 1787373725661068977, "payload": "{\"topic\":\"orderbook.50.BTCUSDT\",\"type\":\"delta\",\"ts\":1787373725628,\"data\":{\"s\":\"BTCUSDT\",\"b\":[],\"a\":[[\"78761.40\",\"0.004\"],[\"78764.70\",\"0\"],[\"78770.30\",\"0.103\"]],\"u\":79825691,\"seq\":786376100448},\"cts\":1787373725627}"}
